Workbook

Sheet Info
A1: Fragebogen A (SoSci test546007) — aufbereiteter Datensatz
A2: Stand 12.09.2026 · erzeugt aus Auswertung_F1_Fragebogen_2026-09-12.py (Claude\03_Skripte) · Quellen: SoSci_Fragebogen\Fragebogen Datensatz.txt (111 Meldungen), data_test546007_2026-08-31_11-37.json (Sekunden, Originalfreitext CASE 189), Fragebogen\Fragebogen_Übersicht.txt (Codebuch), Statistik\Studiendaten_U15_gesamt.xlsx (01_Personen).
A4: Blatt Meldungen: eine Zeile je Meldung (sortiert nach Workbook-Code und Meldezeitpunkt). CASE-Korrekturen angewandt (59/70 → BW-06; 140/158/165/190/206 → BW-04); Listenplatz HL-04 = Workbook HL-05. Keine Meldung entfernt.
A5: Blatt Spieler: eine Zeile je zugeteiltem IG-Spieler (18). Die Zählungen sind Formeln über das Blatt Meldungen (COUNTIFS/SUMIFS) — sie stimmen mit der F1-Ausgabe überein (geprüft 12.09.2026).
A6: Blatt Parameter: Programmwochen, Bodenkontakte, Videodauern (Soll), Erwärmung. GELB = vom Verfasser zu ergänzen (Videodauer Woche 5). Load-Formeln greifen darauf zu.
A8: Zählregeln (F1 § 6.3, Entscheidung 12.09.2026):
A9: Hauptzählung = Meldungen mit Status „ganz“, je Meldung gezählt (Einheitennummer H003 unbeachtlich). Untergrenzen: wochen-gedeckelt (höchstens 2 je Programmwoche nach Meldedatum) und distinkte H003. „ganz + teilweise“ = Beteiligungsrate / Sensitivität.
A10: Programmwoche nach Datum: Kalenderregel Mo 00:00 – So 23:59 (W1 20.–26.07. … W6 24.–30.08.2026); Fensterregel (So 20:00 – So 19:59) nur als Sensitivität. Einheit_rekonstruiert: k-te durchgeführte Meldung der Datumswoche w → 2w−1 bzw. 2w; leer = 3. Meldung derselben Woche („über Soll“) oder „gar nicht“.
A11: CR10 = H005 − 1 (0 Ruhe … 10 Maximal). sRPE-Load = CR10 × Dauer (min), nur für Status „ganz“; Variante I = Wochenvideo, Variante II = Wochenvideo + Erwärmung 8:53 (Annahme: Erwärmung nicht in der Wochendauer enthalten — zu klären).
A12: Dublettenregel: zwei Meldungen desselben Spielers ≤ 5 min mit identischem kodiertem Inhalt (H003–H009) = Dublette (Flag), sonst Sammelmeldung. Einzige Dublette nach Regel: CASE 254 (HL-03, „gar nicht“) — ohne Zählfolge.
A13: „Nicht gemeldet“ ≠ „nicht trainiert“ · Meldeintervall ≠ Trainingsabstand · Attendance ≠ Compliance · Fremdtraining = Untergrenze (Item teils missverstanden).

Sheet Parameter
A1: Parameter
A2: Programmwoche | B2: Zeitraum (nach Datum) | C2: Bodenkontakte je Einheit | D2: Videodauer Soll (min, dezimal) | E2: Videodauer (mm:ss) | F2: Erwärmung (min, dezimal) | G2: Dauer Variante II (min)
A3: 1 | B3: 20.07.–26.07.2026 | C3: 52 | D3: 28.266667 | E3: 28:16 | F3: 8.8833333 | G3: =IF(D3="","",D3+F3) -> 37.15
A4: 2 | B4: 27.07.–02.08.2026 | C4: 66 | D4: 28.033333 | E4: 28:02 | F4: 8.8833333 | G4: =IF(D4="","",D4+F4) -> 36.916667
A5: 3 | B5: 03.08.–09.08.2026 | C5: 80 | D5: 24.283333 | E5: 24:17 | F5: 8.8833333 | G5: =IF(D5="","",D5+F5) -> 33.166667
A6: 4 | B6: 10.08.–16.08.2026 | C6: 96 | D6: 25.916667 | E6: 25:55 | F6: 8.8833333 | G6: =IF(D6="","",D6+F6) -> 34.8
A7: 5 | B7: 17.08.–23.08.2026 | C7: 106 | F7: 8.8833333 | G7: =IF(D7="","",D7+F7)
A8: 6 | B8: 24.08.–30.08.2026 | C8: 120 | D8: 31.05 | E8: 31:03 | F8: 8.8833333 | G8: =IF(D8="","",D8+F8) -> 39.933333
A10: Quellen: Videodauern und Erwärmung 8:53 — Angabe des Verfassers, 12.09.2026 (Soll-Dauer der Wochenvideos). Bodenkontakte — Trainingsdokumentation_Block1-3.docx, Teil A. Programmwochen — Übergabe § 3 (Veröffentlichung sonntags 20 Uhr für die Folgewoche).
A11: GELB = einzutragen (D7/E7: Videodauer Woche 5). Variante II = Videodauer + Erwärmung — nur zutreffend, falls die Erwärmung nicht in der Wochendauer enthalten ist (offen).

Sheet Meldungen
A1: CASE | B1: Listencode | C1: Workbook-Code | D1: CASE-korrigiert | E1: Verein | F1: Meldezeitpunkt (STARTED) | G1: Wochentag | H1: Programmwoche nach Datum | I1: Programmwoche Fensterregel | J1: H003 Einheitennummer | K1: H003-Woche | L1: H003-Einheit | M1: Einheit rekonstruiert (nach Datum) | N1: Status (H004) | O1: durchgeführt (ganz/teilw.) | P1: ganz (1/0) | Q1: CR-10 | R1: Untergrund (H006) | S1: Schmerz (H007) | T1: Videopause (H008) | U1: Fremdtraining (H009) | V1: Grund teilweise (H004_02) | W1: Grund gar nicht (H004_03) | X1: Schmerz Freitext (H007_01) | Y1: Videopause Freitext (H008_01) | Z1: Fremdtraining Freitext (H009_01) | AA1: TIME_SUM (s) | AB1: So ≥ 20 Uhr | AC1: Meldeintervall zur Vormeldung (h) | AD1: Flag (Dublette/Sammelmeldung) | AE1: Bodenkontakte (Woche) | AF1: sRPE-Load I (ganz) | AG1: sRPE-Load II (ganz) | AH1: Hilfsspalte: zählt gedeckelt (ganz) | AI1: Hilfsspalte: erste Meldung dieser H003 (ganz) | AJ1: Hilfsspalte: zählt gedeckelt (ganz+teilw.) | AK1: Hilfsspalte: erste Meldung dieser H003 (ganz+teilw.)
A2: 44 | B2: BW-02 | C2: BW-02 | E2: B | F2: 46227.718 | G2: Fr | H2: 1 | I2: 1 | J2: 1 | K2: 1 | L2: 1 | M2: 1 | N2: ganz | O2: ja | P2: 1 | Q2: 4 | R2: Kunstrasen | S2: ja | T2: ja | U2: ja | X2: Leichte Knie schmerzen habe aber auch auf Socken trainiert | Y2: Weil viele Übungen gleich waren und ich erstmal den Unterschied genau anschauen wollte bevor ich was falsch mache | Z2: Ich war in einem Leistungs Camp und trainiere zusätzlich 1 mal | AA2: 53 | AE2: =INDEX(Parameter!$C$3:$C$8,H2) -> 52 | AF2: =IF(AND(N2="ganz",INDEX(Parameter!$D$3:$D$8,H2)<>""),Q2*INDEX(Parameter!$D$3:$D$8,H2),"") -> 113.06667 | AG2: =IF(AND(N2="ganz",INDEX(Parameter!$D$3:$D$8,H2)<>""),Q2*(INDEX(Parameter!$D$3:$D$8,H2)+INDEX(Parameter!$F$3:$F$8,H2)),"") -> 148.6 | AH2: =IF(AND(N2="ganz",COUNTIFS($C$2:C2,C2,$H$2:H2,H2,$N$2:N2,"ganz")<=2),1,0) -> 1 | AI2: =IF(AND(N2="ganz",COUNTIFS($C$2:C2,C2,$J$2:J2,J2,$N$2:N2,"ganz")=1),1,0) -> 1 | AJ2: =IF(AND(O2="ja",COUNTIFS($C$2:C2,C2,$H$2:H2,H2,$O$2:O2,"ja")<=2),1,0) -> 1 | AK2: =IF(AND(O2="ja",COUNTIFS($C$2:C2,C2,$J$2:J2,J2,$O$2:O2,"ja")=1),1,0) -> 1
A3: 66 | B3: BW-02 | C3: BW-02 | E3: B | F3: 46229.758 | G3: So | H3: 1 | I3: 1 | J3: 2 | K3: 1 | L3: 2 | M3: 2 | N3: ganz | O3: ja | P3: 1 | Q3: 3 | R3: Anderes | S3: nein | T3: nein | U3: ja | Z3: Ich war im gym und war fusballtraniren | AA3: 95 | AC3: =IF(C3=C2,(F3-F2)*24,"") -> 48.953333 | AE3: =INDEX(Parameter!$C$3:$C$8,H3) -> 52 | AF3: =IF(AND(N3="ganz",INDEX(Parameter!$D$3:$D$8,H3)<>""),Q3*INDEX(Parameter!$D$3:$D$8,H3),"") -> 84.8 | AG3: =IF(AND(N3="ganz",INDEX(Parameter!$D$3:$D$8,H3)<>""),Q3*(INDEX(Parameter!$D$3:$D$8,H3)+INDEX(Parameter!$F$3:$F$8,H3)),"") -> 111.45 | AH3: =IF(AND(N3="ganz",COUNTIFS($C$2:C3,C3,$H$2:H3,H3,$N$2:N3,"ganz")<=2),1,0) -> 1 | AI3: =IF(AND(N3="ganz",COUNTIFS($C$2:C3,C3,$J$2:J3,J3,$N$2:N3,"ganz")=1),1,0) -> 1 | AJ3: =IF(AND(O3="ja",COUNTIFS($C$2:C3,C3,$H$2:H3,H3,$O$2:O3,"ja")<=2),1,0) -> 1 | AK3: =IF(AND(O3="ja",COUNTIFS($C$2:C3,C3,$J$2:J3,J3,$O$2:O3,"ja")=1),1,0) -> 1
A4: 78 | B4: BW-02 | C4: BW-02 | E4: B | F4: 46231.762 | G4: Di | H4: 2 | I4: 2 | J4: 3 | K4: 2 | L4: 1 | M4: 3 | N4: ganz | O4: ja | P4: 1 | Q4: 2 | R4: Kunstrasen | S4: nein | T4: nein | U4: ja | Z4: Ich habe heute Frühs schon Fußball trainiert | AA4: 46 | AC4: =IF(C4=C3,(F4-F3)*24,"") -> 48.100556 | AE4: =INDEX(Parameter!$C$3:$C$8,H4) -> 66 | AF4: =IF(AND(N4="ganz",INDEX(Parameter!$D$3:$D$8,H4)<>""),Q4*INDEX(Parameter!$D$3:$D$8,H4),"") -> 56.066667 | AG4: =IF(AND(N4="ganz",INDEX(Parameter!$D$3:$D$8,H4)<>""),Q4*(INDEX(Parameter!$D$3:$D$8,H4)+INDEX(Parameter!$F$3:$F$8,H4)),"") -> 73.833333 | AH4: =IF(AND(N4="ganz",COUNTIFS($C$2:C4,C4,$H$2:H4,H4,$N$2:N4,"ganz")<=2),1,0) -> 1 | AI4: =IF(AND(N4="ganz",COUNTIFS($C$2:C4,C4,$J$2:J4,J4,$N$2:N4,"ganz")=1),1,0) -> 1 | AJ4: =IF(AND(O4="ja",COUNTIFS($C$2:C4,C4,$H$2:H4,H4,$O$2:O4,"ja")<=2),1,0) -> 1 | AK4: =IF(AND(O4="ja",COUNTIFS($C$2:C4,C4,$J$2:J4,J4,$O$2:O4,"ja")=1),1,0) -> 1
A5: 90 | B5: BW-02 | C5: BW-02 | E5: B | F5: 46234.356 | G5: Fr | H5: 2 | I5: 2 | J5: 4 | K5: 2 | L5: 2 | M5: 4 | N5: ganz | O5: ja | P5: 1 | Q5: 3 | R5: Kunstrasen | S5: nein | T5: nein | U5: ja | Z5: Ich war im Fitnessstudio dazu habe ich noch Fußball traniert wie oft weiß ich nicht aber aufjeden Fall sehr viel | AA5: 50 | AC5: =IF(C5=C4,(F5-F4)*24,"") -> 62.255 | AE5: =INDEX(Parameter!$C$3:$C$8,H5) -> 66 | AF5: =IF(AND(N5="ganz",INDEX(Parameter!$D$3:$D$8,H5)<>""),Q5*INDEX(Parameter!$D$3:$D$8,H5),"") -> 84.1 | AG5: =IF(AND(N5="ganz",INDEX(Parameter!$D$3:$D$8,H5)<>""),Q5*(INDEX(Parameter!$D$3:$D$8,H5)+INDEX(Parameter!$F$3:$F$8,H5)),"") -> 110.75 | AH5: =IF(AND(N5="ganz",COUNTIFS($C$2:C5,C5,$H$2:H5,H5,$N$2:N5,"ganz")<=2),1,0) -> 1 | AI5: =IF(AND(N5="ganz",COUNTIFS($C$2:C5,C5,$J$2:J5,J5,$N$2:N5,"ganz")=1),1,0) -> 1 | AJ5: =IF(AND(O5="ja",COUNTIFS($C$2:C5,C5,$H$2:H5,H5,$O$2:O5,"ja")<=2),1,0) -> 1 | AK5: =IF(AND(O5="ja",COUNTIFS($C$2:C5,C5,$J$2:J5,J5,$O$2:O5,"ja")=1),1,0) -> 1
A6: 126 | B6: BW-02 | C6: BW-02 | E6: B | F6: 46238.802 | G6: Di | H6: 3 | I6: 3 | J6: 5 | K6: 3 | L6: 1 | M6: 5 | N6: ganz | O6: ja | P6: 1 | Q6: 3 | R6: Rasen/Wiese | S6: nein | T6: nein | U6: ja | Z6: Ich habe individuell Fußball trainiert | AA6: 64 | AC6: =IF(C6=C5,(F6-F5)*24,"") -> 106.71583 | AE6: =INDEX(Parameter!$C$3:$C$8,H6) -> 80 | AF6: =IF(AND(N6="ganz",INDEX(Parameter!$D$3:$D$8,H6)<>""),Q6*INDEX(Parameter!$D$3:$D$8,H6),"") -> 72.85 | AG6: =IF(AND(N6="ganz",INDEX(Parameter!$D$3:$D$8,H6)<>""),Q6*(INDEX(Parameter!$D$3:$D$8,H6)+INDEX(Parameter!$F$3:$F$8,H6)),"") -> 99.5 | AH6: =IF(AND(N6="ganz",COUNTIFS($C$2:C6,C6,$H$2:H6,H6,$N$2:N6,"ganz")<=2),1,0) -> 1 | AI6: =IF(AND(N6="ganz",COUNTIFS($C$2:C6,C6,$J$2:J6,J6,$N$2:N6,"ganz")=1),1,0) -> 1 | AJ6: =IF(AND(O6="ja",COUNTIFS($C$2:C6,C6,$H$2:H6,H6,$O$2:O6,"ja")<=2),1,0) -> 1 | AK6: =IF(AND(O6="ja",COUNTIFS($C$2:C6,C6,$J$2:J6,J6,$O$2:O6,"ja")=1),1,0) -> 1
A7: 133 | B7: BW-02 | C7: BW-02 | E7: B | F7: 46240.925 | G7: Do | H7: 3 | I7: 3 | J7: 6 | K7: 3 | L7: 2 | M7: 6 | N7: ganz | O7: ja | P7: 1 | Q7: 3 | R7: Kunstrasen | S7: nein | T7: nein | U7: ja | Z7: Ja ich habe heute individuell 2 mal Fußball traning gemacht zum Schluss habe ich das hier gemacht | AA7: 48 | AC7: =IF(C7=C6,(F7-F6)*24,"") -> 50.943889 | AE7: =INDEX(Parameter!$C$3:$C$8,H7) -> 80 | AF7: =IF(AND(N7="ganz",INDEX(Parameter!$D$3:$D$8,H7)<>""),Q7*INDEX(Parameter!$D$3:$D$8,H7),"") -> 72.85 | AG7: =IF(AND(N7="ganz",INDEX(Parameter!$D$3:$D$8,H7)<>""),Q7*(INDEX(Parameter!$D$3:$D$8,H7)+INDEX(Parameter!$F$3:$F$8,H7)),"") -> 99.5 | AH7: =IF(AND(N7="ganz",COUNTIFS($C$2:C7,C7,$H$2:H7,H7,$N$2:N7,"ganz")<=2),1,0) -> 1 | AI7: =IF(AND(N7="ganz",COUNTIFS($C$2:C7,C7,$J$2:J7,J7,$N$2:N7,"ganz")=1),1,0) -> 1 | AJ7: =IF(AND(O7="ja",COUNTIFS($C$2:C7,C7,$H$2:H7,H7,$O$2:O7,"ja")<=2),1,0) -> 1 | AK7: =IF(AND(O7="ja",COUNTIFS($C$2:C7,C7,$J$2:J7,J7,$O$2:O7,"ja")=1),1,0) -> 1
A8: 167 | B8: BW-02 | C8: BW-02 | E8: B | F8: 46245.858 | G8: Di | H8: 4 | I8: 4 | J8: 7 | K8: 4 | L8: 1 | M8: 7 | N8: ganz | O8: ja | P8: 1 | Q8: 2 | R8: Kunstrasen | S8: nein | T8: nein | U8: ja | Z8: Kurz nach Mannschaft traning | AA8: 35 | AC8: =IF(C8=C7,(F8-F7)*24,"") -> 118.385 | AE8: =INDEX(Parameter!$C$3:$C$8,H8) -> 96 | AF8: =IF(AND(N8="ganz",INDEX(Parameter!$D$3:$D$8,H8)<>""),Q8*INDEX(Parameter!$D$3:$D$8,H8),"") -> 51.833333 | AG8: =IF(AND(N8="ganz",INDEX(Parameter!$D$3:$D$8,H8)<>""),Q8*(INDEX(Parameter!$D$3:$D$8,H8)+INDEX(Parameter!$F$3:$F$8,H8)),"") -> 69.6 | AH8: =IF(AND(N8="ganz",COUNTIFS($C$2:C8,C8,$H$2:H8,H8,$N$2:N8,"ganz")<=2),1,0) -> 1 | AI8: =IF(AND(N8="ganz",COUNTIFS($C$2:C8,C8,$J$2:J8,J8,$N$2:N8,"ganz")=1),1,0) -> 1 | AJ8: =IF(AND(O8="ja",COUNTIFS($C$2:C8,C8,$H$2:H8,H8,$O$2:O8,"ja")<=2),1,0) -> 1 | AK8: =IF(AND(O8="ja",COUNTIFS($C$2:C8,C8,$J$2:J8,J8,$O$2:O8,"ja")=1),1,0) -> 1
A9: 197 | B9: BW-02 | C9: BW-02 | E9: B | F9: 46250.829 | G9: So | H9: 4 | I9: 4 | J9: 8 | K9: 4 | L9: 2 | M9: 8 | N9: ganz | O9: ja | P9: 1 | Q9: 1 | R9: Rasen/Wiese | S9: nein | T9: nein | U9: ja | Z9: Ja individuell meinen torschuß und ersten Kontakt trainiert | AA9: 61 | AC9: =IF(C9=C8,(F9-F8)*24,"") -> 119.30528 | AE9: =INDEX(Parameter!$C$3:$C$8,H9) -> 96 | AF9: =IF(AND(N9="ganz",INDEX(Parameter!$D$3:$D$8,H9)<>""),Q9*INDEX(Parameter!$D$3:$D$8,H9),"") -> 25.916667 | AG9: =IF(AND(N9="ganz",INDEX(Parameter!$D$3:$D$8,H9)<>""),Q9*(INDEX(Parameter!$D$3:$D$8,H9)+INDEX(Parameter!$F$3:$F$8,H9)),"") -> 34.8 | AH9: =IF(AND(N9="ganz",COUNTIFS($C$2:C9,C9,$H$2:H9,H9,$N$2:N9,"ganz")<=2),1,0) -> 1 | AI9: =IF(AND(N9="ganz",COUNTIFS($C$2:C9,C9,$J$2:J9,J9,$N$2:N9,"ganz")=1),1,0) -> 1 | AJ9: =IF(AND(O9="ja",COUNTIFS($C$2:C9,C9,$H$2:H9,H9,$O$2:O9,"ja")<=2),1,0) -> 1 | AK9: =IF(AND(O9="ja",COUNTIFS($C$2:C9,C9,$J$2:J9,J9,$O$2:O9,"ja")=1),1,0) -> 1
A10: 209 | B10: BW-02 | C10: BW-02 | E10: B | F10: 46253.483 | G10: Mi | H10: 5 | I10: 5 | J10: 9 | K10: 5 | L10: 1 | M10: 9 | N10: ganz | O10: ja | P10: 1 | Q10: 1 | R10: Kunstrasen | S10: nein | T10: nein | U10: ja | Z10: Ich habe heute Morgen individuell Fußball trainiert | AA10: 67 | AC10: =IF(C10=C9,(F10-F9)*24,"") -> 63.694722 | AE10: =INDEX(Parameter!$C$3:$C$8,H10) -> 106 | AF10: =IF(AND(N10="ganz",INDEX(Parameter!$D$3:$D$8,H10)<>""),Q10*INDEX(Parameter!$D$3:$D$8,H10),"") | AG10: =IF(AND(N10="ganz",INDEX(Parameter!$D$3:$D$8,H10)<>""),Q10*(INDEX(Parameter!$D$3:$D$8,H10)+INDEX(Parameter!$F$3:$F$8,H10)),"") | AH10: =IF(AND(N10="ganz",COUNTIFS($C$2:C10,C10,$H$2:H10,H10,$N$2:N10,"ganz")<=2),1,0) -> 1 | AI10: =IF(AND(N10="ganz",COUNTIFS($C$2:C10,C10,$J$2:J10,J10,$N$2:N10,"ganz")=1),1,0) -> 1 | AJ10: =IF(AND(O10="ja",COUNTIFS($C$2:C10,C10,$H$2:H10,H10,$O$2:O10,"ja")<=2),1,0) -> 1 | AK10: =IF(AND(O10="ja",COUNTIFS($C$2:C10,C10,$J$2:J10,J10,$O$2:O10,"ja")=1),1,0) -> 1
A11: 230 | B11: BW-02 | C11: BW-02 | E11: B | F11: 46257.885 | G11: So | H11: 5 | I11: 6 | J11: 10 | K11: 5 | L11: 2 | M11: 10 | N11: ganz | O11: ja | P11: 1 | Q11: 2 | R11: Rasen/Wiese | S11: nein | T11: nein | U11: ja | Z11: War schwimmen | AA11: 54 | AB11: ja | AC11: =IF(C11=C10,(F11-F10)*24,"") -> 105.65889 | AE11: =INDEX(Parameter!$C$3:$C$8,H11) -> 106 | AF11: =IF(AND(N11="ganz",INDEX(Parameter!$D$3:$D$8,H11)<>""),Q11*INDEX(Parameter!$D$3:$D$8,H11),"") | AG11: =IF(AND(N11="ganz",INDEX(Parameter!$D$3:$D$8,H11)<>""),Q11*(INDEX(Parameter!$D$3:$D$8,H11)+INDEX(Parameter!$F$3:$F$8,H11)),"") | AH11: =IF(AND(N11="ganz",COUNTIFS($C$2:C11,C11,$H$2:H11,H11,$N$2:N11,"ganz")<=2),1,0) -> 1 | AI11: =IF(AND(N11="ganz",COUNTIFS($C$2:C11,C11,$J$2:J11,J11,$N$2:N11,"ganz")=1),1,0) -> 1 | AJ11: =IF(AND(O11="ja",COUNTIFS($C$2:C11,C11,$H$2:H11,H11,$O$2:O11,"ja")<=2),1,0) -> 1 | AK11: =IF(AND(O11="ja",COUNTIFS($C$2:C11,C11,$J$2:J11,J11,$O$2:O11,"ja")=1),1,0) -> 1
A12: 257 | B12: BW-02 | C12: BW-02 | E12: B | F12: 46264.604 | G12: So | H12: 6 | I12: 6 | J12: 11 | K12: 6 | L12: 1 | M12: 11 | N12: ganz | O12: ja | P12: 1 | Q12: 2 | R12: Drinnen | S12: nein | T12: nein | U12: nein | AA12: 39 | AC12: =IF(C12=C11,(F12-F11)*24,"") -> 161.25944 | AE12: =INDEX(Parameter!$C$3:$C$8,H12) -> 120 | AF12: =IF(AND(N12="ganz",INDEX(Parameter!$D$3:$D$8,H12)<>""),Q12*INDEX(Parameter!$D$3:$D$8,H12),"") -> 62.1 | AG12: =IF(AND(N12="ganz",INDEX(Parameter!$D$3:$D$8,H12)<>""),Q12*(INDEX(Parameter!$D$3:$D$8,H12)+INDEX(Parameter!$F$3:$F$8,H12)),"") -> 79.866667 | AH12: =IF(AND(N12="ganz",COUNTIFS($C$2:C12,C12,$H$2:H12,H12,$N$2:N12,"ganz")<=2),1,0) -> 1 | AI12: =IF(AND(N12="ganz",COUNTIFS($C$2:C12,C12,$J$2:J12,J12,$N$2:N12,"ganz")=1),1,0) -> 1 | AJ12: =IF(AND(O12="ja",COUNTIFS($C$2:C12,C12,$H$2:H12,H12,$O$2:O12,"ja")<=2),1,0) -> 1 | AK12: =IF(AND(O12="ja",COUNTIFS($C$2:C12,C12,$J$2:J12,J12,$O$2:O12,"ja")=1),1,0) -> 1
A13: 258 | B13: BW-02 | C13: BW-02 | E13: B | F13: 46264.705 | G13: So | H13: 6 | I13: 6 | J13: 12 | K13: 6 | L13: 2 | M13: 12 | N13: ganz | O13: ja | P13: 1 | Q13: 2 | R13: Anderes | S13: nein | T13: nein | U13: ja | Z13: Ich habe diese andere Einheit gemacht weil ich leider diese Woche voll vergessen habe das zu machen deswegen hab ich heute alles gemacht | AA13: 43 | AC13: =IF(C13=C12,(F13-F12)*24,"") -> 2.4055556 | AE13: =INDEX(Parameter!$C$3:$C$8,H13) -> 120 | AF13: =IF(AND(N13="ganz",INDEX(Parameter!$D$3:$D$8,H13)<>""),Q13*INDEX(Parameter!$D$3:$D$8,H13),"") -> 62.1 | AG13: =IF(AND(N13="ganz",INDEX(Parameter!$D$3:$D$8,H13)<>""),Q13*(INDEX(Parameter!$D$3:$D$8,H13)+INDEX(Parameter!$F$3:$F$8,H13)),"") -> 79.866667 | AH13: =IF(AND(N13="ganz",COUNTIFS($C$2:C13,C13,$H$2:H13,H13,$N$2:N13,"ganz")<=2),1,0) -> 1 | AI13: =IF(AND(N13="ganz",COUNTIFS($C$2:C13,C13,$J$2:J13,J13,$N$2:N13,"ganz")=1),1,0) -> 1 | AJ13: =IF(AND(O13="ja",COUNTIFS($C$2:C13,C13,$H$2:H13,H13,$O$2:O13,"ja")<=2),1,0) -> 1 | AK13: =IF(AND(O13="ja",COUNTIFS($C$2:C13,C13,$J$2:J13,J13,$O$2:O13,"ja")=1),1,0) -> 1
A14: 99 | B14: BW-04 | C14: BW-04 | E14: B | F14: 46235.846 | G14: Sa | H14: 2 | I14: 2 | J14: 3 | K14: 2 | L14: 1 | M14: 3 | N14: teilweise | O14: ja | P14: 0 | Q14: 9 | R14: Drinnen | S14: ja | T14: nein | U14: nein | V14: Alles | X14: Knöchelverletzung | AA14: 46 | AC14: =IF(C14=C13,(F14-F13)*24,"") | AE14: =INDEX(Parameter!$C$3:$C$8,H14) -> 66 | AF14: =IF(AND(N14="ganz",INDEX(Parameter!$D$3:$D$8,H14)<>""),Q14*INDEX(Parameter!$D$3:$D$8,H14),"") | AG14: =IF(AND(N14="ganz",INDEX(Parameter!$D$3:$D$8,H14)<>""),Q14*(INDEX(Parameter!$D$3:$D$8,H14)+INDEX(Parameter!$F$3:$F$8,H14)),"") | AH14: =IF(AND(N14="ganz",COUNTIFS($C$2:C14,C14,$H$2:H14,H14,$N$2:N14,"ganz")<=2),1,0) -> 0 | AI14: =IF(AND(N14="ganz",COUNTIFS($C$2:C14,C14,$J$2:J14,J14,$N$2:N14,"ganz")=1),1,0) -> 0 | AJ14: =IF(AND(O14="ja",COUNTIFS($C$2:C14,C14,$H$2:H14,H14,$O$2:O14,"ja")<=2),1,0) -> 1 | AK14: =IF(AND(O14="ja",COUNTIFS($C$2:C14,C14,$J$2:J14,J14,$O$2:O14,"ja")=1),1,0) -> 1
A15: 140 | B15: HL-04 | C15: BW-04 | D15: ja | E15: B | F15: 46241.726 | G15: Fr | H15: 3 | I15: 3 | J15: 3 | K15: 2 | L15: 1 | M15: 5 | N15: ganz | O15: ja | P15: 1 | Q15: 2 | R15: Drinnen | S15: nein | T15: nein | U15: ja | Z15: Krafttraining 3 mal die Woche | AA15: 64 | AC15: =IF(C15=C14,(F15-F14)*24,"") -> 141.12889 | AE15: =INDEX(Parameter!$C$3:$C$8,H15) -> 80 | AF15: =IF(AND(N15="ganz",INDEX(Parameter!$D$3:$D$8,H15)<>""),Q15*INDEX(Parameter!$D$3:$D$8,H15),"") -> 48.566667 | AG15: =IF(AND(N15="ganz",INDEX(Parameter!$D$3:$D$8,H15)<>""),Q15*(INDEX(Parameter!$D$3:$D$8,H15)+INDEX(Parameter!$F$3:$F$8,H15)),"") -> 66.333333 | AH15: =IF(AND(N15="ganz",COUNTIFS($C$2:C15,C15,$H$2:H15,H15,$N$2:N15,"ganz")<=2),1,0) -> 1 | AI15: =IF(AND(N15="ganz",COUNTIFS($C$2:C15,C15,$J$2:J15,J15,$N$2:N15,"ganz")=1),1,0) -> 1 | AJ15: =IF(AND(O15="ja",COUNTIFS($C$2:C15,C15,$H$2:H15,H15,$O$2:O15,"ja")<=2),1,0) -> 1 | AK15: =IF(AND(O15="ja",COUNTIFS($C$2:C15,C15,$J$2:J15,J15,$O$2:O15,"ja")=1),1,0) -> 0
A16: 158 | B16: HL-04 | C16: BW-04 | D16: ja | E16: B | F16: 46244.34 | G16: Mo | H16: 4 | I16: 4 | J16: 1 | K16: 1 | L16: 1 | M16: 7 | N16: ganz | O16: ja | P16: 1 | Q16: 2 | R16: Drinnen | S16: nein | T16: nein | U16: ja | Z16: Bastis Läufe | AA16: 72 | AC16: =IF(C16=C15,(F16-F15)*24,"") -> 62.726111 | AE16: =INDEX(Parameter!$C$3:$C$8,H16) -> 96 | AF16: =IF(AND(N16="ganz",INDEX(Parameter!$D$3:$D$8,H16)<>""),Q16*INDEX(Parameter!$D$3:$D$8,H16),"") -> 51.833333 | AG16: =IF(AND(N16="ganz",INDEX(Parameter!$D$3:$D$8,H16)<>""),Q16*(INDEX(Parameter!$D$3:$D$8,H16)+INDEX(Parameter!$F$3:$F$8,H16)),"") -> 69.6 | AH16: =IF(AND(N16="ganz",COUNTIFS($C$2:C16,C16,$H$2:H16,H16,$N$2:N16,"ganz")<=2),1,0) -> 1 | AI16: =IF(AND(N16="ganz",COUNTIFS($C$2:C16,C16,$J$2:J16,J16,$N$2:N16,"ganz")=1),1,0) -> 1 | AJ16: =IF(AND(O16="ja",COUNTIFS($C$2:C16,C16,$H$2:H16,H16,$O$2:O16,"ja")<=2),1,0) -> 1 | AK16: =IF(AND(O16="ja",COUNTIFS($C$2:C16,C16,$J$2:J16,J16,$O$2:O16,"ja")=1),1,0) -> 1
A17: 165 | B17: HL-04 | C17: BW-04 | D17: ja | E17: B | F17: 46245.752 | G17: Di | H17: 4 | I17: 4 | J17: 7 | K17: 4 | L17: 1 | M17: 8 | N17: ganz | O17: ja | P17: 1 | Q17: 0 | R17: Rasen/Wiese | S17: nein | T17: nein | U17: nein | AA17: 46 | AC17: =IF(C17=C16,(F17-F16)*24,"") -> 33.900556 | AE17: =INDEX(Parameter!$C$3:$C$8,H17) -> 96 | AF17: =IF(AND(N17="ganz",INDEX(Parameter!$D$3:$D$8,H17)<>""),Q17*INDEX(Parameter!$D$3:$D$8,H17),"") -> 0 | AG17: =IF(AND(N17="ganz",INDEX(Parameter!$D$3:$D$8,H17)<>""),Q17*(INDEX(Parameter!$D$3:$D$8,H17)+INDEX(Parameter!$F$3:$F$8,H17)),"") -> 0 | AH17: =IF(AND(N17="ganz",COUNTIFS($C$2:C17,C17,$H$2:H17,H17,$N$2:N17,"ganz")<=2),1,0) -> 1 | AI17: =IF(AND(N17="ganz",COUNTIFS($C$2:C17,C17,$J$2:J17,J17,$N$2:N17,"ganz")=1),1,0) -> 1 | AJ17: =IF(AND(O17="ja",COUNTIFS($C$2:C17,C17,$H$2:H17,H17,$O$2:O17,"ja")<=2),1,0) -> 1 | AK17: =IF(AND(O17="ja",COUNTIFS($C$2:C17,C17,$J$2:J17,J17,$O$2:O17,"ja")=1),1,0) -> 1
A18: 190 | B18: HL-04 | C18: BW-04 | D18: ja | E18: B | F18: 46250.633 | G18: So | H18: 4 | I18: 4 | J18: 8 | K18: 4 | L18: 2 | N18: ganz | O18: ja | P18: 1 | Q18: 2 | R18: Rasen/Wiese | S18: nein | T18: nein | U18: ja | Z18: Liege stütze 2 mal | AA18: 51 | AC18: =IF(C18=C17,(F18-F17)*24,"") -> 117.14833 | AE18: =INDEX(Parameter!$C$3:$C$8,H18) -> 96 | AF18: =IF(AND(N18="ganz",INDEX(Parameter!$D$3:$D$8,H18)<>""),Q18*INDEX(Parameter!$D$3:$D$8,H18),"") -> 51.833333 | AG18: =IF(AND(N18="ganz",INDEX(Parameter!$D$3:$D$8,H18)<>""),Q18*(INDEX(Parameter!$D$3:$D$8,H18)+INDEX(Parameter!$F$3:$F$8,H18)),"") -> 69.6 | AH18: =IF(AND(N18="ganz",COUNTIFS($C$2:C18,C18,$H$2:H18,H18,$N$2:N18,"ganz")<=2),1,0) -> 0 | AI18: =IF(AND(N18="ganz",COUNTIFS($C$2:C18,C18,$J$2:J18,J18,$N$2:N18,"ganz")=1),1,0) -> 1 | AJ18: =IF(AND(O18="ja",COUNTIFS($C$2:C18,C18,$H$2:H18,H18,$O$2:O18,"ja")<=2),1,0) -> 0 | AK18: =IF(AND(O18="ja",COUNTIFS($C$2:C18,C18,$J$2:J18,J18,$O$2:O18,"ja")=1),1,0) -> 1
A19: 206 | B19: HL-04 | C19: BW-04 | D19: ja | E19: B | F19: 46252.597 | G19: Di | H19: 5 | I19: 5 | J19: 9 | K19: 5 | L19: 1 | M19: 9 | N19: ganz | O19: ja | P19: 1 | Q19: 1 | R19: Rasen/Wiese | S19: nein | T19: ja | U19: nein | Y19: 1 mal bei dem einbeinsprung | AA19: 37 | AC19: =IF(C19=C18,(F19-F18)*24,"") -> 47.135556 | AE19: =INDEX(Parameter!$C$3:$C$8,H19) -> 106 | AF19: =IF(AND(N19="ganz",INDEX(Parameter!$D$3:$D$8,H19)<>""),Q19*INDEX(Parameter!$D$3:$D$8,H19),"") | AG19: =IF(AND(N19="ganz",INDEX(Parameter!$D$3:$D$8,H19)<>""),Q19*(INDEX(Parameter!$D$3:$D$8,H19)+INDEX(Parameter!$F$3:$F$8,H19)),"") | AH19: =IF(AND(N19="ganz",COUNTIFS($C$2:C19,C19,$H$2:H19,H19,$N$2:N19,"ganz")<=2),1,0) -> 1 | AI19: =IF(AND(N19="ganz",COUNTIFS($C$2:C19,C19,$J$2:J19,J19,$N$2:N19,"ganz")=1),1,0) -> 1 | AJ19: =IF(AND(O19="ja",COUNTIFS($C$2:C19,C19,$H$2:H19,H19,$O$2:O19,"ja")<=2),1,0) -> 1 | AK19: =IF(AND(O19="ja",COUNTIFS($C$2:C19,C19,$J$2:J19,J19,$O$2:O19,"ja")=1),1,0) -> 1
A20: 256 | B20: BW-04 | C20: BW-04 | E20: B | F20: 46264.508 | G20: So | H20: 6 | I20: 6 | J20: 11 | K20: 6 | L20: 1 | M20: 11 | N20: ganz | O20: ja | P20: 1 | Q20: 1 | R20: Rasen/Wiese | S20: nein | T20: nein | U20: ja | Z20: Fussball 2 | AA20: 60 | AC20: =IF(C20=C19,(F20-F19)*24,"") -> 285.85667 | AE20: =INDEX(Parameter!$C$3:$C$8,H20) -> 120 | AF20: =IF(AND(N20="ganz",INDEX(Parameter!$D$3:$D$8,H20)<>""),Q20*INDEX(Parameter!$D$3:$D$8,H20),"") -> 31.05 | AG20: =IF(AND(N20="ganz",INDEX(Parameter!$D$3:$D$8,H20)<>""),Q20*(INDEX(Parameter!$D$3:$D$8,H20)+INDEX(Parameter!$F$3:$F$8,H20)),"") -> 39.933333 | AH20: =IF(AND(N20="ganz",COUNTIFS($C$2:C20,C20,$H$2:H20,H20,$N$2:N20,"ganz")<=2),1,0) -> 1 | AI20: =IF(AND(N20="ganz",COUNTIFS($C$2:C20,C20,$J$2:J20,J20,$N$2:N20,"ganz")=1),1,0) -> 1 | AJ20: =IF(AND(O20="ja",COUNTIFS($C$2:C20,C20,$H$2:H20,H20,$O$2:O20,"ja")<=2),1,0) -> 1 | AK20: =IF(AND(O20="ja",COUNTIFS($C$2:C20,C20,$J$2:J20,J20,$O$2:O20,"ja")=1),1,0) -> 1
A21: 40 | B21: BW-05 | C21: BW-05 | E21: B | F21: 46226.88 | G21: Do | H21: 1 | I21: 1 | J21: 2 | K21: 1 | L21: 2 | M21: 1 | N21: ganz | O21: ja | P21: 1 | Q21: 2 | R21: Drinnen | S21: nein | T21: nein | U21: nein | AA21: 69 | AC21: =IF(C21=C20,(F21-F20)*24,"") | AE21: =INDEX(Parameter!$C$3:$C$8,H21) -> 52 | AF21: =IF(AND(N21="ganz",INDEX(Parameter!$D$3:$D$8,H21)<>""),Q21*INDEX(Parameter!$D$3:$D$8,H21),"") -> 56.533333 | AG21: =IF(AND(N21="ganz",INDEX(Parameter!$D$3:$D$8,H21)<>""),Q21*(INDEX(Parameter!$D$3:$D$8,H21)+INDEX(Parameter!$F$3:$F$8,H21)),"") -> 74.3 | AH21: =IF(AND(N21="ganz",COUNTIFS($C$2:C21,C21,$H$2:H21,H21,$N$2:N21,"ganz")<=2),1,0) -> 1 | AI21: =IF(AND(N21="ganz",COUNTIFS($C$2:C21,C21,$J$2:J21,J21,$N$2:N21,"ganz")=1),1,0) -> 1 | AJ21: =IF(AND(O21="ja",COUNTIFS($C$2:C21,C21,$H$2:H21,H21,$O$2:O21,"ja")<=2),1,0) -> 1 | AK21: =IF(AND(O21="ja",COUNTIFS($C$2:C21,C21,$J$2:J21,J21,$O$2:O21,"ja")=1),1,0) -> 1
A22: 61 | B22: BW-05 | C22: BW-05 | E22: B | F22: 46229.659 | G22: So | H22: 1 | I22: 1 | J22: 1 | K22: 1 | L22: 1 | N22: gar nicht | O22: nein | P22: 0 | Q22: 0 | R22: Drinnen | S22: nein | T22: nein | U22: nein | W22: Hatte Kin Probleme | AA22: 50 | AC22: =IF(C22=C21,(F22-F21)*24,"") -> 66.708056 | AE22: =INDEX(Parameter!$C$3:$C$8,H22) -> 52 | AF22: =IF(AND(N22="ganz",INDEX(Parameter!$D$3:$D$8,H22)<>""),Q22*INDEX(Parameter!$D$3:$D$8,H22),"") | AG22: =IF(AND(N22="ganz",INDEX(Parameter!$D$3:$D$8,H22)<>""),Q22*(INDEX(Parameter!$D$3:$D$8,H22)+INDEX(Parameter!$F$3:$F$8,H22)),"") | AH22: =IF(AND(N22="ganz",COUNTIFS($C$2:C22,C22,$H$2:H22,H22,$N$2:N22,"ganz")<=2),1,0) -> 0 | AI22: =IF(AND(N22="ganz",COUNTIFS($C$2:C22,C22,$J$2:J22,J22,$N$2:N22,"ganz")=1),1,0) -> 0 | AJ22: =IF(AND(O22="ja",COUNTIFS($C$2:C22,C22,$H$2:H22,H22,$O$2:O22,"ja")<=2),1,0) -> 0 | AK22: =IF(AND(O22="ja",COUNTIFS($C$2:C22,C22,$J$2:J22,J22,$O$2:O22,"ja")=1),1,0) -> 0
A23: 91 | B23: BW-05 | C23: BW-05 | E23: B | F23: 46234.612 | G23: Fr | H23: 2 | I23: 2 | J23: 3 | K23: 2 | L23: 1 | M23: 3 | N23: ganz | O23: ja | P23: 1 | Q23: 3 | R23: Drinnen | S23: nein | T23: nein | U23: nein | AA23: 48 | AC23: =IF(C23=C22,(F23-F22)*24,"") -> 118.87694 | AE23: =INDEX(Parameter!$C$3:$C$8,H23) -> 66 | AF23: =IF(AND(N23="ganz",INDEX(Parameter!$D$3:$D$8,H23)<>""),Q23*INDEX(Parameter!$D$3:$D$8,H23),"") -> 84.1 | AG23: =IF(AND(N23="ganz",INDEX(Parameter!$D$3:$D$8,H23)<>""),Q23*(INDEX(Parameter!$D$3:$D$8,H23)+INDEX(Parameter!$F$3:$F$8,H23)),"") -> 110.75 | AH23: =IF(AND(N23="ganz",COUNTIFS($C$2:C23,C23,$H$2:H23,H23,$N$2:N23,"ganz")<=2),1,0) -> 1 | AI23: =IF(AND(N23="ganz",COUNTIFS($C$2:C23,C23,$J$2:J23,J23,$N$2:N23,"ganz")=1),1,0) -> 1 | AJ23: =IF(AND(O23="ja",COUNTIFS($C$2:C23,C23,$H$2:H23,H23,$O$2:O23,"ja")<=2),1,0) -> 1 | AK23: =IF(AND(O23="ja",COUNTIFS($C$2:C23,C23,$J$2:J23,J23,$O$2:O23,"ja")=1),1,0) -> 1
A24: 117 | B24: BW-05 | C24: BW-05 | E24: B | F24: 46236.907 | G24: So | H24: 2 | I24: 3 | J24: 4 | K24: 2 | L24: 2 | M24: 4 | N24: ganz | O24: ja | P24: 1 | Q24: 3 | R24: Drinnen | S24: nein | T24: nein | U24: nein | AA24: 39 | AB24: ja | AC24: =IF(C24=C23,(F24-F23)*24,"") -> 55.08 | AE24: =INDEX(Parameter!$C$3:$C$8,H24) -> 66 | AF24: =IF(AND(N24="ganz",INDEX(Parameter!$D$3:$D$8,H24)<>""),Q24*INDEX(Parameter!$D$3:$D$8,H24),"") -> 84.1 | AG24: =IF(AND(N24="ganz",INDEX(Parameter!$D$3:$D$8,H24)<>""),Q24*(INDEX(Parameter!$D$3:$D$8,H24)+INDEX(Parameter!$F$3:$F$8,H24)),"") -> 110.75 | AH24: =IF(AND(N24="ganz",COUNTIFS($C$2:C24,C24,$H$2:H24,H24,$N$2:N24,"ganz")<=2),1,0) -> 1 | AI24: =IF(AND(N24="ganz",COUNTIFS($C$2:C24,C24,$J$2:J24,J24,$N$2:N24,"ganz")=1),1,0) -> 1 | AJ24: =IF(AND(O24="ja",COUNTIFS($C$2:C24,C24,$H$2:H24,H24,$O$2:O24,"ja")<=2),1,0) -> 1 | AK24: =IF(AND(O24="ja",COUNTIFS($C$2:C24,C24,$J$2:J24,J24,$O$2:O24,"ja")=1),1,0) -> 1
A25: 144 | B25: BW-05 | C25: BW-05 | E25: B | F25: 46242.84 | G25: Sa | H25: 3 | I25: 3 | J25: 5 | K25: 3 | L25: 1 | M25: 5 | N25: ganz | O25: ja | P25: 1 | Q25: 3 | R25: Drinnen | S25: nein | T25: nein | U25: nein | AA25: 59 | AC25: =IF(C25=C24,(F25-F24)*24,"") -> 142.37639 | AE25: =INDEX(Parameter!$C$3:$C$8,H25) -> 80 | AF25: =IF(AND(N25="ganz",INDEX(Parameter!$D$3:$D$8,H25)<>""),Q25*INDEX(Parameter!$D$3:$D$8,H25),"") -> 72.85 | AG25: =IF(AND(N25="ganz",INDEX(Parameter!$D$3:$D$8,H25)<>""),Q25*(INDEX(Parameter!$D$3:$D$8,H25)+INDEX(Parameter!$F$3:$F$8,H25)),"") -> 99.5 | AH25: =IF(AND(N25="ganz",COUNTIFS($C$2:C25,C25,$H$2:H25,H25,$N$2:N25,"ganz")<=2),1,0) -> 1 | AI25: =IF(AND(N25="ganz",COUNTIFS($C$2:C25,C25,$J$2:J25,J25,$N$2:N25,"ganz")=1),1,0) -> 1 | AJ25: =IF(AND(O25="ja",COUNTIFS($C$2:C25,C25,$H$2:H25,H25,$O$2:O25,"ja")<=2),1,0) -> 1 | AK25: =IF(AND(O25="ja",COUNTIFS($C$2:C25,C25,$J$2:J25,J25,$O$2:O25,"ja")=1),1,0) -> 1
A26: 147 | B26: BW-05 | C26: BW-05 | E26: B | F26: 46243.745 | G26: So | H26: 3 | I26: 3 | J26: 6 | K26: 3 | L26: 2 | M26: 6 | N26: ganz | O26: ja | P26: 1 | Q26: 2 | R26: Drinnen | S26: nein | T26: nein | U26: nein | AA26: 42 | AC26: =IF(C26=C25,(F26-F25)*24,"") -> 21.7375 | AE26: =INDEX(Parameter!$C$3:$C$8,H26) -> 80 | AF26: =IF(AND(N26="ganz",INDEX(Parameter!$D$3:$D$8,H26)<>""),Q26*INDEX(Parameter!$D$3:$D$8,H26),"") -> 48.566667 | AG26: =IF(AND(N26="ganz",INDEX(Parameter!$D$3:$D$8,H26)<>""),Q26*(INDEX(Parameter!$D$3:$D$8,H26)+INDEX(Parameter!$F$3:$F$8,H26)),"") -> 66.333333 | AH26: =IF(AND(N26="ganz",COUNTIFS($C$2:C26,C26,$H$2:H26,H26,$N$2:N26,"ganz")<=2),1,0) -> 1 | AI26: =IF(AND(N26="ganz",COUNTIFS($C$2:C26,C26,$J$2:J26,J26,$N$2:N26,"ganz")=1),1,0) -> 1 | AJ26: =IF(AND(O26="ja",COUNTIFS($C$2:C26,C26,$H$2:H26,H26,$O$2:O26,"ja")<=2),1,0) -> 1 | AK26: =IF(AND(O26="ja",COUNTIFS($C$2:C26,C26,$J$2:J26,J26,$O$2:O26,"ja")=1),1,0) -> 1
A27: 181 | B27: BW-05 | C27: BW-05 | E27: B | F27: 46249.715 | G27: Sa | H27: 4 | I27: 4 | J27: 7 | K27: 4 | L27: 1 | M27: 7 | N27: ganz | O27: ja | P27: 1 | Q27: 2 | R27: Drinnen | S27: nein | T27: nein | U27: nein | AA27: 38 | AC27: =IF(C27=C26,(F27-F26)*24,"") -> 143.265 | AE27: =INDEX(Parameter!$C$3:$C$8,H27) -> 96 | AF27: =IF(AND(N27="ganz",INDEX(Parameter!$D$3:$D$8,H27)<>""),Q27*INDEX(Parameter!$D$3:$D$8,H27),"") -> 51.833333 | AG27: =IF(AND(N27="ganz",INDEX(Parameter!$D$3:$D$8,H27)<>""),Q27*(INDEX(Parameter!$D$3:$D$8,H27)+INDEX(Parameter!$F$3:$F$8,H27)),"") -> 69.6 | AH27: =IF(AND(N27="ganz",COUNTIFS($C$2:C27,C27,$H$2:H27,H27,$N$2:N27,"ganz")<=2),1,0) -> 1 | AI27: =IF(AND(N27="ganz",COUNTIFS($C$2:C27,C27,$J$2:J27,J27,$N$2:N27,"ganz")=1),1,0) -> 1 | AJ27: =IF(AND(O27="ja",COUNTIFS($C$2:C27,C27,$H$2:H27,H27,$O$2:O27,"ja")<=2),1,0) -> 1 | AK27: =IF(AND(O27="ja",COUNTIFS($C$2:C27,C27,$J$2:J27,J27,$O$2:O27,"ja")=1),1,0) -> 1
A28: 198 | B28: BW-05 | C28: BW-05 | E28: B | F28: 46250.843 | G28: So | H28: 4 | I28: 5 | J28: 8 | K28: 4 | L28: 2 | M28: 8 | N28: ganz | O28: ja | P28: 1 | Q28: 3 | R28: Drinnen | S28: nein | T28: nein | U28: nein | AA28: 39 | AB28: ja | AC28: =IF(C28=C27,(F28-F27)*24,"") -> 27.076944 | AE28: =INDEX(Parameter!$C$3:$C$8,H28) -> 96 | AF28: =IF(AND(N28="ganz",INDEX(Parameter!$D$3:$D$8,H28)<>""),Q28*INDEX(Parameter!$D$3:$D$8,H28),"") -> 77.75 | AG28: =IF(AND(N28="ganz",INDEX(Parameter!$D$3:$D$8,H28)<>""),Q28*(INDEX(Parameter!$D$3:$D$8,H28)+INDEX(Parameter!$F$3:$F$8,H28)),"") -> 104.4 | AH28: =IF(AND(N28="ganz",COUNTIFS($C$2:C28,C28,$H$2:H28,H28,$N$2:N28,"ganz")<=2),1,0) -> 1 | AI28: =IF(AND(N28="ganz",COUNTIFS($C$2:C28,C28,$J$2:J28,J28,$N$2:N28,"ganz")=1),1,0) -> 1 | AJ28: =IF(AND(O28="ja",COUNTIFS($C$2:C28,C28,$H$2:H28,H28,$O$2:O28,"ja")<=2),1,0) -> 1 | AK28: =IF(AND(O28="ja",COUNTIFS($C$2:C28,C28,$J$2:J28,J28,$O$2:O28,"ja")=1),1,0) -> 1
A29: 59 | B29: HL-06 | C29: BW-06 | D29: ja | E29: B | F29: 46228.732 | G29: Sa | H29: 1 | I29: 1 | J29: 1 | K29: 1 | L29: 1 | M29: 1 | N29: ganz | O29: ja | P29: 1 | Q29: 3 | R29: Drinnen | S29: nein | T29: nein | U29: nein | AA29: 54 | AC29: =IF(C29=C28,(F29-F28)*24,"") | AE29: =INDEX(Parameter!$C$3:$C$8,H29) -> 52 | AF29: =IF(AND(N29="ganz",INDEX(Parameter!$D$3:$D$8,H29)<>""),Q29*INDEX(Parameter!$D$3:$D$8,H29),"") -> 84.8 | AG29: =IF(AND(N29="ganz",INDEX(Parameter!$D$3:$D$8,H29)<>""),Q29*(INDEX(Parameter!$D$3:$D$8,H29)+INDEX(Parameter!$F$3:$F$8,H29)),"") -> 111.45 | AH29: =IF(AND(N29="ganz",COUNTIFS($C$2:C29,C29,$H$2:H29,H29,$N$2:N29,"ganz")<=2),1,0) -> 1 | AI29: =IF(AND(N29="ganz",COUNTIFS($C$2:C29,C29,$J$2:J29,J29,$N$2:N29,"ganz")=1),1,0) -> 1 | AJ29: =IF(AND(O29="ja",COUNTIFS($C$2:C29,C29,$H$2:H29,H29,$O$2:O29,"ja")<=2),1,0) -> 1 | AK29: =IF(AND(O29="ja",COUNTIFS($C$2:C29,C29,$J$2:J29,J29,$O$2:O29,"ja")=1),1,0) -> 1
A30: 70 | B30: HL-06 | C30: BW-06 | D30: ja | E30: B | F30: 46229.848 | G30: So | H30: 1 | I30: 2 | J30: 2 | K30: 1 | L30: 2 | M30: 2 | N30: teilweise | O30: ja | P30: 0 | Q30: 7 | R30: Drinnen | S30: ja | T30: nein | U30: nein | V30: Konnte die weitsprünge nicht machen, da ich zum wnde hin nur begrenzten platz hatte ich aber auch nucht abbrechen wollte | X30: Bisschen Muskelkater noch von der ersten Einheit | AA30: 53 | AB30: ja | AC30: =IF(C30=C29,(F30-F29)*24,"") -> 26.800278 | AE30: =INDEX(Parameter!$C$3:$C$8,H30) -> 52 | AF30: =IF(AND(N30="ganz",INDEX(Parameter!$D$3:$D$8,H30)<>""),Q30*INDEX(Parameter!$D$3:$D$8,H30),"") | AG30: =IF(AND(N30="ganz",INDEX(Parameter!$D$3:$D$8,H30)<>""),Q30*(INDEX(Parameter!$D$3:$D$8,H30)+INDEX(Parameter!$F$3:$F$8,H30)),"") | AH30: =IF(AND(N30="ganz",COUNTIFS($C$2:C30,C30,$H$2:H30,H30,$N$2:N30,"ganz")<=2),1,0) -> 0 | AI30: =IF(AND(N30="ganz",COUNTIFS($C$2:C30,C30,$J$2:J30,J30,$N$2:N30,"ganz")=1),1,0) -> 0 | AJ30: =IF(AND(O30="ja",COUNTIFS($C$2:C30,C30,$H$2:H30,H30,$O$2:O30,"ja")<=2),1,0) -> 1 | AK30: =IF(AND(O30="ja",COUNTIFS($C$2:C30,C30,$J$2:J30,J30,$O$2:O30,"ja")=1),1,0) -> 1
A31: 101 | B31: BW-06 | C31: BW-06 | E31: B | F31: 46235.937 | G31: Sa | H31: 2 | I31: 2 | J31: 3 | K31: 2 | L31: 1 | M31: 3 | N31: teilweise | O31: ja | P31: 0 | Q31: 4 | R31: Rasen/Wiese | S31: nein | T31: nein | U31: ja | V31: Letzte paar minuten | Z31: Fussball platz einmal und laufen einmal | AA31: 44 | AC31: =IF(C31=C30,(F31-F30)*24,"") -> 146.12139 | AE31: =INDEX(Parameter!$C$3:$C$8,H31) -> 66 | AF31: =IF(AND(N31="ganz",INDEX(Parameter!$D$3:$D$8,H31)<>""),Q31*INDEX(Parameter!$D$3:$D$8,H31),"") | AG31: =IF(AND(N31="ganz",INDEX(Parameter!$D$3:$D$8,H31)<>""),Q31*(INDEX(Parameter!$D$3:$D$8,H31)+INDEX(Parameter!$F$3:$F$8,H31)),"") | AH31: =IF(AND(N31="ganz",COUNTIFS($C$2:C31,C31,$H$2:H31,H31,$N$2:N31,"ganz")<=2),1,0) -> 0 | AI31: =IF(AND(N31="ganz",COUNTIFS($C$2:C31,C31,$J$2:J31,J31,$N$2:N31,"ganz")=1),1,0) -> 0 | AJ31: =IF(AND(O31="ja",COUNTIFS($C$2:C31,C31,$H$2:H31,H31,$O$2:O31,"ja")<=2),1,0) -> 1 | AK31: =IF(AND(O31="ja",COUNTIFS($C$2:C31,C31,$J$2:J31,J31,$O$2:O31,"ja")=1),1,0) -> 1
A32: 116 | B32: BW-06 | C32: BW-06 | E32: B | F32: 46236.879 | G32: So | H32: 2 | I32: 3 | J32: 4 | K32: 2 | L32: 2 | N32: gar nicht | O32: nein | P32: 0 | Q32: 0 | R32: Anderes | S32: ja | T32: nein | U32: ja | W32: Schmerzen | X32: Knie und oberschenkel | Z32: Fussball und laufen | AA32: 43 | AB32: ja | AC32: =IF(C32=C31,(F32-F31)*24,"") -> 22.615556 | AE32: =INDEX(Parameter!$C$3:$C$8,H32) -> 66 | AF32: =IF(AND(N32="ganz",INDEX(Parameter!$D$3:$D$8,H32)<>""),Q32*INDEX(Parameter!$D$3:$D$8,H32),"") | AG32: =IF(AND(N32="ganz",INDEX(Parameter!$D$3:$D$8,H32)<>""),Q32*(INDEX(Parameter!$D$3:$D$8,H32)+INDEX(Parameter!$F$3:$F$8,H32)),"") | AH32: =IF(AND(N32="ganz",COUNTIFS($C$2:C32,C32,$H$2:H32,H32,$N$2:N32,"ganz")<=2),1,0) -> 0 | AI32: =IF(AND(N32="ganz",COUNTIFS($C$2:C32,C32,$J$2:J32,J32,$N$2:N32,"ganz")=1),1,0) -> 0 | AJ32: =IF(AND(O32="ja",COUNTIFS($C$2:C32,C32,$H$2:H32,H32,$O$2:O32,"ja")<=2),1,0) -> 0 | AK32: =IF(AND(O32="ja",COUNTIFS($C$2:C32,C32,$J$2:J32,J32,$O$2:O32,"ja")=1),1,0) -> 0
A33: 187 | B33: BW-06 | C33: BW-06 | E33: B | F33: 46250.565 | G33: So | H33: 4 | I33: 4 | J33: 7 | K33: 4 | L33: 1 | M33: 7 | N33: ganz | O33: ja | P33: 1 | Q33: 4 | R33: Drinnen | S33: nein | T33: ja | U33: ja | Y33: 2 mal | Z33: 2 mal Training | AA33: 52 | AC33: =IF(C33=C32,(F33-F32)*24,"") -> 328.46889 | AE33: =INDEX(Parameter!$C$3:$C$8,H33) -> 96 | AF33: =IF(AND(N33="ganz",INDEX(Parameter!$D$3:$D$8,H33)<>""),Q33*INDEX(Parameter!$D$3:$D$8,H33),"") -> 103.66667 | AG33: =IF(AND(N33="ganz",INDEX(Parameter!$D$3:$D$8,H33)<>""),Q33*(INDEX(Parameter!$D$3:$D$8,H33)+INDEX(Parameter!$F$3:$F$8,H33)),"") -> 139.2 | AH33: =IF(AND(N33="ganz",COUNTIFS($C$2:C33,C33,$H$2:H33,H33,$N$2:N33,"ganz")<=2),1,0) -> 1 | AI33: =IF(AND(N33="ganz",COUNTIFS($C$2:C33,C33,$J$2:J33,J33,$N$2:N33,"ganz")=1),1,0) -> 1 | AJ33: =IF(AND(O33="ja",COUNTIFS($C$2:C33,C33,$H$2:H33,H33,$O$2:O33,"ja")<=2),1,0) -> 1 | AK33: =IF(AND(O33="ja",COUNTIFS($C$2:C33,C33,$J$2:J33,J33,$O$2:O33,"ja")=1),1,0) -> 1
A34: 39 | B34: BW-07 | C34: BW-07 | E34: B | F34: 46226.877 | G34: Do | H34: 1 | I34: 1 | J34: 1 | K34: 1 | L34: 1 | M34: 1 | N34: ganz | O34: ja | P34: 1 | Q34: 2 | R34: Drinnen | S34: nein | T34: ja | U34: nein | Y34: 4 | AA34: 52 | AC34: =IF(C34=C33,(F34-F33)*24,"") | AE34: =INDEX(Parameter!$C$3:$C$8,H34) -> 52 | AF34: =IF(AND(N34="ganz",INDEX(Parameter!$D$3:$D$8,H34)<>""),Q34*INDEX(Parameter!$D$3:$D$8,H34),"") -> 56.533333 | AG34: =IF(AND(N34="ganz",INDEX(Parameter!$D$3:$D$8,H34)<>""),Q34*(INDEX(Parameter!$D$3:$D$8,H34)+INDEX(Parameter!$F$3:$F$8,H34)),"") -> 74.3 | AH34: =IF(AND(N34="ganz",COUNTIFS($C$2:C34,C34,$H$2:H34,H34,$N$2:N34,"ganz")<=2),1,0) -> 1 | AI34: =IF(AND(N34="ganz",COUNTIFS($C$2:C34,C34,$J$2:J34,J34,$N$2:N34,"ganz")=1),1,0) -> 1 | AJ34: =IF(AND(O34="ja",COUNTIFS($C$2:C34,C34,$H$2:H34,H34,$O$2:O34,"ja")<=2),1,0) -> 1 | AK34: =IF(AND(O34="ja",COUNTIFS($C$2:C34,C34,$J$2:J34,J34,$O$2:O34,"ja")=1),1,0) -> 1
A35: 48 | B35: BW-07 | C35: BW-07 | E35: B | F35: 46227.76 | G35: Fr | H35: 1 | I35: 1 | J35: 2 | K35: 1 | L35: 2 | M35: 2 | N35: ganz | O35: ja | P35: 1 | Q35: 3 | R35: Drinnen | S35: nein | T35: nein | U35: ja | Z35: Joggen 1 mal | AA35: 51 | AC35: =IF(C35=C34,(F35-F34)*24,"") -> 21.206667 | AE35: =INDEX(Parameter!$C$3:$C$8,H35) -> 52 | AF35: =IF(AND(N35="ganz",INDEX(Parameter!$D$3:$D$8,H35)<>""),Q35*INDEX(Parameter!$D$3:$D$8,H35),"") -> 84.8 | AG35: =IF(AND(N35="ganz",INDEX(Parameter!$D$3:$D$8,H35)<>""),Q35*(INDEX(Parameter!$D$3:$D$8,H35)+INDEX(Parameter!$F$3:$F$8,H35)),"") -> 111.45 | AH35: =IF(AND(N35="ganz",COUNTIFS($C$2:C35,C35,$H$2:H35,H35,$N$2:N35,"ganz")<=2),1,0) -> 1 | AI35: =IF(AND(N35="ganz",COUNTIFS($C$2:C35,C35,$J$2:J35,J35,$N$2:N35,"ganz")=1),1,0) -> 1 | AJ35: =IF(AND(O35="ja",COUNTIFS($C$2:C35,C35,$H$2:H35,H35,$O$2:O35,"ja")<=2),1,0) -> 1 | AK35: =IF(AND(O35="ja",COUNTIFS($C$2:C35,C35,$J$2:J35,J35,$O$2:O35,"ja")=1),1,0) -> 1
A36: 188 | B36: BW-07 | C36: BW-07 | E36: B | F36: 46250.567 | G36: So | H36: 4 | I36: 4 | J36: 7 | K36: 4 | L36: 1 | M36: 7 | N36: ganz | O36: ja | P36: 1 | Q36: 3 | R36: Drinnen | S36: nein | T36: ja | U36: ja | Y36: ca 3-6 mal | Z36: Fußball und Joggen | AA36: 63 | AC36: =IF(C36=C35,(F36-F35)*24,"") -> 547.35889 | AD36: Sammelmeldung (Paar mit CASE 189, Δ 4 min) | AE36: =INDEX(Parameter!$C$3:$C$8,H36) -> 96 | AF36: =IF(AND(N36="ganz",INDEX(Parameter!$D$3:$D$8,H36)<>""),Q36*INDEX(Parameter!$D$3:$D$8,H36),"") -> 77.75 | AG36: =IF(AND(N36="ganz",INDEX(Parameter!$D$3:$D$8,H36)<>""),Q36*(INDEX(Parameter!$D$3:$D$8,H36)+INDEX(Parameter!$F$3:$F$8,H36)),"") -> 104.4 | AH36: =IF(AND(N36="ganz",COUNTIFS($C$2:C36,C36,$H$2:H36,H36,$N$2:N36,"ganz")<=2),1,0) -> 1 | AI36: =IF(AND(N36="ganz",COUNTIFS($C$2:C36,C36,$J$2:J36,J36,$N$2:N36,"ganz")=1),1,0) -> 1 | AJ36: =IF(AND(O36="ja",COUNTIFS($C$2:C36,C36,$H$2:H36,H36,$O$2:O36,"ja")<=2),1,0) -> 1 | AK36: =IF(AND(O36="ja",COUNTIFS($C$2:C36,C36,$J$2:J36,J36,$O$2:O36,"ja")=1),1,0) -> 1
A37: 189 | B37: BW-07 | C37: BW-07 | E37: B | F37: 46250.57 | G37: So | H37: 4 | I37: 4 | J37: 8 | K37: 4 | L37: 2 | M37: 8 | N37: ganz | O37: ja | P37: 1 | Q37: 4 | R37: Drinnen | S37: nein | T37: ja | U37: ja | Y37: 3-6 | Z37: Einmal Joggen | AA37: 56 | AC37: =IF(C37=C36,(F37-F36)*24,"") -> 0.065555556 | AD37: Sammelmeldung (Paar mit CASE 188, Δ 4 min) | AE37: =INDEX(Parameter!$C$3:$C$8,H37) -> 96 | AF37: =IF(AND(N37="ganz",INDEX(Parameter!$D$3:$D$8,H37)<>""),Q37*INDEX(Parameter!$D$3:$D$8,H37),"") -> 103.66667 | AG37: =IF(AND(N37="ganz",INDEX(Parameter!$D$3:$D$8,H37)<>""),Q37*(INDEX(Parameter!$D$3:$D$8,H37)+INDEX(Parameter!$F$3:$F$8,H37)),"") -> 139.2 | AH37: =IF(AND(N37="ganz",COUNTIFS($C$2:C37,C37,$H$2:H37,H37,$N$2:N37,"ganz")<=2),1,0) -> 1 | AI37: =IF(AND(N37="ganz",COUNTIFS($C$2:C37,C37,$J$2:J37,J37,$N$2:N37,"ganz")=1),1,0) -> 1 | AJ37: =IF(AND(O37="ja",COUNTIFS($C$2:C37,C37,$H$2:H37,H37,$O$2:O37,"ja")<=2),1,0) -> 1 | AK37: =IF(AND(O37="ja",COUNTIFS($C$2:C37,C37,$J$2:J37,J37,$O$2:O37,"ja")=1),1,0) -> 1
A38: 217 | B38: BW-07 | C38: BW-07 | E38: B | F38: 46255.854 | G38: Fr | H38: 5 | I38: 5 | J38: 9 | K38: 5 | L38: 1 | M38: 9 | N38: ganz | O38: ja | P38: 1 | Q38: 4 | R38: Drinnen | S38: nein | T38: ja | U38: ja | Y38: 3 | Z38: Training Fussball 2 | AA38: 76 | AC38: =IF(C38=C37,(F38-F37)*24,"") -> 126.83444 | AE38: =INDEX(Parameter!$C$3:$C$8,H38) -> 106 | AF38: =IF(AND(N38="ganz",INDEX(Parameter!$D$3:$D$8,H38)<>""),Q38*INDEX(Parameter!$D$3:$D$8,H38),"") | AG38: =IF(AND(N38="ganz",INDEX(Parameter!$D$3:$D$8,H38)<>""),Q38*(INDEX(Parameter!$D$3:$D$8,H38)+INDEX(Parameter!$F$3:$F$8,H38)),"") | AH38: =IF(AND(N38="ganz",COUNTIFS($C$2:C38,C38,$H$2:H38,H38,$N$2:N38,"ganz")<=2),1,0) -> 1 | AI38: =IF(AND(N38="ganz",COUNTIFS($C$2:C38,C38,$J$2:J38,J38,$N$2:N38,"ganz")=1),1,0) -> 1 | AJ38: =IF(AND(O38="ja",COUNTIFS($C$2:C38,C38,$H$2:H38,H38,$O$2:O38,"ja")<=2),1,0) -> 1 | AK38: =IF(AND(O38="ja",COUNTIFS($C$2:C38,C38,$J$2:J38,J38,$O$2:O38,"ja")=1),1,0) -> 1
A39: 246 | B39: BW-07 | C39: BW-07 | E39: B | F39: 46262.557 | G39: Fr | H39: 6 | I39: 6 | J39: 11 | K39: 6 | L39: 1 | M39: 11 | N39: ganz | O39: ja | P39: 1 | Q39: 4 | R39: Drinnen | S39: nein | T39: ja | U39: ja | Y39: 6 | Z39: Training 2x und ein Spiel | AA39: 48 | AC39: =IF(C39=C38,(F39-F38)*24,"") -> 160.8525 | AE39: =INDEX(Parameter!$C$3:$C$8,H39) -> 120 | AF39: =IF(AND(N39="ganz",INDEX(Parameter!$D$3:$D$8,H39)<>""),Q39*INDEX(Parameter!$D$3:$D$8,H39),"") -> 124.2 | AG39: =IF(AND(N39="ganz",INDEX(Parameter!$D$3:$D$8,H39)<>""),Q39*(INDEX(Parameter!$D$3:$D$8,H39)+INDEX(Parameter!$F$3:$F$8,H39)),"") -> 159.73333 | AH39: =IF(AND(N39="ganz",COUNTIFS($C$2:C39,C39,$H$2:H39,H39,$N$2:N39,"ganz")<=2),1,0) -> 1 | AI39: =IF(AND(N39="ganz",COUNTIFS($C$2:C39,C39,$J$2:J39,J39,$N$2:N39,"ganz")=1),1,0) -> 1 | AJ39: =IF(AND(O39="ja",COUNTIFS($C$2:C39,C39,$H$2:H39,H39,$O$2:O39,"ja")<=2),1,0) -> 1 | AK39: =IF(AND(O39="ja",COUNTIFS($C$2:C39,C39,$J$2:J39,J39,$O$2:O39,"ja")=1),1,0) -> 1
A40: 46 | B40: BW-08 | C40: BW-08 | E40: B | F40: 46227.727 | G40: Fr | H40: 1 | I40: 1 | J40: 1 | K40: 1 | L40: 1 | M40: 1 | N40: ganz | O40: ja | P40: 1 | Q40: 3 | R40: Drinnen | S40: nein | T40: nein | U40: nein | AA40: 62 | AC40: =IF(C40=C39,(F40-F39)*24,"") | AE40: =INDEX(Parameter!$C$3:$C$8,H40) -> 52 | AF40: =IF(AND(N40="ganz",INDEX(Parameter!$D$3:$D$8,H40)<>""),Q40*INDEX(Parameter!$D$3:$D$8,H40),"") -> 84.8 | AG40: =IF(AND(N40="ganz",INDEX(Parameter!$D$3:$D$8,H40)<>""),Q40*(INDEX(Parameter!$D$3:$D$8,H40)+INDEX(Parameter!$F$3:$F$8,H40)),"") -> 111.45 | AH40: =IF(AND(N40="ganz",COUNTIFS($C$2:C40,C40,$H$2:H40,H40,$N$2:N40,"ganz")<=2),1,0) -> 1 | AI40: =IF(AND(N40="ganz",COUNTIFS($C$2:C40,C40,$J$2:J40,J40,$N$2:N40,"ganz")=1),1,0) -> 1 | AJ40: =IF(AND(O40="ja",COUNTIFS($C$2:C40,C40,$H$2:H40,H40,$O$2:O40,"ja")<=2),1,0) -> 1 | AK40: =IF(AND(O40="ja",COUNTIFS($C$2:C40,C40,$J$2:J40,J40,$O$2:O40,"ja")=1),1,0) -> 1
...

Sheet Spieler
A1: Code | B1: Verein | C1: Status Workbook | D1: Familiarisierung | E1: %PAH | F1: Meldungen | G1: ganz je Meldung (Haupt) | H1: ganz wochen-gedeckelt | I1: ganz distinkte H003 | J1: teilweise | K1: gar nicht | L1: ganz+teilw. je Meldung | M1: ganz+teilw. wochen-gedeckelt | N1: ganz+teilw. distinkte H003 | O1: Umsetzungsrate ganz (von 12) | P1: Beteiligungsrate ganz+teilw. (von 12) | Q1: ≥ 6 (Per-Protokoll) | R1: ≥ 9 (Antragskriterium) | S1: CR-10 M (ganz) | T1: CR-10 Median (ganz) | U1: sRPE-Load I Σ (AU, ohne W5) | V1: sRPE-Load II Σ (AU, ohne W5) | W1: Einheiten in W5 (Load offen) | X1: Untergrund Modalwert (durchgef.) | Y1: Videopausen (Meld.) | Z1: Fremdtraining (Meld.) | AA1: Schmerzmeldungen | AB1: Klasse / Bemerkung
A2: BW-01 | B2: B | C2: ausgewertet | D2: 1 | E2: 91.58 | F2: =COUNTIF(Meldungen!$C$2:$C$112,$A2) -> 0 | G2: =COUNTIFS(Meldungen!$C$2:$C$112,$A2,Meldungen!$N$2:$N$112,"ganz") -> 0 | H2: =SUMIFS(Meldungen!$AH$2:$AH$112,Meldungen!$C$2:$C$112,$A2) -> 0 | I2: =SUMIFS(Meldungen!$AI$2:$AI$112,Meldungen!$C$2:$C$112,$A2) -> 0 | J2: =COUNTIFS(Meldungen!$C$2:$C$112,$A2,Meldungen!$N$2:$N$112,"teilweise") -> 0 | K2: =COUNTIFS(Meldungen!$C$2:$C$112,$A2,Meldungen!$N$2:$N$112,"gar nicht") -> 0 | L2: =COUNTIFS(Meldungen!$C$2:$C$112,$A2,Meldungen!$O$2:$O$112,"ja") -> 0 | M2: =SUMIFS(Meldungen!$AJ$2:$AJ$112,Meldungen!$C$2:$C$112,$A2) -> 0 | N2: =SUMIFS(Meldungen!$AK$2:$AK$112,Meldungen!$C$2:$C$112,$A2) -> 0 | O2: =G2/12 -> 0 | P2: =L2/12 -> 0 | Q2: =IF(G2>=6,"ja","nein") -> nein | R2: =IF(G2>=9,"ja","nein") -> nein | S2: =IFERROR(AVERAGEIFS(Meldungen!$Q$2:$Q$112,Meldungen!$C$2:$C$112,$A2,Meldungen!$N$2:$N$112,"ganz"),"") | U2: =SUMIFS(Meldungen!$AF$2:$AF$112,Meldungen!$C$2:$C$112,$A2) -> 0 | V2: =SUMIFS(Meldungen!$AG$2:$AG$112,Meldungen!$C$2:$C$112,$A2) -> 0 | W2: =COUNTIFS(Meldungen!$C$2:$C$112,$A2,Meldungen!$N$2:$N$112,"ganz",Meldungen!$H$2:$H$112,5) -> 0 | X2: — | Y2: =COUNTIFS(Meldungen!$C$2:$C$112,$A2,Meldungen!$T$2:$T$112,"ja") -> 0 | Z2: =COUNTIFS(Meldungen!$C$2:$C$112,$A2,Meldungen!$U$2:$U$112,"ja") -> 0 | AA2: =COUNTIFS(Meldungen!$C$2:$C$112,$A2,Meldungen!$S$2:$S$112,"ja") -> 0 | AB2: Nichteinhaltung — keine Meldung; Post-Werte vorhanden (ITT ja, PP nein)
A3: BW-02 | B3: B | C3: ausgewertet | D3: 1 | E3: 97.17 | F3: =COUNTIF(Meldungen!$C$2:$C$112,$A3) -> 12 | G3: =COUNTIFS(Meldungen!$C$2:$C$112,$A3,Meldungen!$N$2:$N$112,"ganz") -> 12 | H3: =SUMIFS(Meldungen!$AH$2:$AH$112,Meldungen!$C$2:$C$112,$A3) -> 12 | I3: =SUMIFS(Meldungen!$AI$2:$AI$112,Meldungen!$C$2:$C$112,$A3) -> 12 | J3: =COUNTIFS(Meldungen!$C$2:$C$112,$A3,Meldungen!$N$2:$N$112,"teilweise") -> 0 | K3: =COUNTIFS(Meldungen!$C$2:$C$112,$A3,Meldungen!$N$2:$N$112,"gar nicht") -> 0 | L3: =COUNTIFS(Meldungen!$C$2:$C$112,$A3,Meldungen!$O$2:$O$112,"ja") -> 12 | M3: =SUMIFS(Meldungen!$AJ$2:$AJ$112,Meldungen!$C$2:$C$112,$A3) -> 12 | N3: =SUMIFS(Meldungen!$AK$2:$AK$112,Meldungen!$C$2:$C$112,$A3) -> 12 | O3: =G3/12 -> 1 | P3: =L3/12 -> 1 | Q3: =IF(G3>=6,"ja","nein") -> ja | R3: =IF(G3>=9,"ja","nein") -> ja | S3: =IFERROR(AVERAGEIFS(Meldungen!$Q$2:$Q$112,Meldungen!$C$2:$C$112,$A3,Meldungen!$N$2:$N$112,"ganz"),"") -> 2.3333333 | T3: 2 | U3: =SUMIFS(Meldungen!$AF$2:$AF$112,Meldungen!$C$2:$C$112,$A3) -> 685.68333 | V3: =SUMIFS(Meldungen!$AG$2:$AG$112,Meldungen!$C$2:$C$112,$A3) -> 907.76667 | W3: =COUNTIFS(Meldungen!$C$2:$C$112,$A3,Meldungen!$N$2:$N$112,"ganz",Meldungen!$H$2:$H$112,5) -> 2 | X3: Kunstrasen (6/12) | Y3: =COUNTIFS(Meldungen!$C$2:$C$112,$A3,Meldungen!$T$2:$T$112,"ja") -> 1 | Z3: =COUNTIFS(Meldungen!$C$2:$C$112,$A3,Meldungen!$U$2:$U$112,"ja") -> 11 | AA3: =COUNTIFS(Meldungen!$C$2:$C$112,$A3,Meldungen!$S$2:$S$112,"ja") -> 1
A4: BW-04 | B4: B | C4: ausgewertet | D4: 2 | E4: 94.81 | F4: =COUNTIF(Meldungen!$C$2:$C$112,$A4) -> 7 | G4: =COUNTIFS(Meldungen!$C$2:$C$112,$A4,Meldungen!$N$2:$N$112,"ganz") -> 6 | H4: =SUMIFS(Meldungen!$AH$2:$AH$112,Meldungen!$C$2:$C$112,$A4) -> 5 | I4: =SUMIFS(Meldungen!$AI$2:$AI$112,Meldungen!$C$2:$C$112,$A4) -> 6 | J4: =COUNTIFS(Meldungen!$C$2:$C$112,$A4,Meldungen!$N$2:$N$112,"teilweise") -> 1 | K4: =COUNTIFS(Meldungen!$C$2:$C$112,$A4,Meldungen!$N$2:$N$112,"gar nicht") -> 0 | L4: =COUNTIFS(Meldungen!$C$2:$C$112,$A4,Meldungen!$O$2:$O$112,"ja") -> 7 | M4: =SUMIFS(Meldungen!$AJ$2:$AJ$112,Meldungen!$C$2:$C$112,$A4) -> 6 | N4: =SUMIFS(Meldungen!$AK$2:$AK$112,Meldungen!$C$2:$C$112,$A4) -> 6 | O4: =G4/12 -> 0.5 | P4: =L4/12 -> 0.58333333 | Q4: =IF(G4>=6,"ja","nein") -> ja | R4: =IF(G4>=9,"ja","nein") -> nein | S4: =IFERROR(AVERAGEIFS(Meldungen!$Q$2:$Q$112,Meldungen!$C$2:$C$112,$A4,Meldungen!$N$2:$N$112,"ganz"),"") -> 1.3333333 | T4: 1.5 | U4: =SUMIFS(Meldungen!$AF$2:$AF$112,Meldungen!$C$2:$C$112,$A4) -> 183.28333 | V4: =SUMIFS(Meldungen!$AG$2:$AG$112,Meldungen!$C$2:$C$112,$A4) -> 245.46667 | W4: =COUNTIFS(Meldungen!$C$2:$C$112,$A4,Meldungen!$N$2:$N$112,"ganz",Meldungen!$H$2:$H$112,5) -> 1 | X4: Rasen/Wiese (4/7) | Y4: =COUNTIFS(Meldungen!$C$2:$C$112,$A4,Meldungen!$T$2:$T$112,"ja") -> 1 | Z4: =COUNTIFS(Meldungen!$C$2:$C$112,$A4,Meldungen!$U$2:$U$112,"ja") -> 4 | AA4: =COUNTIFS(Meldungen!$C$2:$C$112,$A4,Meldungen!$S$2:$S$112,"ja") -> 1 | AB4: W4 drei „ganz“-Meldungen (Deckelung greift); 5 Meldungen CASE-korrigiert von HL-04
A5: BW-05 | B5: B | C5: ausgewertet | D5: 2 | E5: 93.96 | F5: =COUNTIF(Meldungen!$C$2:$C$112,$A5) -> 8 | G5: =COUNTIFS(Meldungen!$C$2:$C$112,$A5,Meldungen!$N$2:$N$112,"ganz") -> 7 | H5: =SUMIFS(Meldungen!$AH$2:$AH$112,Meldungen!$C$2:$C$112,$A5) -> 7 | I5: =SUMIFS(Meldungen!$AI$2:$AI$112,Meldungen!$C$2:$C$112,$A5) -> 7 | J5: =COUNTIFS(Meldungen!$C$2:$C$112,$A5,Meldungen!$N$2:$N$112,"teilweise") -> 0 | K5: =COUNTIFS(Meldungen!$C$2:$C$112,$A5,Meldungen!$N$2:$N$112,"gar nicht") -> 1 | L5: =COUNTIFS(Meldungen!$C$2:$C$112,$A5,Meldungen!$O$2:$O$112,"ja") -> 7 | M5: =SUMIFS(Meldungen!$AJ$2:$AJ$112,Meldungen!$C$2:$C$112,$A5) -> 7 | N5: =SUMIFS(Meldungen!$AK$2:$AK$112,Meldungen!$C$2:$C$112,$A5) -> 7 | O5: =G5/12 -> 0.58333333 | P5: =L5/12 -> 0.58333333 | Q5: =IF(G5>=6,"ja","nein") -> ja | R5: =IF(G5>=9,"ja","nein") -> nein | S5: =IFERROR(AVERAGEIFS(Meldungen!$Q$2:$Q$112,Meldungen!$C$2:$C$112,$A5,Meldungen!$N$2:$N$112,"ganz"),"") -> 2.5714286 | T5: 3 | U5: =SUMIFS(Meldungen!$AF$2:$AF$112,Meldungen!$C$2:$C$112,$A5) -> 475.73333 | V5: =SUMIFS(Meldungen!$AG$2:$AG$112,Meldungen!$C$2:$C$112,$A5) -> 635.63333 | W5: =COUNTIFS(Meldungen!$C$2:$C$112,$A5,Meldungen!$N$2:$N$112,"ganz",Meldungen!$H$2:$H$112,5) -> 0 | X5: Drinnen (7/7) | Y5: =COUNTIFS(Meldungen!$C$2:$C$112,$A5,Meldungen!$T$2:$T$112,"ja") -> 0 | Z5: =COUNTIFS(Meldungen!$C$2:$C$112,$A5,Meldungen!$U$2:$U$112,"ja") -> 0 | AA5: =COUNTIFS(Meldungen!$C$2:$C$112,$A5,Meldungen!$S$2:$S$112,"ja") -> 0
A6: BW-06 | B6: B | C6: ausgewertet | D6: 2 | E6: 86.65 | F6: =COUNTIF(Meldungen!$C$2:$C$112,$A6) -> 5 | G6: =COUNTIFS(Meldungen!$C$2:$C$112,$A6,Meldungen!$N$2:$N$112,"ganz") -> 2 | H6: =SUMIFS(Meldungen!$AH$2:$AH$112,Meldungen!$C$2:$C$112,$A6) -> 2 | I6: =SUMIFS(Meldungen!$AI$2:$AI$112,Meldungen!$C$2:$C$112,$A6) -> 2 | J6: =COUNTIFS(Meldungen!$C$2:$C$112,$A6,Meldungen!$N$2:$N$112,"teilweise") -> 2 | K6: =COUNTIFS(Meldungen!$C$2:$C$112,$A6,Meldungen!$N$2:$N$112,"gar nicht") -> 1 | L6: =COUNTIFS(Meldungen!$C$2:$C$112,$A6,Meldungen!$O$2:$O$112,"ja") -> 4 | M6: =SUMIFS(Meldungen!$AJ$2:$AJ$112,Meldungen!$C$2:$C$112,$A6) -> 4 | N6: =SUMIFS(Meldungen!$AK$2:$AK$112,Meldungen!$C$2:$C$112,$A6) -> 4 | O6: =G6/12 -> 0.16666667 | P6: =L6/12 -> 0.33333333 | Q6: =IF(G6>=6,"ja","nein") -> nein | R6: =IF(G6>=9,"ja","nein") -> nein | S6: =IFERROR(AVERAGEIFS(Meldungen!$Q$2:$Q$112,Meldungen!$C$2:$C$112,$A6,Meldungen!$N$2:$N$112,"ganz"),"") -> 3.5 | T6: 3.5 | U6: =SUMIFS(Meldungen!$AF$2:$AF$112,Meldungen!$C$2:$C$112,$A6) -> 188.46667 | V6: =SUMIFS(Meldungen!$AG$2:$AG$112,Meldungen!$C$2:$C$112,$A6) -> 250.65 | W6: =COUNTIFS(Meldungen!$C$2:$C$112,$A6,Meldungen!$N$2:$N$112,"ganz",Meldungen!$H$2:$H$112,5) -> 0 | X6: Drinnen (3/4) | Y6: =COUNTIFS(Meldungen!$C$2:$C$112,$A6,Meldungen!$T$2:$T$112,"ja") -> 1 | Z6: =COUNTIFS(Meldungen!$C$2:$C$112,$A6,Meldungen!$U$2:$U$112,"ja") -> 3 | AA6: =COUNTIFS(Meldungen!$C$2:$C$112,$A6,Meldungen!$S$2:$S$112,"ja") -> 2 | AB6: 2 Meldungen CASE-korrigiert von BW-04; teilweise ×2
A7: BW-07 | B7: B | C7: Post nicht angetreten | D7: 2 | E7: 92.16 | F7: =COUNTIF(Meldungen!$C$2:$C$112,$A7) -> 6 | G7: =COUNTIFS(Meldungen!$C$2:$C$112,$A7,Meldungen!$N$2:$N$112,"ganz") -> 6 | H7: =SUMIFS(Meldungen!$AH$2:$AH$112,Meldungen!$C$2:$C$112,$A7) -> 6 | I7: =SUMIFS(Meldungen!$AI$2:$AI$112,Meldungen!$C$2:$C$112,$A7) -> 6 | J7: =COUNTIFS(Meldungen!$C$2:$C$112,$A7,Meldungen!$N$2:$N$112,"teilweise") -> 0 | K7: =COUNTIFS(Meldungen!$C$2:$C$112,$A7,Meldungen!$N$2:$N$112,"gar nicht") -> 0 | L7: =COUNTIFS(Meldungen!$C$2:$C$112,$A7,Meldungen!$O$2:$O$112,"ja") -> 6 | M7: =SUMIFS(Meldungen!$AJ$2:$AJ$112,Meldungen!$C$2:$C$112,$A7) -> 6 | N7: =SUMIFS(Meldungen!$AK$2:$AK$112,Meldungen!$C$2:$C$112,$A7) -> 6 | O7: =G7/12 -> 0.5 | P7: =L7/12 -> 0.5 | Q7: =IF(G7>=6,"ja","nein") -> ja | R7: =IF(G7>=9,"ja","nein") -> nein | S7: =IFERROR(AVERAGEIFS(Meldungen!$Q$2:$Q$112,Meldungen!$C$2:$C$112,$A7,Meldungen!$N$2:$N$112,"ganz"),"") -> 3.3333333 | T7: 3.5 | U7: =SUMIFS(Meldungen!$AF$2:$AF$112,Meldungen!$C$2:$C$112,$A7) -> 446.95 | V7: =SUMIFS(Meldungen!$AG$2:$AG$112,Meldungen!$C$2:$C$112,$A7) -> 589.08333 | W7: =COUNTIFS(Meldungen!$C$2:$C$112,$A7,Meldungen!$N$2:$N$112,"ganz",Meldungen!$H$2:$H$112,5) -> 1 | X7: Drinnen (6/6) | Y7: =COUNTIFS(Meldungen!$C$2:$C$112,$A7,Meldungen!$T$2:$T$112,"ja") -> 5 | Z7: =COUNTIFS(Meldungen!$C$2:$C$112,$A7,Meldungen!$U$2:$U$112,"ja") -> 5 | AA7: =COUNTIFS(Meldungen!$C$2:$C$112,$A7,Meldungen!$S$2:$S$112,"ja") -> 0 | AB7: Post-Testung nicht angetreten — 6 vollständige Einheiten, keine Ergebnisanalyse
A8: BW-08 | B8: B | C8: ausgewertet | D8: 2 | E8: 96.72 | F8: =COUNTIF(Meldungen!$C$2:$C$112,$A8) -> 9 | G8: =COUNTIFS(Meldungen!$C$2:$C$112,$A8,Meldungen!$N$2:$N$112,"ganz") -> 9 | H8: =SUMIFS(Meldungen!$AH$2:$AH$112,Meldungen!$C$2:$C$112,$A8) -> 8 | I8: =SUMIFS(Meldungen!$AI$2:$AI$112,Meldungen!$C$2:$C$112,$A8) -> 8 | J8: =COUNTIFS(Meldungen!$C$2:$C$112,$A8,Meldungen!$N$2:$N$112,"teilweise") -> 0 | K8: =COUNTIFS(Meldungen!$C$2:$C$112,$A8,Meldungen!$N$2:$N$112,"gar nicht") -> 0 | L8: =COUNTIFS(Meldungen!$C$2:$C$112,$A8,Meldungen!$O$2:$O$112,"ja") -> 9 | M8: =SUMIFS(Meldungen!$AJ$2:$AJ$112,Meldungen!$C$2:$C$112,$A8) -> 8 | N8: =SUMIFS(Meldungen!$AK$2:$AK$112,Meldungen!$C$2:$C$112,$A8) -> 8 | O8: =G8/12 -> 0.75 | P8: =L8/12 -> 0.75 | Q8: =IF(G8>=6,"ja","nein") -> ja | R8: =IF(G8>=9,"ja","nein") -> ja | S8: =IFERROR(AVERAGEIFS(Meldungen!$Q$2:$Q$112,Meldungen!$C$2:$C$112,$A8,Meldungen!$N$2:$N$112,"ganz"),"") -> 3 | T8: 3 | U8: =SUMIFS(Meldungen!$AF$2:$AF$112,Meldungen!$C$2:$C$112,$A8) -> 560.55 | V8: =SUMIFS(Meldungen!$AG$2:$AG$112,Meldungen!$C$2:$C$112,$A8) -> 747.1 | W8: =COUNTIFS(Meldungen!$C$2:$C$112,$A8,Meldungen!$N$2:$N$112,"ganz",Meldungen!$H$2:$H$112,5) -> 2 | X8: Drinnen (6/9) | Y8: =COUNTIFS(Meldungen!$C$2:$C$112,$A8,Meldungen!$T$2:$T$112,"ja") -> 0 | Z8: =COUNTIFS(Meldungen!$C$2:$C$112,$A8,Meldungen!$U$2:$U$112,"ja") -> 1 | AA8: =COUNTIFS(Meldungen!$C$2:$C$112,$A8,Meldungen!$S$2:$S$112,"ja") -> 2 | AB8: W2 drei „ganz“-Meldungen (Deckelung greift); H003 = 5 doppelt
A9: BW-09 | B9: B | C9: ausgewertet | D9: 2 | E9: 91.99 | F9: =COUNTIF(Meldungen!$C$2:$C$112,$A9) -> 8 | G9: =COUNTIFS(Meldungen!$C$2:$C$112,$A9,Meldungen!$N$2:$N$112,"ganz") -> 7 | H9: =SUMIFS(Meldungen!$AH$2:$AH$112,Meldungen!$C$2:$C$112,$A9) -> 7 | I9: =SUMIFS(Meldungen!$AI$2:$AI$112,Meldungen!$C$2:$C$112,$A9) -> 7 | J9: =COUNTIFS(Meldungen!$C$2:$C$112,$A9,Meldungen!$N$2:$N$112,"teilweise") -> 0 | K9: =COUNTIFS(Meldungen!$C$2:$C$112,$A9,Meldungen!$N$2:$N$112,"gar nicht") -> 1 | L9: =COUNTIFS(Meldungen!$C$2:$C$112,$A9,Meldungen!$O$2:$O$112,"ja") -> 7 | M9: =SUMIFS(Meldungen!$AJ$2:$AJ$112,Meldungen!$C$2:$C$112,$A9) -> 7 | N9: =SUMIFS(Meldungen!$AK$2:$AK$112,Meldungen!$C$2:$C$112,$A9) -> 7 | O9: =G9/12 -> 0.58333333 | P9: =L9/12 -> 0.58333333 | Q9: =IF(G9>=6,"ja","nein") -> ja | R9: =IF(G9>=9,"ja","nein") -> nein | S9: =IFERROR(AVERAGEIFS(Meldungen!$Q$2:$Q$112,Meldungen!$C$2:$C$112,$A9,Meldungen!$N$2:$N$112,"ganz"),"") -> 2.7142857 | T9: 3 | U9: =SUMIFS(Meldungen!$AF$2:$AF$112,Meldungen!$C$2:$C$112,$A9) -> 334.66667 | V9: =SUMIFS(Meldungen!$AG$2:$AG$112,Meldungen!$C$2:$C$112,$A9) -> 441.26667 | W9: =COUNTIFS(Meldungen!$C$2:$C$112,$A9,Meldungen!$N$2:$N$112,"ganz",Meldungen!$H$2:$H$112,5) -> 2 | X9: Drinnen (7/7) | Y9: =COUNTIFS(Meldungen!$C$2:$C$112,$A9,Meldungen!$T$2:$T$112,"ja") -> 0 | Z9: =COUNTIFS(Meldungen!$C$2:$C$112,$A9,Meldungen!$U$2:$U$112,"ja") -> 7 | AA9: =COUNTIFS(Meldungen!$C$2:$C$112,$A9,Meldungen!$S$2:$S$112,"ja") -> 2
A10: BW-10 | B10: B | C10: ausgewertet | D10: 2 | E10: 93.64 | F10: =COUNTIF(Meldungen!$C$2:$C$112,$A10) -> 5 | G10: =COUNTIFS(Meldungen!$C$2:$C$112,$A10,Meldungen!$N$2:$N$112,"ganz") -> 5 | H10: =SUMIFS(Meldungen!$AH$2:$AH$112,Meldungen!$C$2:$C$112,$A10) -> 5 | I10: =SUMIFS(Meldungen!$AI$2:$AI$112,Meldungen!$C$2:$C$112,$A10) -> 5 | J10: =COUNTIFS(Meldungen!$C$2:$C$112,$A10,Meldungen!$N$2:$N$112,"teilweise") -> 0 | K10: =COUNTIFS(Meldungen!$C$2:$C$112,$A10,Meldungen!$N$2:$N$112,"gar nicht") -> 0 | L10: =COUNTIFS(Meldungen!$C$2:$C$112,$A10,Meldungen!$O$2:$O$112,"ja") -> 5 | M10: =SUMIFS(Meldungen!$AJ$2:$AJ$112,Meldungen!$C$2:$C$112,$A10) -> 5 | N10: =SUMIFS(Meldungen!$AK$2:$AK$112,Meldungen!$C$2:$C$112,$A10) -> 5 | O10: =G10/12 -> 0.41666667 | P10: =L10/12 -> 0.41666667 | Q10: =IF(G10>=6,"ja","nein") -> nein | R10: =IF(G10>=9,"ja","nein") -> nein | S10: =IFERROR(AVERAGEIFS(Meldungen!$Q$2:$Q$112,Meldungen!$C$2:$C$112,$A10,Meldungen!$N$2:$N$112,"ganz"),"") -> 4 | T10: 4 | U10: =SUMIFS(Meldungen!$AF$2:$AF$112,Meldungen!$C$2:$C$112,$A10) -> 410.61667 | V10: =SUMIFS(Meldungen!$AG$2:$AG$112,Meldungen!$C$2:$C$112,$A10) -> 543.86667 | W10: =COUNTIFS(Meldungen!$C$2:$C$112,$A10,Meldungen!$N$2:$N$112,"ganz",Meldungen!$H$2:$H$112,5) -> 1 | X10: Kunstrasen (3/5) | Y10: =COUNTIFS(Meldungen!$C$2:$C$112,$A10,Meldungen!$T$2:$T$112,"ja") -> 3 | Z10: =COUNTIFS(Meldungen!$C$2:$C$112,$A10,Meldungen!$U$2:$U$112,"ja") -> 4 | AA10: =COUNTIFS(Meldungen!$C$2:$C$112,$A10,Meldungen!$S$2:$S$112,"ja") -> 0
A11: BW-11 | B11: B | C11: ausgewertet | D11: 2 | E11: 93.22 | F11: =COUNTIF(Meldungen!$C$2:$C$112,$A11) -> 2 | G11: =COUNTIFS(Meldungen!$C$2:$C$112,$A11,Meldungen!$N$2:$N$112,"ganz") -> 2 | H11: =SUMIFS(Meldungen!$AH$2:$AH$112,Meldungen!$C$2:$C$112,$A11) -> 2 | I11: =SUMIFS(Meldungen!$AI$2:$AI$112,Meldungen!$C$2:$C$112,$A11) -> 2 | J11: =COUNTIFS(Meldungen!$C$2:$C$112,$A11,Meldungen!$N$2:$N$112,"teilweise") -> 0 | K11: =COUNTIFS(Meldungen!$C$2:$C$112,$A11,Meldungen!$N$2:$N$112,"gar nicht") -> 0 | L11: =COUNTIFS(Meldungen!$C$2:$C$112,$A11,Meldungen!$O$2:$O$112,"ja") -> 2 | M11: =SUMIFS(Meldungen!$AJ$2:$AJ$112,Meldungen!$C$2:$C$112,$A11) -> 2 | N11: =SUMIFS(Meldungen!$AK$2:$AK$112,Meldungen!$C$2:$C$112,$A11) -> 2 | O11: =G11/12 -> 0.16666667 | P11: =L11/12 -> 0.16666667 | Q11: =IF(G11>=6,"ja","nein") -> nein | R11: =IF(G11>=9,"ja","nein") -> nein | S11: =IFERROR(AVERAGEIFS(Meldungen!$Q$2:$Q$112,Meldungen!$C$2:$C$112,$A11,Meldungen!$N$2:$N$112,"ganz"),"") -> 3.5 | T11: 3.5 | U11: =SUMIFS(Meldungen!$AF$2:$AF$112,Meldungen!$C$2:$C$112,$A11) -> 196.93333 | V11: =SUMIFS(Meldungen!$AG$2:$AG$112,Meldungen!$C$2:$C$112,$A11) -> 259.11667 | W11: =COUNTIFS(Meldungen!$C$2:$C$112,$A11,Meldungen!$N$2:$N$112,"ganz",Meldungen!$H$2:$H$112,5) -> 0 | X11: Rasen/Wiese (2/2) | Y11: =COUNTIFS(Meldungen!$C$2:$C$112,$A11,Meldungen!$T$2:$T$112,"ja") -> 0 | Z11: =COUNTIFS(Meldungen!$C$2:$C$112,$A11,Meldungen!$U$2:$U$112,"ja") -> 2 | AA11: =COUNTIFS(Meldungen!$C$2:$C$112,$A11,Meldungen!$S$2:$S$112,"ja") -> 1
A12: BW-21 | B12: B | C12: Post nicht angetreten | D12: 1 | E12: 91.06 | F12: =COUNTIF(Meldungen!$C$2:$C$112,$A12) -> 0 | G12: =COUNTIFS(Meldungen!$C$2:$C$112,$A12,Meldungen!$N$2:$N$112,"ganz") -> 0 | H12: =SUMIFS(Meldungen!$AH$2:$AH$112,Meldungen!$C$2:$C$112,$A12) -> 0 | I12: =SUMIFS(Meldungen!$AI$2:$AI$112,Meldungen!$C$2:$C$112,$A12) -> 0 | J12: =COUNTIFS(Meldungen!$C$2:$C$112,$A12,Meldungen!$N$2:$N$112,"teilweise") -> 0 | K12: =COUNTIFS(Meldungen!$C$2:$C$112,$A12,Meldungen!$N$2:$N$112,"gar nicht") -> 0 | L12: =COUNTIFS(Meldungen!$C$2:$C$112,$A12,Meldungen!$O$2:$O$112,"ja") -> 0 | M12: =SUMIFS(Meldungen!$AJ$2:$AJ$112,Meldungen!$C$2:$C$112,$A12) -> 0 | N12: =SUMIFS(Meldungen!$AK$2:$AK$112,Meldungen!$C$2:$C$112,$A12) -> 0 | O12: =G12/12 -> 0 | P12: =L12/12 -> 0 | Q12: =IF(G12>=6,"ja","nein") -> nein | R12: =IF(G12>=9,"ja","nein") -> nein | S12: =IFERROR(AVERAGEIFS(Meldungen!$Q$2:$Q$112,Meldungen!$C$2:$C$112,$A12,Meldungen!$N$2:$N$112,"ganz"),"") | U12: =SUMIFS(Meldungen!$AF$2:$AF$112,Meldungen!$C$2:$C$112,$A12) -> 0 | V12: =SUMIFS(Meldungen!$AG$2:$AG$112,Meldungen!$C$2:$C$112,$A12) -> 0 | W12: =COUNTIFS(Meldungen!$C$2:$C$112,$A12,Meldungen!$N$2:$N$112,"ganz",Meldungen!$H$2:$H$112,5) -> 0 | X12: — | Y12: =COUNTIFS(Meldungen!$C$2:$C$112,$A12,Meldungen!$T$2:$T$112,"ja") -> 0 | Z12: =COUNTIFS(Meldungen!$C$2:$C$112,$A12,Meldungen!$U$2:$U$112,"ja") -> 0 | AA12: =COUNTIFS(Meldungen!$C$2:$C$112,$A12,Meldungen!$S$2:$S$112,"ja") -> 0 | AB12: Instrumentenfehler — kein Listenplatz; Post nicht angetreten (Teilnehmerfluss)
