Workbook

Sheet Anleitung
A1: Handprobenblatt Phase 6.3 als Excel-Formelprobe — Auswertungsverfahren 2026-09-24, Schritt 6.3
A2: Bachelorarbeit U15-Plyometrie · Datenstand 2026-09-24 · berichtete Rechnung: Blindrechnung in R vom 25.09.2026 · Gegenprobe: Python-Kette (Gegenprobe_Python_2026-09-25.py) · Erzeuger dieses Blatts: Handprobe_2026-09-25.py, Fassung 2
A4: Zweck
A5: Das Auswertungsverfahren sieht in 6.3 vor, dass der Verfasser vorab bestimmte Kennwerte in Excel nachrechnet. Verfasserentscheidung vom 25.09.2026 (Register R12): Die Handprobe wird als Formelprobe geführt. Jede gelbe Zelle „Handwert“ im Blatt „Handprobe“ enthält eine Excel-Formel, die den Kennwert allein aus den Eingangsblättern nach den Regeln der Spezifikation berechnet. Excel ist damit eine dritte, von R und Python unabhängige Implementierung der 34 Kennwerte. Die Formeln sind offen lesbar und in Excel Schritt für Schritt nachvollziehbar.
A7: Vorgehen für den Verfasser
A8: 1. Datei in Excel öffnen. Excel berechnet alle Formeln beim Öffnen. Die Spalte „Urteil“ im Blatt „Handprobe“ muss bei allen 34 Kennwerten „stimmt“ zeigen, ebenso die Zusatzprüfungen unter der Tabelle.
A9: 2. Formeln stichprobenartig lesen (Zelle anklicken): Sie greifen nur auf die Blätter Versuchsdaten, Personendaten, Fragebogen_A, Koeffizienten_KR, Vokabular und Zuordnung zu, teils über die Rechenblätter Formelwerte, TE_Z30_prae und ANCOVA_Z30. Kein Handwert liest einen Wert aus der Ergebnisdatei. Einzige Ausnahme nach dem vorab festgelegten Rechenweg von Kennwert Nr. 34: p und b1 der Zielgrößen CM und SBJ stehen als Eingang aus der Ergebnisdatei in der kleinen Tabelle rechts neben den Kennwerten.
A10: 3. Blatt „Formelwerte“: Die per Formel abgeleiteten Zwischengrößen je Spieler (Bestwerte, 505-Seitenmittel, %PAH, Setmitgliedschaft, Adhärenz) stehen neben dem Vergleich mit der berichteten Rechnung (Blatt „Analysedaten“, grüne Werte). Die Zahl der abweichenden Zellen steht in der Zusatzprüfung Z2.
A11: 4. Ergebnis mit Datum in Zelle B4 des Blatts „Handprobe“ eintragen („bestanden“ oder Liste der abweichenden Nummern), Datei sichern. Danach Freigabe F2.
A13: Aufbau der Rechenblätter
A14: Versuchsdaten: Spalten A bis H unverändert aus dem Datenstand. Hilfsspalten (grün hinterlegt, Formeln): I Gruppe des Spielers · J gültig_roh (S02 Regel 1: Wert vorhanden, ungültig leer) · K, L, M Teilzeiten 5, 10, 30 m des Laufs (gleiche Versuchsnummer, nur gültig_roh) · N auslösegestört (S02 Regel 2: ein Abschnitt mit Δt ≤ 0 s oder v > 10,0 m/s) · O gültig (S02 Regel 3) · P Status des Spielers · Q Ausfallkategorie (S03: NANG vor AUSL vor Vokabular).
A15: Fragebogen_A: Spalten A bis K unverändert. Hilfsspalten: L Listenlabel aus H010 mit den Fallkorrekturen (S06 Regel 1 und 2) · M Analysecode aus der Zuordnung (S06 Regel 3).
... A23: Werte in diesem Blatt sind pseudonymisiert (Analysecodes). Die Datei bleibt im Projektordner (04_Uebergaben) und geht nicht an Dritte.

Sheet Handprobe
A1: Handprobe Phase 6.3 als Excel-Formelprobe — Kennwerte, Sollwerte beider Implementierungen, Formelwert (Excel)
A2: Gelbe Zellen tragen Excel-Formeln aus den Eingangsblättern (dritte Implementierung). Toleranz: Anzahlen exakt, übrige relativ 1e-6. Spalte „Wert R“ ist die berichtete Rechnung, „Wert Python“ die Gegenprobe (beide aus den Ergebnisdateien vom 25.09.2026).
A4: Ergebnis der Handprobe (Verfasser, Datum):
A6: Nr. | B6: Kennung | C6: Beschreibung | D6: Rechenweg (Regel der Spezifikation) und Formel | E6: Eingang (Blatt, Auswahl) | F6: Wert R | G6: Wert Python | H6: Handwert (Formel) | I6: Abweichung Hand − R | J6: Toleranz | K6: Urteil | M6: Eingang aus der Ergebnisdatei nur für Nr. 34 (Rechenweg vorab festgelegt)
A7: 1 | B7: S02.NGUELT.Z30.PRE.ALL.X | C7: Zahl gültiger Versuche 30 m prä, alle Spieler | D7: S02 Regel 1 bis 3: Zeilen mit Test Sprint_30m, Zeitpunkt prä und gültig = 1 zählen (Spalte O des Blatts Versuchsdaten, mit Auslöseprüfung). | E7: Versuchsdaten | F7: 78 | G7: 78 | H7: =COUNTIFS(Versuchsdaten!$C$2:$C$1117,"Sprint_30m",Versuchsdaten!$B$2:$B$1117,"prä",Versuchsdaten!$O$2:$O$1117,1) | I7: =IF(H7="","",IFERROR(H7-F7,"FEHLER")) | J7: 0 | K7: =IF(H7="","offen",IFERROR(IF(ABS(H7-F7)<=J7*MAX(1,ABS(F7)),"stimmt","ABWEICHUNG"),"FEHLER")) | M7: S13.P.CM.X.ITT.HAUPT | N7: p 505-Seitenmittel | O7: 0.73433331
A8: 2 | B8: S03.NKAT.Z30.POST.KG.TECH | C8: Ungültige Zeilen 30 m post der KG, Kategorie TECH | D8: S03 Regel 1 bis 3 mit Vokabular: Zeilen mit Test Sprint_30m, Zeitpunkt post, Gruppe KG und Kategorie TECH zählen (Spalte Q des Blatts Versuchsdaten: NANG vor AUSL vor Vokabular). | E8: Versuchsdaten (Hilfsspalten I und Q) | F8: 2 | G8: 2 | H8: =COUNTIFS(Versuchsdaten!$C$2:$C$1117,"Sprint_30m",Versuchsdaten!$B$2:$B$1117,"post",Versuchsdaten!$I$2:$I$1117,"KG",Versuchsdaten!$Q$2:$Q$1117,"TECH") | I8: =IF(H8="","",IFERROR(H8-F8,"FEHLER")) | J8: 0 | K8: =IF(H8="","offen",IFERROR(IF(ABS(H8-F8)<=J8*MAX(1,ABS(F8)),"stimmt","ABWEICHUNG"),"FEHLER")) | M8: S13.B1.CM.X.ITT.HAUPT | N8: b1 505-Seitenmittel | O8: -0.012071414
A9: 3 | B9: S04.K.Z30.PRE.PBW-01.X | C9: Zahl gültiger Versuche 30 m prä, Spieler BW-01 | D9: S04 Regel 1: gültige Versuche des Spielers zählen. | E9: Versuchsdaten, Code BW-01 | F9: 3 | G9: 3 | H9: =COUNTIFS(Versuchsdaten!$A$2:$A$1117,"BW-01",Versuchsdaten!$B$2:$B$1117,"prä",Versuchsdaten!$C$2:$C$1117,"Sprint_30m",Versuchsdaten!$O$2:$O$1117,1) | I9: =IF(H9="","",IFERROR(H9-F9,"FEHLER")) | J9: 0 | K9: =IF(H9="","offen",IFERROR(IF(ABS(H9-F9)<=J9*MAX(1,ABS(F9)),"stimmt","ABWEICHUNG"),"FEHLER")) | M9: S13.P.SBJ.X.ITT.HAUPT | N9: p Standweitsprung | O9: 0.9868585
A10: 4 | B10: S04.BEST.Z30.PRE.PBW-01.X | C10: Bestwert 30 m prä, Spieler BW-01 | D10: S04 Regel 2: Minimum der gültigen Werte (Zeit). MINIFS über die gültigen Zeilen des Spielers. | E10: Versuchsdaten, Code BW-01 | F10: 4.53 | G10: 4.53 | H10: =_xlfn.MINIFS(Versuchsdaten!$F$2:$F$1117,Versuchsdaten!$A$2:$A$1117,"BW-01",Versuchsdaten!$B$2:$B$1117,"prä",Versuchsdaten!$C$2:$C$1117,"Sprint_30m",Versuchsdaten!$O$2:$O$1117,1) | I10: =IF(H10="","",IFERROR(H10-F10,"FEHLER")) | J10: 1e-06 | K10: =IF(H10="","offen",IFERROR(IF(ABS(H10-F10)<=J10*MAX(1,ABS(F10)),"stimmt","ABWEICHUNG"),"FEHLER")) | M10: S13.B1.SBJ.X.ITT.HAUPT | N10: b1 Standweitsprung | O10: -0.069440121
A11: 5 | B11: S04.MEAN.Z30.PRE.PBW-01.X | C11: Mittelwert 30 m prä, Spieler BW-01 | D11: S04 Regel 3: arithmetisches Mittel der gültigen Werte. AVERAGEIFS über die gültigen Zeilen des Spielers. | E11: Versuchsdaten, Code BW-01 | F11: 4.5866667 | G11: 4.5866667 | H11: =AVERAGEIFS(Versuchsdaten!$F$2:$F$1117,Versuchsdaten!$A$2:$A$1117,"BW-01",Versuchsdaten!$B$2:$B$1117,"prä",Versuchsdaten!$C$2:$C$1117,"Sprint_30m",Versuchsdaten!$O$2:$O$1117,1) | I11: =IF(H11="","",IFERROR(H11-F11,"FEHLER")) | J11: 1e-06 | K11: =IF(H11="","offen",IFERROR(IF(ABS(H11-F11)<=J11*MAX(1,ABS(F11)),"stimmt","ABWEICHUNG"),"FEHLER"))
A12: 6 | B12: S04.BEST.CM.PRE.PBW-01.X | C12: 505-Seitenmittel prä, Spieler BW-01 | D12: S04 Regel 4: Bestwert (Minimum) je Seite L und R aus den gültigen Versuchen, dann Mittel der beiden Seiten-Bestwerte, nur wenn beide Seiten einen gültigen Versuch haben (Blatt Formelwerte, Spalten T, U, V). | E12: Versuchsdaten, Code BW-01, Test COD_505 | F12: 2.555 | G12: 2.555 | H12: =INDEX(Formelwerte!$V$4:$V$34,MATCH("BW-01",Formelwerte!$A$4:$A$34,0)) | I12: =IF(H12="","",IFERROR(H12-F12,"FEHLER")) | J12: 1e-06 | K12: =IF(H12="","offen",IFERROR(IF(ABS(H12-F12)<=J12*MAX(1,ABS(F12)),"stimmt","ABWEICHUNG"),"FEHLER"))
A13: 7 | B13: S05.MP.PAH.PRE.PBW-01.X | C13: Mittlere Elterngröße in Zoll, Spieler BW-01 | D13: S05 Regel 2 und 3: (Groesse_Mutter/2,54 + Groesse_Vater/2,54)/2 (Blatt Formelwerte, Spalte G). | E13: Personendaten, Code BW-01 | F13: 71.259843 | G13: 71.259843 | H13: =INDEX(Formelwerte!$G$4:$G$34,MATCH("BW-01",Formelwerte!$A$4:$A$34,0)) | I13: =IF(H13="","",IFERROR(H13-F13,"FEHLER")) | J13: 1e-06 | K13: =IF(H13="","offen",IFERROR(IF(ABS(H13-F13)<=J13*MAX(1,ABS(F13)),"stimmt","ABWEICHUNG"),"FEHLER"))
A14: 8 | B14: S05.PAS.PAH.PRE.PBW-01.X | C14: Vorhergesagte Erwachsenengröße in Zoll, Spieler BW-01 | D14: S05 Regel 6 und 7: a_lo = 14.5, a_hi = 15.0, w = (Alter − a_lo)/0,5. Jeden Koeffizienten linear interpolieren: c = (1 − w)·c(a_lo) + w·c(a_hi). PAS = β0 + β1·Körperhöhe/2,54 + β2·Körpermasse/0,45359237 + β3·MP (Blatt Formelwerte, Spalten H bis N). | E14: Personendaten, Code BW-01, Koeffizienten_KR Zeilen 14.5 und 15.0 | F14: 74.57886 | G14: 74.57886 | H14: =INDEX(Formelwerte!$N$4:$N$34,MATCH("BW-01",Formelwerte!$A$4:$A$34,0)) | I14: =IF(H14="","",IFERROR(H14-F14,"FEHLER")) | J14: 1e-06 | K14: =IF(H14="","offen",IFERROR(IF(ABS(H14-F14)<=J14*MAX(1,ABS(F14)),"stimmt","ABWEICHUNG"),"FEHLER"))
A15: 9 | B15: S05.PAH.PAH.PRE.PBW-01.X | C15: %PAH, Spieler BW-01 | D15: S05 Regel 8: 100 · (Körperhöhe/2,54) / PAS (Blatt Formelwerte, Spalte O). | E15: Personendaten, Code BW-01 | F15: 91.854363 | G15: 91.854363 | H15: =INDEX(Formelwerte!$O$4:$O$34,MATCH("BW-01",Formelwerte!$A$4:$A$34,0)) | I15: =IF(H15="","",IFERROR(H15-F15,"FEHLER")) | J15: 1e-06 | K15: =IF(H15="","offen",IFERROR(IF(ABS(H15-F15)<=J15*MAX(1,ABS(F15)),"stimmt","ABWEICHUNG"),"FEHLER"))
A16: 10 | B16: S06.NMELD.FB.X.PHL-01.X | C16: Zahl der Meldungen, Spieler HL-01 (Listenplatz H010 = 1) | D16: S06 Regel 1 bis 3: Listenlabel aus H010 mit den Fallkorrekturen (CASE 59, 70, 140, 158, 165, 190, 206), Analysecode aus der Zuordnung (Blatt Fragebogen_A, Spalten L und M), Meldungen des Analysecodes zählen. | E16: Fragebogen_A, Zuordnung | F16: 10 | G16: 10 | H16: =COUNTIF(Fragebogen_A!$M$2:$M$112,"HL-01") | I16: =IF(H16="","",IFERROR(H16-F16,"FEHLER")) | J16: 0 | K16: =IF(H16="","offen",IFERROR(IF(ABS(H16-F16)<=J16*MAX(1,ABS(F16)),"stimmt","ABWEICHUNG"),"FEHLER"))
A17: 11 | B17: S07.ADH.ADH.X.PHL-01.GANZ | C17: Adhärenz GANZ, Spieler HL-01 | D17: S07 Regel 1: Meldungen des Analysecodes mit H004 = 1 zählen. | E17: Fragebogen_A | F17: 8 | G17: 8 | H17: =COUNTIFS(Fragebogen_A!$M$2:$M$112,"HL-01",Fragebogen_A!$F$2:$F$112,1) | I17: =IF(H17="","",IFERROR(H17-F17,"FEHLER")) | J17: 0 | K17: =IF(H17="","offen",IFERROR(IF(ABS(H17-F17)<=J17*MAX(1,ABS(F17)),"stimmt","ABWEICHUNG"),"FEHLER"))
A18: 12 | B18: S07.SUMME.ADH.X.IG.GANZ | C18: Summe der Meldungen „ganz“ über alle IG-Spieler | D18: S07 Regel 5 und 6: Summe der Zählung GANZ über die zugeteilten Spieler, Spieler ohne Meldung mit 0, Spieler ohne Listenplatz in der Summe mit 0 (Blatt Formelwerte, Spalte AE). Jede Meldung zählt (K7). | E18: Fragebogen_A über Formelwerte | F18: 92 | G18: 92 | H18: =SUM(Formelwerte!$AE$4:$AE$34) | I18: =IF(H18="","",IFERROR(H18-F18,"FEHLER")) | J18: 0 | K18: =IF(H18="","offen",IFERROR(IF(ABS(H18-F18)<=J18*MAX(1,ABS(F18)),"stimmt","ABWEICHUNG"),"FEHLER"))
A19: 13 | B19: S07.RATE.ADH.X.IG.GANZ | C19: Umsetzungsrate GANZ | D19: S07 Regel 6: Summe / (12 · Zahl der zugeteilten IG-Spieler der Personendaten). | E19: Kennwert Nr. 12, Personendaten | F19: 0.42592593 | G19: 0.42592593 | H19: =$H$18/(12*COUNTIF(Personendaten!$C$2:$C$32,"IG")) | I19: =IF(H19="","",IFERROR(H19-F19,"FEHLER")) | J19: 1e-06 | K19: =IF(H19="","offen",IFERROR(IF(ABS(H19-F19)<=J19*MAX(1,ABS(F19)),"stimmt","ABWEICHUNG"),"FEHLER"))
A20: 14 | B20: S08.N.Z30.X.ITTIG.X | C20: Zahl der IG-Spieler im ITT-Set 30 m | D20: S08 Regel 1: IG-Spieler mit BEST prä, BEST post und %PAH zählen (Blatt Formelwerte, Spalten D und AB). | E20: Formelwerte | F20: 16 | G20: 16 | H20: =COUNTIFS(Formelwerte!$D$4:$D$34,1,Formelwerte!$AB$4:$AB$34,1) | I20: =IF(H20="","",IFERROR(H20-F20,"FEHLER")) | J20: 0 | K20: =IF(H20="","offen",IFERROR(IF(ABS(H20-F20)<=J20*MAX(1,ABS(F20)),"stimmt","ABWEICHUNG"),"FEHLER"))
A21: 15 | B21: S10.TE.Z30.PRE.ALL.X | C21: Typischer Messfehler 30 m prä | D21: S10 Regel 1: je Spieler mit k ≥ 2 die Quadratsumme der Abweichungen vom Spielermittel (DEVSQ), Summe über Spieler geteilt durch Σ(k − 1), Wurzel (Blatt TE_Z30_prae). | E21: TE_Z30_prae | F21: 0.077491706 | G21: 0.077491706 | H21: =SQRT(SUM(TE_Z30_prae!$F$3:$F$33)/SUM(TE_Z30_prae!$G$3:$G$33)) | I21: =IF(H21="","",IFERROR(H21-F21,"FEHLER")) | J21: 1e-06 | K21: =IF(H21="","offen",IFERROR(IF(ABS(H21-F21)<=J21*MAX(1,ABS(F21)),"stimmt","ABWEICHUNG"),"FEHLER"))
A22: 16 | B22: S10.DFTE.Z30.PRE.ALL.X | C22: Freiheitsgrade des TE 30 m prä | D22: S10 Regel 1: Σ(k_i − 1) über Spieler mit k ≥ 2. | E22: TE_Z30_prae | F22: 47 | G22: 47 | H22: =SUM(TE_Z30_prae!$G$3:$G$33) | I22: =IF(H22="","",IFERROR(H22-F22,"FEHLER")) | J22: 0 | K22: =IF(H22="","offen",IFERROR(IF(ABS(H22-F22)<=J22*MAX(1,ABS(F22)),"stimmt","ABWEICHUNG"),"FEHLER"))
A23: 17 | B23: S10.SB.Z30.PRE.ALL.X | C23: Zwischen-Athleten-SD der Bestwerte 30 m prä | D23: S10 Regel 5: STDEV.S über BEST Z30 prä aller Spieler mit Wert (beide Gruppen, Blatt Formelwerte, Spalte Q). | E23: Formelwerte, Spalte BEST Z30 prä | F23: 0.31325897 | G23: 0.31325897 | H23: =_xlfn.STDEV.S(Formelwerte!$Q$4:$Q$34) | I23: =IF(H23="","",IFERROR(H23-F23,"FEHLER")) | J23: 1e-06 | K23: =IF(H23="","offen",IFERROR(IF(ABS(H23-F23)<=J23*MAX(1,ABS(F23)),"stimmt","ABWEICHUNG"),"FEHLER"))
A24: 18 | B24: S10.SESOI.Z30.PRE.ALL.X | C24: SESOI 30 m | D24: S10 Regel 6: 0,2 · S. | E24: Kennwert Nr. 17 | F24: 0.062651794 | G24: 0.062651794 | H24: =0.2*$H$23 | I24: =IF(H24="","",IFERROR(H24-F24,"FEHLER")) | J24: 1e-06 | K24: =IF(H24="","offen",IFERROR(IF(ABS(H24-F24)<=J24*MAX(1,ABS(F24)),"stimmt","ABWEICHUNG"),"FEHLER"))
A25: 19 | B25: S12.M.Z30.PRE.ITTIG.HAUPT | C25: Mittel BEST 30 m prä, IG im ITT-Set | D25: S12 Regel 4: AVERAGE über die Prä-Werte der IG-Spieler des ITT-Sets (Blatt ANCOVA_Z30, Spalte G). | E25: ANCOVA_Z30 | F25: 4.510625 | G25: 4.510625 | H25: =AVERAGE(ANCOVA_Z30!$G$3:$G$28) | I25: =IF(H25="","",IFERROR(H25-F25,"FEHLER")) | J25: 1e-06 | K25: =IF(H25="","offen",IFERROR(IF(ABS(H25-F25)<=J25*MAX(1,ABS(F25)),"stimmt","ABWEICHUNG"),"FEHLER"))
A26: 20 | B26: S12.SD.Z30.PRE.ITTIG.HAUPT | C26: SD BEST 30 m prä, IG im ITT-Set | D26: S12 Regel 4: STDEV.S über dieselben Spieler. | E26: ANCOVA_Z30 | F26: 0.2087253 | G26: 0.2087253 | H26: =_xlfn.STDEV.S(ANCOVA_Z30!$G$3:$G$28) | I26: =IF(H26="","",IFERROR(H26-F26,"FEHLER")) | J26: 1e-06 | K26: =IF(H26="","offen",IFERROR(IF(ABS(H26-F26)<=J26*MAX(1,ABS(F26)),"stimmt","ABWEICHUNG"),"FEHLER"))
A27: 21 | B27: S15.UD.Z30.X.ITT.HAUPT | C27: Unadjustierte Differenz der Post-Mittel 30 m (IG − KG), ITT-Set | D27: S15 Regel 4: Mittel BEST Z30 post der IG minus Mittel der KG, jeweils im ITT-Set (Blatt ANCOVA_Z30, Spalten I und J). | E27: ANCOVA_Z30 | F27: -0.32675 | G27: -0.32675 | H27: =AVERAGE(ANCOVA_Z30!$I$3:$I$28)-AVERAGE(ANCOVA_Z30!$J$3:$J$28) | I27: =IF(H27="","",IFERROR(H27-F27,"FEHLER")) | J27: 1e-06 | K27: =IF(H27="","offen",IFERROR(IF(ABS(H27-F27)<=J27*MAX(1,ABS(F27)),"stimmt","ABWEICHUNG"),"FEHLER"))
A28: 22 | B28: S15.SDPOST.Z30.X.ITT.HAUPT | C28: Gepoolte Post-SD 30 m, ITT-Set | D28: 0.5 Nr. 2: √(((n_IG − 1)·s_IG² + (n_KG − 1)·s_KG²)/(n_IG + n_KG − 2)) mit VAR.S je Gruppe. | E28: ANCOVA_Z30 | F28: 0.20469337 | G28: 0.20469337 | H28: =SQRT(((ANCOVA_Z30!$B$31-1)*_xlfn.VAR.S(ANCOVA_Z30!$I$3:$I$28)+(ANCOVA_Z30!$B$32-1)*_xlfn.VAR.S(ANCOVA_Z30!$J$3:$J$28))/(ANCOVA_Z30!$B$33-2)) | I28: =IF(H28="","",IFERROR(H28-F28,"FEHLER")) | J28: 1e-06 | K28: =IF(H28="","offen",IFERROR(IF(ABS(H28-F28)<=J28*MAX(1,ABS(F28)),"stimmt","ABWEICHUNG"),"FEHLER"))
A29: 23 | B29: S15.UDT.Z30.X.ITT.HAUPT | C29: t der unadjustierten Differenz | D29: S15 Regel 4: UD / (SD_pool · √(1/n_IG + 1/n_KG)). | E29: Kennwerte Nr. 21 und 22 | F29: -3.9599084 | G29: -3.9599084 | H29: =$H$27/($H$28*SQRT(1/ANCOVA_Z30!$B$31+1/ANCOVA_Z30!$B$32)) | I29: =IF(H29="","",IFERROR(H29-F29,"FEHLER")) | J29: 1e-06 | K29: =IF(H29="","offen",IFERROR(IF(ABS(H29-F29)<=J29*MAX(1,ABS(F29)),"stimmt","ABWEICHUNG"),"FEHLER"))
A30: 24 | B30: S15.UDP.Z30.X.ITT.HAUPT | C30: p der unadjustierten Differenz | D30: S15 Regel 4: zweiseitig, df = n − 2. Excel: T.DIST.2T(ABS(t), df). | E30: Kennwert Nr. 23 | F30: 0.00058305067 | G30: 0.00058305067 | H30: =_xlfn.T.DIST.2T(ABS($H$29),ANCOVA_Z30!$B$33-2) | I30: =IF(H30="","",IFERROR(H30-F30,"FEHLER")) | J30: 1e-06 | K30: =IF(H30="","offen",IFERROR(IF(ABS(H30-F30)<=J30*MAX(1,ABS(F30)),"stimmt","ABWEICHUNG"),"FEHLER"))
A31: 25 | B31: S13.B1.Z30.X.ITT.HAUPT | C31: Adjustierte Differenz b1 (ANCOVA 30 m, ITT) | D31: S13 Modell Post = b0 + b1·G + b2·Prä + b3·PAH. Excel: INDEX(LINEST(Post-Bereich, [G, Prä, PAH]-Bereich, WAHR, WAHR), 1, 3). LINEST gibt die Koeffizienten in umgekehrter Reihenfolge der x-Spalten aus, b1 steht in Zeile 1, Spalte 3 (Blatt ANCOVA_Z30). | E31: ANCOVA_Z30 (ITT-Set aus Formelwerte) | F31: -0.04450618 | G31: -0.04450618 | H31: =ANCOVA_Z30!$B$35 | I31: =IF(H31="","",IFERROR(H31-F31,"FEHLER")) | J31: 1e-06 | K31: =IF(H31="","offen",IFERROR(IF(ABS(H31-F31)<=J31*MAX(1,ABS(F31)),"stimmt","ABWEICHUNG"),"FEHLER"))
A32: 26 | B32: S13.SEB1.Z30.X.ITT.HAUPT | C32: Standardfehler von b1 | D32: S13 Regel 1: zweite Zeile von LINEST, dieselbe Spalte wie b1. | E32: ANCOVA_Z30 | F32: 0.07462827 | G32: 0.07462827 | H32: =ANCOVA_Z30!$B$36 | I32: =IF(H32="","",IFERROR(H32-F32,"FEHLER")) | J32: 1e-06 | K32: =IF(H32="","offen",IFERROR(IF(ABS(H32-F32)<=J32*MAX(1,ABS(F32)),"stimmt","ABWEICHUNG"),"FEHLER"))
A33: 27 | B33: S13.DF.Z30.X.ITT.HAUPT | C33: Residualfreiheitsgrade | D33: S13 Regel 1: n − 4. | E33: ANCOVA_Z30 | F33: 22 | G33: 22 | H33: =ANCOVA_Z30!$B$33-4 | I33: =IF(H33="","",IFERROR(H33-F33,"FEHLER")) | J33: 0 | K33: =IF(H33="","offen",IFERROR(IF(ABS(H33-F33)<=J33*MAX(1,ABS(F33)),"stimmt","ABWEICHUNG"),"FEHLER"))
A34: 28 | B34: S13.P.Z30.X.ITT.HAUPT | C34: p von b1, zweiseitig | D34: S13 Regel 2: t = b1/SE, p = T.DIST.2T(ABS(t), df). | E34: Kennwerte Nr. 25 bis 27 | F34: 0.55701433 | G34: 0.55701433 | H34: =_xlfn.T.DIST.2T(ABS($H$31/$H$32),$H$33) | I34: =IF(H34="","",IFERROR(H34-F34,"FEHLER")) | J34: 1e-06 | K34: =IF(H34="","offen",IFERROR(IF(ABS(H34-F34)<=J34*MAX(1,ABS(F34)),"stimmt","ABWEICHUNG"),"FEHLER"))
A35: 29 | B35: S13.KIU.Z30.X.ITT.HAUPT | C35: Untere KI-Grenze von b1 | D35: S13 Regel 2: b1 − T.INV.2T(0,05, df) · SE. | E35: Kennwerte Nr. 25 bis 27 | F35: -0.19927574 | G35: -0.19927574 | H35: =$H$31-_xlfn.T.INV.2T(0.05,$H$33)*$H$32 | I35: =IF(H35="","",IFERROR(H35-F35,"FEHLER")) | J35: 1e-06 | K35: =IF(H35="","offen",IFERROR(IF(ABS(H35-F35)<=J35*MAX(1,ABS(F35)),"stimmt","ABWEICHUNG"),"FEHLER"))
A36: 30 | B36: S15.SDPRE.Z30.X.ITT.HAUPT | C36: Gepoolte Prä-SD des ITT-Sets 30 m | D36: S15 Regel 1: wie Nr. 22, mit den BEST prä (Blatt ANCOVA_Z30, Spalten G und H). | E36: ANCOVA_Z30 | F36: 0.23369618 | G36: 0.23369618 | H36: =SQRT(((ANCOVA_Z30!$B$31-1)*_xlfn.VAR.S(ANCOVA_Z30!$G$3:$G$28)+(ANCOVA_Z30!$B$32-1)*_xlfn.VAR.S(ANCOVA_Z30!$H$3:$H$28))/(ANCOVA_Z30!$B$33-2)) | I36: =IF(H36="","",IFERROR(H36-F36,"FEHLER")) | J36: 1e-06 | K36: =IF(H36="","offen",IFERROR(IF(ABS(H36-F36)<=J36*MAX(1,ABS(F36)),"stimmt","ABWEICHUNG"),"FEHLER"))
A37: 31 | B37: S15.J.Z30.X.ITT.HAUPT | C37: Korrekturfaktor J | D37: S15 Regel 2: 1 − 3/(4·(n_IG + n_KG − 2) − 1). | E37: ANCOVA_Z30 | F37: 0.96842105 | G37: 0.96842105 | H37: =1-3/(4*(ANCOVA_Z30!$B$33-2)-1) | I37: =IF(H37="","",IFERROR(H37-F37,"FEHLER")) | J37: 1e-06 | K37: =IF(H37="","offen",IFERROR(IF(ABS(H37-F37)<=J37*MAX(1,ABS(F37)),"stimmt","ABWEICHUNG"),"FEHLER"))
A38: 32 | B38: S15.G.Z30.X.ITT.HAUPT | C38: Hedges’ g | D38: S15 Regel 3: b1 / SD_prä · J. | E38: Kennwerte Nr. 25, 30, 31 | F38: -0.18443057 | G38: -0.18443057 | H38: =$H$31/$H$36*$H$37 | I38: =IF(H38="","",IFERROR(H38-F38,"FEHLER")) | J38: 1e-06 | K38: =IF(H38="","offen",IFERROR(IF(ABS(H38-F38)<=J38*MAX(1,ABS(F38)),"stimmt","ABWEICHUNG"),"FEHLER"))
A39: 33 | B39: S18.FCRIT.Z30.X.ITT.X | C39: Kritischer F-Wert der Poweranalyse 30 m | D39: S18 Regel 3: F_1,df2(0,95) mit df2 = N − 4. Excel: F.INV.RT(0,05, 1, df2). | E39: ANCOVA_Z30 (N = n_IG + n_KG des ITT-Sets) | F39: 4.3009495 | G39: 4.3009495 | H39: =_xlfn.F.INV.RT(0.05,1,ANCOVA_Z30!$B$33-4) | I39: =IF(H39="","",IFERROR(H39-F39,"FEHLER")) | J39: 1e-06 | K39: =IF(H39="","offen",IFERROR(IF(ABS(H39-F39)<=J39*MAX(1,ABS(F39)),"stimmt","ABWEICHUNG"),"FEHLER"))
A40: 34 | B40: S13.H0REJ.X.X.ITT.HAUPT | C40: Merkmal H0 abgelehnt | D40: S13 Entscheidungsregel: 1, wenn für mindestens eine der drei Zielgrößen p < 0,05 und b1 in günstiger Richtung (Zeiten negativ, Sprung positiv), sonst 0. Für 30 m aus den Kennwerten Nr. 25 und 28, für CM und SBJ aus der Tabelle „Eingang aus der Ergebnisdatei“ (Spalten M bis O), wie vorab festgelegt. | E40: Kennwerte Nr. 25 und 28, Eingang aus der Ergebnisdatei | F40: 0 | G40: 0 | H40: =IF(OR(AND($H$34<0.05,$H$31<0),AND($O$7<0.05,$O$8<0),AND($O$9<0.05,$O$10>0)),1,0) | I40: =IF(H40="","",IFERROR(H40-F40,"FEHLER")) | J40: 0 | K40: =IF(H40="","offen",IFERROR(IF(ABS(H40-F40)<=J40*MAX(1,ABS(F40)),"stimmt","ABWEICHUNG"),"FEHLER"))
A42: Zusatzprüfungen (Formeln, kein Kennwert der Liste)
A43: Z1 | C43: Zahl auslösegestörter Sprintläufe prä und post (S02 Regel 2), Formel gegen berichtete Rechnung | E43: S02.NAUSL.X.PRE.ALL.X + S02.NAUSL.X.POST.ALL.X | F43: 0 | H43: =COUNTIF(Versuchsdaten!$N$2:$N$1117,1)/3 | J43: 0 | K43: =IFERROR(IF(ABS(H43-F43)<=J43,"stimmt","ABWEICHUNG"),"FEHLER")
...

Sheet Versuchsdaten
A1: Code | B1: Zeitpunkt | C1: Test | D1: Seite | E1: Versuch | F1: Wert | G1: ungültig | H1: Bemerkung | I1: Gruppe (Formel) | J1: gültig_roh (S02 R1) | K1: t5 des Laufs | L1: t10 des Laufs | M1: t30 des Laufs | N1: auslösegestört (S02 R2) | O1: gültig (S02 R3) | P1: Status (Formel) | Q1: Kategorie (S03)
A2: BW-01 | B2: prä | C2: Sprint_5m | D2: – | E2: 1 | F2: 1.06 | I2: =INDEX(Personendaten!$C$2:$C$32,MATCH(A2,Personendaten!$A$2:$A$32,0)) | J2: =IF(AND(F2<>"",G2=""),1,0) | K2: =IF(LEFT(C2,7)<>"Sprint_","",IF(COUNTIFS(Versuchsdaten!$A$2:$A$1117,$A2,Versuchsdaten!$B$2:$B$1117,$B2,Versuchsdaten!$C$2:$C$1117,"Sprint_5m",Versuchsdaten!$E$2:$E$1117,$E2,Versuchsdaten!$J$2:$J$1117,1)=1,SUMIFS(Versuchsdaten!$F$2:$F$1117,Versuchsdaten!$A$2:$A$1117,$A2,Versuchsdaten!$B$2:$B$1117,$B2,Versuchsdaten!$C$2:$C$1117,"Sprint_5m",Versuchsdaten!$E$2:$E$1117,$E2,Versuchsdaten!$J$2:$J$1117,1),"")) | L2: =IF(LEFT(C2,7)<>"Sprint_","",IF(COUNTIFS(Versuchsdaten!$A$2:$A$1117,$A2,Versuchsdaten!$B$2:$B$1117,$B2,Versuchsdaten!$C$2:$C$1117,"Sprint_10m",Versuchsdaten!$E$2:$E$1117,$E2,Versuchsdaten!$J$2:$J$1117,1)=1,SUMIFS(Versuchsdaten!$F$2:$F$1117,Versuchsdaten!$A$2:$A$1117,$A2,Versuchsdaten!$B$2:$B$1117,$B2,Versuchsdaten!$C$2:$C$1117,"Sprint_10m",Versuchsdaten!$E$2:$E$1117,$E2,Versuchsdaten!$J$2:$J$1117,1),"")) | M2: =IF(LEFT(C2,7)<>"Sprint_","",IF(COUNTIFS(Versuchsdaten!$A$2:$A$1117,$A2,Versuchsdaten!$B$2:$B$1117,$B2,Versuchsdaten!$C$2:$C$1117,"Sprint_30m",Versuchsdaten!$E$2:$E$1117,$E2,Versuchsdaten!$J$2:$J$1117,1)=1,SUMIFS(Versuchsdaten!$F$2:$F$1117,Versuchsdaten!$A$2:$A$1117,$A2,Versuchsdaten!$B$2:$B$1117,$B2,Versuchsdaten!$C$2:$C$1117,"Sprint_30m",Versuchsdaten!$E$2:$E$1117,$E2,Versuchsdaten!$J$2:$J$1117,1),"")) | N2: =IF(LEFT(C2,7)<>"Sprint_",0,IF(IF(ISNUMBER(K2),IF(K2<=0,1,IF(5/K2>10,1,0)),0)+IF(ISNUMBER(L2),IF(ISNUMBER(K2),IF(L2-K2<=0,1,IF(5/(L2-K2)>10,1,0)),IF(L2<=0,1,IF(10/L2>10,1,0))),0)+IF(ISNUMBER(M2),IF(ISNUMBER(L2),IF(M2-L2<=0,1,IF(20/(M2-L2)>10,1,0)),IF(ISNUMBER(K2),IF(M2-K2<=0,1,IF(25/(M2-K2)>10,1,0)),IF(M2<=0,1,IF(30/M2>10,1,0)))),0)>0,1,0)) | O2: =IF(AND(J2=1,N2=0),1,0) | P2: =INDEX(Personendaten!$J$2:$J$32,MATCH(A2,Personendaten!$A$2:$A$32,0)) | Q2: =IF(O2=1,"",IF(AND(B2="post",P2="nicht angetreten"),"NANG",IF(N2=1,"AUSL",IFERROR(VLOOKUP(H2,Vokabular!$A$2:$B$8,2,FALSE),"UNBEKANNT"))))
A3: BW-01 | B3: prä | C3: Sprint_5m | D3: – | E3: 2 | H3: System nicht aufgenommen | I3: =INDEX(Personendaten!$C$2:$C$32,MATCH(A3,Personendaten!$A$2:$A$32,0)) | J3: =IF(AND(F3<>"",G3=""),1,0) | K3: =IF(LEFT(C3,7)<>"Sprint_","",IF(COUNTIFS(Versuchsdaten!$A$2:$A$1117,$A3,Versuchsdaten!$B$2:$B$1117,$B3,Versuchsdaten!$C$2:$C$1117,"Sprint_5m",Versuchsdaten!$E$2:$E$1117,$E3,Versuchsdaten!$J$2:$J$1117,1)=1,SUMIFS(Versuchsdaten!$F$2:$F$1117,Versuchsdaten!$A$2:$A$1117,$A3,Versuchsdaten!$B$2:$B$1117,$B3,Versuchsdaten!$C$2:$C$1117,"Sprint_5m",Versuchsdaten!$E$2:$E$1117,$E3,Versuchsdaten!$J$2:$J$1117,1),"")) | L3: =IF(LEFT(C3,7)<>"Sprint_","",IF(COUNTIFS(Versuchsdaten!$A$2:$A$1117,$A3,Versuchsdaten!$B$2:$B$1117,$B3,Versuchsdaten!$C$2:$C$1117,"Sprint_10m",Versuchsdaten!$E$2:$E$1117,$E3,Versuchsdaten!$J$2:$J$1117,1)=1,SUMIFS(Versuchsdaten!$F$2:$F$1117,Versuchsdaten!$A$2:$A$1117,$A3,Versuchsdaten!$B$2:$B$1117,$B3,Versuchsdaten!$C$2:$C$1117,"Sprint_10m",Versuchsdaten!$E$2:$E$1117,$E3,Versuchsdaten!$J$2:$J$1117,1),"")) | M3: =IF(LEFT(C3,7)<>"Sprint_","",IF(COUNTIFS(Versuchsdaten!$A$2:$A$1117,$A3,Versuchsdaten!$B$2:$B$1117,$B3,Versuchsdaten!$C$2:$C$1117,"Sprint_30m",Versuchsdaten!$E$2:$E$1117,$E3,Versuchsdaten!$J$2:$J$1117,1)=1,SUMIFS(Versuchsdaten!$F$2:$F$1117,Versuchsdaten!$A$2:$A$1117,$A3,Versuchsdaten!$B$2:$B$1117,$B3,Versuchsdaten!$C$2:$C$1117,"Sprint_30m",Versuchsdaten!$E$2:$E$1117,$E3,Versuchsdaten!$J$2:$J$1117,1),"")) | N3: =IF(LEFT(C3,7)<>"Sprint_",0,IF(IF(ISNUMBER(K3),IF(K3<=0,1,IF(5/K3>10,1,0)),0)+IF(ISNUMBER(L3),IF(ISNUMBER(K3),IF(L3-K3<=0,1,IF(5/(L3-K3)>10,1,0)),IF(L3<=0,1,IF(10/L3>10,1,0))),0)+IF(ISNUMBER(M3),IF(ISNUMBER(L3),IF(M3-L3<=0,1,IF(20/(M3-L3)>10,1,0)),IF(ISNUMBER(K3),IF(M3-K3<=0,1,IF(25/(M3-K3)>10,1,0)),IF(M3<=0,1,IF(30/M3>10,1,0)))),0)>0,1,0)) | O3: =IF(AND(J3=1,N3=0),1,0) | P3: =INDEX(Personendaten!$J$2:$J$32,MATCH(A3,Personendaten!$A$2:$A$32,0)) | Q3: =IF(O3=1,"",IF(AND(B3="post",P3="nicht angetreten"),"NANG",IF(N3=1,"AUSL",IFERROR(VLOOKUP(H3,Vokabular!$A$2:$B$8,2,FALSE),"UNBEKANNT"))))
A4: BW-01 | B4: prä | C4: Sprint_5m | D4: – | E4: 3 | F4: 1.05 | I4: =INDEX(Personendaten!$C$2:$C$32,MATCH(A4,Personendaten!$A$2:$A$32,0)) | J4: =IF(AND(F4<>"",G4=""),1,0) | K4: =IF(LEFT(C4,7)<>"Sprint_","",IF(COUNTIFS(Versuchsdaten!$A$2:$A$1117,$A4,Versuchsdaten!$B$2:$B$1117,$B4,Versuchsdaten!$C$2:$C$1117,"Sprint_5m",Versuchsdaten!$E$2:$E$1117,$E4,Versuchsdaten!$J$2:$J$1117,1)=1,SUMIFS(Versuchsdaten!$F$2:$F$1117,Versuchsdaten!$A$2:$A$1117,$A4,Versuchsdaten!$B$2:$B$1117,$B4,Versuchsdaten!$C$2:$C$1117,"Sprint_5m",Versuchsdaten!$E$2:$E$1117,$E4,Versuchsdaten!$J$2:$J$1117,1),"")) | L4: =IF(LEFT(C4,7)<>"Sprint_","",IF(COUNTIFS(Versuchsdaten!$A$2:$A$1117,$A4,Versuchsdaten!$B$2:$B$1117,$B4,Versuchsdaten!$C$2:$C$1117,"Sprint_10m",Versuchsdaten!$E$2:$E$1117,$E4,Versuchsdaten!$J$2:$J$1117,1)=1,SUMIFS(Versuchsdaten!$F$2:$F$1117,Versuchsdaten!$A$2:$A$1117,$A4,Versuchsdaten!$B$2:$B$1117,$B4,Versuchsdaten!$C$2:$C$1117,"Sprint_10m",Versuchsdaten!$E$2:$E$1117,$E4,Versuchsdaten!$J$2:$J$1117,1),"")) | M4: =IF(LEFT(C4,7)<>"Sprint_","",IF(COUNTIFS(Versuchsdaten!$A$2:$A$1117,$A4,Versuchsdaten!$B$2:$B$1117,$B4,Versuchsdaten!$C$2:$C$1117,"Sprint_30m",Versuchsdaten!$E$2:$E$1117,$E4,Versuchsdaten!$J$2:$J$1117,1)=1,SUMIFS(Versuchsdaten!$F$2:$F$1117,Versuchsdaten!$A$2:$A$1117,$A4,Versuchsdaten!$B$2:$B$1117,$B4,Versuchsdaten!$C$2:$C$1117,"Sprint_30m",Versuchsdaten!$E$2:$E$1117,$E4,Versuchsdaten!$J$2:$J$1117,1),"")) | N4: =IF(LEFT(C4,7)<>"Sprint_",0,IF(IF(ISNUMBER(K4),IF(K4<=0,1,IF(5/K4>10,1,0)),0)+IF(ISNUMBER(L4),IF(ISNUMBER(K4),IF(L4-K4<=0,1,IF(5/(L4-K4)>10,1,0)),IF(L4<=0,1,IF(10/L4>10,1,0))),0)+IF(ISNUMBER(M4),IF(ISNUMBER(L4),IF(M4-L4<=0,1,IF(20/(M4-L4)>10,1,0)),IF(ISNUMBER(K4),IF(M4-K4<=0,1,IF(25/(M4-K4)>10,1,0)),IF(M4<=0,1,IF(30/M4>10,1,0)))),0)>0,1,0)) | O4: =IF(AND(J4=1,N4=0),1,0) | P4: =INDEX(Personendaten!$J$2:$J$32,MATCH(A4,Personendaten!$A$2:$A$32,0)) | Q4: =IF(O4=1,"",IF(AND(B4="post",P4="nicht angetreten"),"NANG",IF(N4=1,"AUSL",IFERROR(VLOOKUP(H4,Vokabular!$A$2:$B$8,2,FALSE),"UNBEKANNT"))))
A5: BW-01 | B5: prä | C5: Sprint_10m | D5: – | E5: 1 | F5: 1.84 | I5: =INDEX(Personendaten!$C$2:$C$32,MATCH(A5,Personendaten!$A$2:$A$32,0)) | J5: =IF(AND(F5<>"",G5=""),1,0) | K5: =IF(LEFT(C5,7)<>"Sprint_","",IF(COUNTIFS(Versuchsdaten!$A$2:$A$1117,$A5,Versuchsdaten!$B$2:$B$1117,$B5,Versuchsdaten!$C$2:$C$1117,"Sprint_5m",Versuchsdaten!$E$2:$E$1117,$E5,Versuchsdaten!$J$2:$J$1117,1)=1,SUMIFS(Versuchsdaten!$F$2:$F$1117,Versuchsdaten!$A$2:$A$1117,$A5,Versuchsdaten!$B$2:$B$1117,$B5,Versuchsdaten!$C$2:$C$1117,"Sprint_5m",Versuchsdaten!$E$2:$E$1117,$E5,Versuchsdaten!$J$2:$J$1117,1),"")) | L5: =IF(LEFT(C5,7)<>"Sprint_","",IF(COUNTIFS(Versuchsdaten!$A$2:$A$1117,$A5,Versuchsdaten!$B$2:$B$1117,$B5,Versuchsdaten!$C$2:$C$1117,"Sprint_10m",Versuchsdaten!$E$2:$E$1117,$E5,Versuchsdaten!$J$2:$J$1117,1)=1,SUMIFS(Versuchsdaten!$F$2:$F$1117,Versuchsdaten!$A$2:$A$1117,$A5,Versuchsdaten!$B$2:$B$1117,$B5,Versuchsdaten!$C$2:$C$1117,"Sprint_10m",Versuchsdaten!$E$2:$E$1117,$E5,Versuchsdaten!$J$2:$J$1117,1),"")) | M5: =IF(LEFT(C5,7)<>"Sprint_","",IF(COUNTIFS(Versuchsdaten!$A$2:$A$1117,$A5,Versuchsdaten!$B$2:$B$1117,$B5,Versuchsdaten!$C$2:$C$1117,"Sprint_30m",Versuchsdaten!$E$2:$E$1117,$E5,Versuchsdaten!$J$2:$J$1117,1)=1,SUMIFS(Versuchsdaten!$F$2:$F$1117,Versuchsdaten!$A$2:$A$1117,$A5,Versuchsdaten!$B$2:$B$1117,$B5,Versuchsdaten!$C$2:$C$1117,"Sprint_30m",Versuchsdaten!$E$2:$E$1117,$E5,Versuchsdaten!$J$2:$J$1117,1),"")) | N5: =IF(LEFT(C5,7)<>"Sprint_",0,IF(IF(ISNUMBER(K5),IF(K5<=0,1,IF(5/K5>10,1,0)),0)+IF(ISNUMBER(L5),IF(ISNUMBER(K5),IF(L5-K5<=0,1,IF(5/(L5-K5)>10,1,0)),IF(L5<=0,1,IF(10/L5>10,1,0))),0)+IF(ISNUMBER(M5),IF(ISNUMBER(L5),IF(M5-L5<=0,1,IF(20/(M5-L5)>10,1,0)),IF(ISNUMBER(K5),IF(M5-K5<=0,1,IF(25/(M5-K5)>10,1,0)),IF(M5<=0,1,IF(30/M5>10,1,0)))),0)>0,1,0)) | O5: =IF(AND(J5=1,N5=0),1,0) | P5: =INDEX(Personendaten!$J$2:$J$32,MATCH(A5,Personendaten!$A$2:$A$32,0)) | Q5: =IF(O5=1,"",IF(AND(B5="post",P5="nicht angetreten"),"NANG",IF(N5=1,"AUSL",IFERROR(VLOOKUP(H5,Vokabular!$A$2:$B$8,2,FALSE),"UNBEKANNT"))))
A6: BW-01 | B6: prä | C6: Sprint_10m | D6: – | E6: 2 | F6: 1.93 | I6: =INDEX(Personendaten!$C$2:$C$32,MATCH(A6,Personendaten!$A$2:$A$32,0)) | J6: =IF(AND(F6<>"",G6=""),1,0) | K6: =IF(LEFT(C6,7)<>"Sprint_","",IF(COUNTIFS(Versuchsdaten!$A$2:$A$1117,$A6,Versuchsdaten!$B$2:$B$1117,$B6,Versuchsdaten!$C$2:$C$1117,"Sprint_5m",Versuchsdaten!$E$2:$E$1117,$E6,Versuchsdaten!$J$2:$J$1117,1)=1,SUMIFS(Versuchsdaten!$F$2:$F$1117,Versuchsdaten!$A$2:$A$1117,$A6,Versuchsdaten!$B$2:$B$1117,$B6,Versuchsdaten!$C$2:$C$1117,"Sprint_5m",Versuchsdaten!$E$2:$E$1117,$E6,Versuchsdaten!$J$2:$J$1117,1),"")) | L6: =IF(LEFT(C6,7)<>"Sprint_","",IF(COUNTIFS(Versuchsdaten!$A$2:$A$1117,$A6,Versuchsdaten!$B$2:$B$1117,$B6,Versuchsdaten!$C$2:$C$1117,"Sprint_10m",Versuchsdaten!$E$2:$E$1117,$E6,Versuchsdaten!$J$2:$J$1117,1)=1,SUMIFS(Versuchsdaten!$F$2:$F$1117,Versuchsdaten!$A$2:$A$1117,$A6,Versuchsdaten!$B$2:$B$1117,$B6,Versuchsdaten!$C$2:$C$1117,"Sprint_10m",Versuchsdaten!$E$2:$E$1117,$E6,Versuchsdaten!$J$2:$J$1117,1),"")) | M6: =IF(LEFT(C6,7)<>"Sprint_","",IF(COUNTIFS(Versuchsdaten!$A$2:$A$1117,$A6,Versuchsdaten!$B$2:$B$1117,$B6,Versuchsdaten!$C$2:$C$1117,"Sprint_30m",Versuchsdaten!$E$2:$E$1117,$E6,Versuchsdaten!$J$2:$J$1117,1)=1,SUMIFS(Versuchsdaten!$F$2:$F$1117,Versuchsdaten!$A$2:$A$1117,$A6,Versuchsdaten!$B$2:$B$1117,$B6,Versuchsdaten!$C$2:$C$1117,"Sprint_30m",Versuchsdaten!$E$2:$E$1117,$E6,Versuchsdaten!$J$2:$J$1117,1),"")) | N6: =IF(LEFT(C6,7)<>"Sprint_",0,IF(IF(ISNUMBER(K6),IF(K6<=0,1,IF(5/K6>10,1,0)),0)+IF(ISNUMBER(L6),IF(ISNUMBER(K6),IF(L6-K6<=0,1,IF(5/(L6-K6)>10,1,0)),IF(L6<=0,1,IF(10/L6>10,1,0))),0)+IF(ISNUMBER(M6),IF(ISNUMBER(L6),IF(M6-L6<=0,1,IF(20/(M6-L6)>10,1,0)),IF(ISNUMBER(K6),IF(M6-K6<=0,1,IF(25/(M6-K6)>10,1,0)),IF(M6<=0,1,IF(30/M6>10,1,0)))),0)>0,1,0)) | O6: =IF(AND(J6=1,N6=0),1,0) | P6: =INDEX(Personendaten!$J$2:$J$32,MATCH(A6,Personendaten!$A$2:$A$32,0)) | Q6: =IF(O6=1,"",IF(AND(B6="post",P6="nicht angetreten"),"NANG",IF(N6=1,"AUSL",IFERROR(VLOOKUP(H6,Vokabular!$A$2:$B$8,2,FALSE),"UNBEKANNT"))))
A7: BW-01 | B7: prä | C7: Sprint_10m | D7: – | E7: 3 | F7: 1.9 | I7: =INDEX(Personendaten!$C$2:$C$32,MATCH(A7,Personendaten!$A$2:$A$32,0)) | J7: =IF(AND(F7<>"",G7=""),1,0) | K7: =IF(LEFT(C7,7)<>"Sprint_","",IF(COUNTIFS(Versuchsdaten!$A$2:$A$1117,$A7,Versuchsdaten!$B$2:$B$1117,$B7,Versuchsdaten!$C$2:$C$1117,"Sprint_5m",Versuchsdaten!$E$2:$E$1117,$E7,Versuchsdaten!$J$2:$J$1117,1)=1,SUMIFS(Versuchsdaten!$F$2:$F$1117,Versuchsdaten!$A$2:$A$1117,$A7,Versuchsdaten!$B$2:$B$1117,$B7,Versuchsdaten!$C$2:$C$1117,"Sprint_5m",Versuchsdaten!$E$2:$E$1117,$E7,Versuchsdaten!$J$2:$J$1117,1),"")) | L7: =IF(LEFT(C7,7)<>"Sprint_","",IF(COUNTIFS(Versuchsdaten!$A$2:$A$1117,$A7,Versuchsdaten!$B$2:$B$1117,$B7,Versuchsdaten!$C$2:$C$1117,"Sprint_10m",Versuchsdaten!$E$2:$E$1117,$E7,Versuchsdaten!$J$2:$J$1117,1)=1,SUMIFS(Versuchsdaten!$F$2:$F$1117,Versuchsdaten!$A$2:$A$1117,$A7,Versuchsdaten!$B$2:$B$1117,$B7,Versuchsdaten!$C$2:$C$1117,"Sprint_10m",Versuchsdaten!$E$2:$E$1117,$E7,Versuchsdaten!$J$2:$J$1117,1),"")) | M7: =IF(LEFT(C7,7)<>"Sprint_","",IF(COUNTIFS(Versuchsdaten!$A$2:$A$1117,$A7,Versuchsdaten!$B$2:$B$1117,$B7,Versuchsdaten!$C$2:$C$1117,"Sprint_30m",Versuchsdaten!$E$2:$E$1117,$E7,Versuchsdaten!$J$2:$J$1117,1)=1,SUMIFS(Versuchsdaten!$F$2:$F$1117,Versuchsdaten!$A$2:$A$1117,$A7,Versuchsdaten!$B$2:$B$1117,$B7,Versuchsdaten!$C$2:$C$1117,"Sprint_30m",Versuchsdaten!$E$2:$E$1117,$E7,Versuchsdaten!$J$2:$J$1117,1),"")) | N7: =IF(LEFT(C7,7)<>"Sprint_",0,IF(IF(ISNUMBER(K7),IF(K7<=0,1,IF(5/K7>10,1,0)),0)+IF(ISNUMBER(L7),IF(ISNUMBER(K7),IF(L7-K7<=0,1,IF(5/(L7-K7)>10,1,0)),IF(L7<=0,1,IF(10/L7>10,1,0))),0)+IF(ISNUMBER(M7),IF(ISNUMBER(L7),IF(M7-L7<=0,1,IF(20/(M7-L7)>10,1,0)),IF(ISNUMBER(K7),IF(M7-K7<=0,1,IF(25/(M7-K7)>10,1,0)),IF(M7<=0,1,IF(30/M7>10,1,0)))),0)>0,1,0)) | O7: =IF(AND(J7=1,N7=0),1,0) | P7: =INDEX(Personendaten!$J$2:$J$32,MATCH(A7,Personendaten!$A$2:$A$32,0)) | Q7: =IF(O7=1,"",IF(AND(B7="post",P7="nicht angetreten"),"NANG",IF(N7=1,"AUSL",IFERROR(VLOOKUP(H7,Vokabular!$A$2:$B$8,2,FALSE),"UNBEKANNT"))))
A8: BW-01 | B8: prä | C8: Sprint_30m | D8: – | E8: 1 | F8: 4.53 | I8: =INDEX(Personendaten!$C$2:$C$32,MATCH(A8,Personendaten!$A$2:$A$32,0)) | J8: =IF(AND(F8<>"",G8=""),1,0) | K8: =IF(LEFT(C8,7)<>"Sprint_","",IF(COUNTIFS(Versuchsdaten!$A$2:$A$1117,$A8,Versuchsdaten!$B$2:$B$1117,$B8,Versuchsdaten!$C$2:$C$1117,"Sprint_5m",Versuchsdaten!$E$2:$E$1117,$E8,Versuchsdaten!$J$2:$J$1117,1)=1,SUMIFS(Versuchsdaten!$F$2:$F$1117,Versuchsdaten!$A$2:$A$1117,$A8,Versuchsdaten!$B$2:$B$1117,$B8,Versuchsdaten!$C$2:$C$1117,"Sprint_5m",Versuchsdaten!$E$2:$E$1117,$E8,Versuchsdaten!$J$2:$J$1117,1),"")) | L8: =IF(LEFT(C8,7)<>"Sprint_","",IF(COUNTIFS(Versuchsdaten!$A$2:$A$1117,$A8,Versuchsdaten!$B$2:$B$1117,$B8,Versuchsdaten!$C$2:$C$1117,"Sprint_10m",Versuchsdaten!$E$2:$E$1117,$E8,Versuchsdaten!$J$2:$J$1117,1)=1,SUMIFS(Versuchsdaten!$F$2:$F$1117,Versuchsdaten!$A$2:$A$1117,$A8,Versuchsdaten!$B$2:$B$1117,$B8,Versuchsdaten!$C$2:$C$1117,"Sprint_10m",Versuchsdaten!$E$2:$E$1117,$E8,Versuchsdaten!$J$2:$J$1117,1),"")) | M8: =IF(LEFT(C8,7)<>"Sprint_","",IF(COUNTIFS(Versuchsdaten!$A$2:$A$1117,$A8,Versuchsdaten!$B$2:$B$1117,$B8,Versuchsdaten!$C$2:$C$1117,"Sprint_30m",Versuchsdaten!$E$2:$E$1117,$E8,Versuchsdaten!$J$2:$J$1117,1)=1,SUMIFS(Versuchsdaten!$F$2:$F$1117,Versuchsdaten!$A$2:$A$1117,$A8,Versuchsdaten!$B$2:$B$1117,$B8,Versuchsdaten!$C$2:$C$1117,"Sprint_30m",Versuchsdaten!$E$2:$E$1117,$E8,Versuchsdaten!$J$2:$J$1117,1),"")) | N8: =IF(LEFT(C8,7)<>"Sprint_",0,IF(IF(ISNUMBER(K8),IF(K8<=0,1,IF(5/K8>10,1,0)),0)+IF(ISNUMBER(L8),IF(ISNUMBER(K8),IF(L8-K8<=0,1,IF(5/(L8-K8)>10,1,0)),IF(L8<=0,1,IF(10/L8>10,1,0))),0)+IF(ISNUMBER(M8),IF(ISNUMBER(L8),IF(M8-L8<=0,1,IF(20/(M8-L8)>10,1,0)),IF(ISNUMBER(K8),IF(M8-K8<=0,1,IF(25/(M8-K8)>10,1,0)),IF(M8<=0,1,IF(30/M8>10,1,0)))),0)>0,1,0)) | O8: =IF(AND(J8=1,N8=0),1,0) | P8: =INDEX(Personendaten!$J$2:$J$32,MATCH(A8,Personendaten!$A$2:$A$32,0)) | Q8: =IF(O8=1,"",IF(AND(B8="post",P8="nicht angetreten"),"NANG",IF(N8=1,"AUSL",IFERROR(VLOOKUP(H8,Vokabular!$A$2:$B$8,2,FALSE),"UNBEKANNT"))))
A9: BW-01 | B9: prä | C9: Sprint_30m | D9: – | E9: 2 | F9: 4.68 | I9: =INDEX(Personendaten!$C$2:$C$32,MATCH(A9,Personendaten!$A$2:$A$32,0)) | J9: =IF(AND(F9<>"",G9=""),1,0) | K9: =IF(LEFT(C9,7)<>"Sprint_","",IF(COUNTIFS(Versuchsdaten!$A$2:$A$1117,$A9,Versuchsdaten!$B$2:$B$1117,$B9,Versuchsdaten!$C$2:$C$1117,"Sprint_5m",Versuchsdaten!$E$2:$E$1117,$E9,Versuchsdaten!$J$2:$J$1117,1)=1,SUMIFS(Versuchsdaten!$F$2:$F$1117,Versuchsdaten!$A$2:$A$1117,$A9,Versuchsdaten!$B$2:$B$1117,$B9,Versuchsdaten!$C$2:$C$1117,"Sprint_5m",Versuchsdaten!$E$2:$E$1117,$E9,Versuchsdaten!$J$2:$J$1117,1),"")) | L9: =IF(LEFT(C9,7)<>"Sprint_","",IF(COUNTIFS(Versuchsdaten!$A$2:$A$1117,$A9,Versuchsdaten!$B$2:$B$1117,$B9,Versuchsdaten!$C$2:$C$1117,"Sprint_10m",Versuchsdaten!$E$2:$E$1117,$E9,Versuchsdaten!$J$2:$J$1117,1)=1,SUMIFS(Versuchsdaten!$F$2:$F$1117,Versuchsdaten!$A$2:$A$1117,$A9,Versuchsdaten!$B$2:$B$1117,$B9,Versuchsdaten!$C$2:$C$1117,"Sprint_10m",Versuchsdaten!$E$2:$E$1117,$E9,Versuchsdaten!$J$2:$J$1117,1),"")) | M9: =IF(LEFT(C9,7)<>"Sprint_","",IF(COUNTIFS(Versuchsdaten!$A$2:$A$1117,$A9,Versuchsdaten!$B$2:$B$1117,$B9,Versuchsdaten!$C$2:$C$1117,"Sprint_30m",Versuchsdaten!$E$2:$E$1117,$E9,Versuchsdaten!$J$2:$J$1117,1)=1,SUMIFS(Versuchsdaten!$F$2:$F$1117,Versuchsdaten!$A$2:$A$1117,$A9,Versuchsdaten!$B$2:$B$1117,$B9,Versuchsdaten!$C$2:$C$1117,"Sprint_30m",Versuchsdaten!$E$2:$E$1117,$E9,Versuchsdaten!$J$2:$J$1117,1),"")) | N9: =IF(LEFT(C9,7)<>"Sprint_",0,IF(IF(ISNUMBER(K9),IF(K9<=0,1,IF(5/K9>10,1,0)),0)+IF(ISNUMBER(L9),IF(ISNUMBER(K9),IF(L9-K9<=0,1,IF(5/(L9-K9)>10,1,0)),IF(L9<=0,1,IF(10/L9>10,1,0))),0)+IF(ISNUMBER(M9),IF(ISNUMBER(L9),IF(M9-L9<=0,1,IF(20/(M9-L9)>10,1,0)),IF(ISNUMBER(K9),IF(M9-K9<=0,1,IF(25/(M9-K9)>10,1,0)),IF(M9<=0,1,IF(30/M9>10,1,0)))),0)>0,1,0)) | O9: =IF(AND(J9=1,N9=0),1,0) | P9: =INDEX(Personendaten!$J$2:$J$32,MATCH(A9,Personendaten!$A$2:$A$32,0)) | Q9: =IF(O9=1,"",IF(AND(B9="post",P9="nicht angetreten"),"NANG",IF(N9=1,"AUSL",IFERROR(VLOOKUP(H9,Vokabular!$A$2:$B$8,2,FALSE),"UNBEKANNT"))))
A10: BW-01 | B10: prä | C10: Sprint_30m | D10: – | E10: 3 | F10: 4.55 | I10: =INDEX(Personendaten!$C$2:$C$32,MATCH(A10,Personendaten!$A$2:$A$32,0)) | J10: =IF(AND(F10<>"",G10=""),1,0) | K10: =IF(LEFT(C10,7)<>"Sprint_","",IF(COUNTIFS(Versuchsdaten!$A$2:$A$1117,$A10,Versuchsdaten!$B$2:$B$1117,$B10,Versuchsdaten!$C$2:$C$1117,"Sprint_5m",Versuchsdaten!$E$2:$E$1117,$E10,Versuchsdaten!$J$2:$J$1117,1)=1,SUMIFS(Versuchsdaten!$F$2:$F$1117,Versuchsdaten!$A$2:$A$1117,$A10,Versuchsdaten!$B$2:$B$1117,$B10,Versuchsdaten!$C$2:$C$1117,"Sprint_5m",Versuchsdaten!$E$2:$E$1117,$E10,Versuchsdaten!$J$2:$J$1117,1),"")) | L10: =IF(LEFT(C10,7)<>"Sprint_","",IF(COUNTIFS(Versuchsdaten!$A$2:$A$1117,$A10,Versuchsdaten!$B$2:$B$1117,$B10,Versuchsdaten!$C$2:$C$1117,"Sprint_10m",Versuchsdaten!$E$2:$E$1117,$E10,Versuchsdaten!$J$2:$J$1117,1)=1,SUMIFS(Versuchsdaten!$F$2:$F$1117,Versuchsdaten!$A$2:$A$1117,$A10,Versuchsdaten!$B$2:$B$1117,$B10,Versuchsdaten!$C$2:$C$1117,"Sprint_10m",Versuchsdaten!$E$2:$E$1117,$E10,Versuchsdaten!$J$2:$J$1117,1),"")) | M10: =IF(LEFT(C10,7)<>"Sprint_","",IF(COUNTIFS(Versuchsdaten!$A$2:$A$1117,$A10,Versuchsdaten!$B$2:$B$1117,$B10,Versuchsdaten!$C$2:$C$1117,"Sprint_30m",Versuchsdaten!$E$2:$E$1117,$E10,Versuchsdaten!$J$2:$J$1117,1)=1,SUMIFS(Versuchsdaten!$F$2:$F$1117,Versuchsdaten!$A$2:$A$1117,$A10,Versuchsdaten!$B$2:$B$1117,$B10,Versuchsdaten!$C$2:$C$1117,"Sprint_30m",Versuchsdaten!$E$2:$E$1117,$E10,Versuchsdaten!$J$2:$J$1117,1),"")) | N10: =IF(LEFT(C10,7)<>"Sprint_",0,IF(IF(ISNUMBER(K10),IF(K10<=0,1,IF(5/K10>10,1,0)),0)+IF(ISNUMBER(L10),IF(ISNUMBER(K10),IF(L10-K10<=0,1,IF(5/(L10-K10)>10,1,0)),IF(L10<=0,1,IF(10/L10>10,1,0))),0)+IF(ISNUMBER(M10),IF(ISNUMBER(L10),IF(M10-L10<=0,1,IF(20/(M10-L10)>10,1,0)),IF(ISNUMBER(K10),IF(M10-K10<=0,1,IF(25/(M10-K10)>10,1,0)),IF(M10<=0,1,IF(30/M10>10,1,0)))),0)>0,1,0)) | O10: =IF(AND(J10=1,N10=0),1,0) | P10: =INDEX(Personendaten!$J$2:$J$32,MATCH(A10,Personendaten!$A$2:$A$32,0)) | Q10: =IF(O10=1,"",IF(AND(B10="post",P10="nicht angetreten"),"NANG",IF(N10=1,"AUSL",IFERROR(VLOOKUP(H10,Vokabular!$A$2:$B$8,2,FALSE),"UNBEKANNT"))))
A11: BW-01 | B11: prä | C11: Standweitsprung | D11: – | E11: 1 | G11: x | H11: Kein fester Stand | I11: =INDEX(Personendaten!$C$2:$C$32,MATCH(A11,Personendaten!$A$2:$A$32,0)) | J11: =IF(AND(F11<>"",G11=""),1,0) | K11: =IF(LEFT(C11,7)<>"Sprint_","",IF(COUNTIFS(Versuchsdaten!$A$2:$A$1117,$A11,Versuchsdaten!$B$2:$B$1117,$B11,Versuchsdaten!$C$2:$C$1117,"Sprint_5m",Versuchsdaten!$E$2:$E$1117,$E11,Versuchsdaten!$J$2:$J$1117,1)=1,SUMIFS(Versuchsdaten!$F$2:$F$1117,Versuchsdaten!$A$2:$A$1117,$A11,Versuchsdaten!$B$2:$B$1117,$B11,Versuchsdaten!$C$2:$C$1117,"Sprint_5m",Versuchsdaten!$E$2:$E$1117,$E11,Versuchsdaten!$J$2:$J$1117,1),"")) | L11: =IF(LEFT(C11,7)<>"Sprint_","",IF(COUNTIFS(Versuchsdaten!$A$2:$A$1117,$A11,Versuchsdaten!$B$2:$B$1117,$B11,Versuchsdaten!$C$2:$C$1117,"Sprint_10m",Versuchsdaten!$E$2:$E$1117,$E11,Versuchsdaten!$J$2:$J$1117,1)=1,SUMIFS(Versuchsdaten!$F$2:$F$1117,Versuchsdaten!$A$2:$A$1117,$A11,Versuchsdaten!$B$2:$B$1117,$B11,Versuchsdaten!$C$2:$C$1117,"Sprint_10m",Versuchsdaten!$E$2:$E$1117,$E11,Versuchsdaten!$J$2:$J$1117,1),"")) | M11: =IF(LEFT(C11,7)<>"Sprint_","",IF(COUNTIFS(Versuchsdaten!$A$2:$A$1117,$A11,Versuchsdaten!$B$2:$B$1117,$B11,Versuchsdaten!$C$2:$C$1117,"Sprint_30m",Versuchsdaten!$E$2:$E$1117,$E11,Versuchsdaten!$J$2:$J$1117,1)=1,SUMIFS(Versuchsdaten!$F$2:$F$1117,Versuchsdaten!$A$2:$A$1117,$A11,Versuchsdaten!$B$2:$B$1117,$B11,Versuchsdaten!$C$2:$C$1117,"Sprint_30m",Versuchsdaten!$E$2:$E$1117,$E11,Versuchsdaten!$J$2:$J$1117,1),"")) | N11: =IF(LEFT(C11,7)<>"Sprint_",0,IF(IF(ISNUMBER(K11),IF(K11<=0,1,IF(5/K11>10,1,0)),0)+IF(ISNUMBER(L11),IF(ISNUMBER(K11),IF(L11-K11<=0,1,IF(5/(L11-K11)>10,1,0)),IF(L11<=0,1,IF(10/L11>10,1,0))),0)+IF(ISNUMBER(M11),IF(ISNUMBER(L11),IF(M11-L11<=0,1,IF(20/(M11-L11)>10,1,0)),IF(ISNUMBER(K11),IF(M11-K11<=0,1,IF(25/(M11-K11)>10,1,0)),IF(M11<=0,1,IF(30/M11>10,1,0)))),0)>0,1,0)) | O11: =IF(AND(J11=1,N11=0),1,0) | P11: =INDEX(Personendaten!$J$2:$J$32,MATCH(A11,Personendaten!$A$2:$A$32,0)) | Q11: =IF(O11=1,"",IF(AND(B11="post",P11="nicht angetreten"),"NANG",IF(N11=1,"AUSL",IFERROR(VLOOKUP(H11,Vokabular!$A$2:$B$8,2,FALSE),"UNBEKANNT"))))
A12: BW-01 | B12: prä | C12: Standweitsprung | D12: – | E12: 2 | F12: 219 | I12: =INDEX(Personendaten!$C$2:$C$32,MATCH(A12,Personendaten!$A$2:$A$32,0)) | J12: =IF(AND(F12<>"",G12=""),1,0) | K12: =IF(LEFT(C12,7)<>"Sprint_","",IF(COUNTIFS(Versuchsdaten!$A$2:$A$1117,$A12,Versuchsdaten!$B$2:$B$1117,$B12,Versuchsdaten!$C$2:$C$1117,"Sprint_5m",Versuchsdaten!$E$2:$E$1117,$E12,Versuchsdaten!$J$2:$J$1117,1)=1,SUMIFS(Versuchsdaten!$F$2:$F$1117,Versuchsdaten!$A$2:$A$1117,$A12,Versuchsdaten!$B$2:$B$1117,$B12,Versuchsdaten!$C$2:$C$1117,"Sprint_5m",Versuchsdaten!$E$2:$E$1117,$E12,Versuchsdaten!$J$2:$J$1117,1),"")) | L12: =IF(LEFT(C12,7)<>"Sprint_","",IF(COUNTIFS(Versuchsdaten!$A$2:$A$1117,$A12,Versuchsdaten!$B$2:$B$1117,$B12,Versuchsdaten!$C$2:$C$1117,"Sprint_10m",Versuchsdaten!$E$2:$E$1117,$E12,Versuchsdaten!$J$2:$J$1117,1)=1,SUMIFS(Versuchsdaten!$F$2:$F$1117,Versuchsdaten!$A$2:$A$1117,$A12,Versuchsdaten!$B$2:$B$1117,$B12,Versuchsdaten!$C$2:$C$1117,"Sprint_10m",Versuchsdaten!$E$2:$E$1117,$E12,Versuchsdaten!$J$2:$J$1117,1),"")) | M12: =IF(LEFT(C12,7)<>"Sprint_","",IF(COUNTIFS(Versuchsdaten!$A$2:$A$1117,$A12,Versuchsdaten!$B$2:$B$1117,$B12,Versuchsdaten!$C$2:$C$1117,"Sprint_30m",Versuchsdaten!$E$2:$E$1117,$E12,Versuchsdaten!$J$2:$J$1117,1)=1,SUMIFS(Versuchsdaten!$F$2:$F$1117,Versuchsdaten!$A$2:$A$1117,$A12,Versuchsdaten!$B$2:$B$1117,$B12,Versuchsdaten!$C$2:$C$1117,"Sprint_30m",Versuchsdaten!$E$2:$E$1117,$E12,Versuchsdaten!$J$2:$J$1117,1),"")) | N12: =IF(LEFT(C12,7)<>"Sprint_",0,IF(IF(ISNUMBER(K12),IF(K12<=0,1,IF(5/K12>10,1,0)),0)+IF(ISNUMBER(L12),IF(ISNUMBER(K12),IF(L12-K12<=0,1,IF(5/(L12-K12)>10,1,0)),IF(L12<=0,1,IF(10/L12>10,1,0))),0)+IF(ISNUMBER(M12),IF(ISNUMBER(L12),IF(M12-L12<=0,1,IF(20/(M12-L12)>10,1,0)),IF(ISNUMBER(K12),IF(M12-K12<=0,1,IF(25/(M12-K12)>10,1,0)),IF(M12<=0,1,IF(30/M12>10,1,0)))),0)>0,1,0)) | O12: =IF(AND(J12=1,N12=0),1,0) | P12: =INDEX(Personendaten!$J$2:$J$32,MATCH(A12,Personendaten!$A$2:$A$32,0)) | Q12: =IF(O12=1,"",IF(AND(B12="post",P12="nicht angetreten"),"NANG",IF(N12=1,"AUSL",IFERROR(VLOOKUP(H12,Vokabular!$A$2:$B$8,2,FALSE),"UNBEKANNT"))))
A13: BW-01 | B13: prä | C13: Standweitsprung | D13: – | E13: 3 | F13: 222 | I13: =INDEX(Personendaten!$C$2:$C$32,MATCH(A13,Personendaten!$A$2:$A$32,0)) | J13: =IF(AND(F13<>"",G13=""),1,0) | K13: =IF(LEFT(C13,7)<>"Sprint_","",IF(COUNTIFS(Versuchsdaten!$A$2:$A$1117,$A13,Versuchsdaten!$B$2:$B$1117,$B13,Versuchsdaten!$C$2:$C$1117,"Sprint_5m",Versuchsdaten!$E$2:$E$1117,$E13,Versuchsdaten!$J$2:$J$1117,1)=1,SUMIFS(Versuchsdaten!$F$2:$F$1117,Versuchsdaten!$A$2:$A$1117,$A13,Versuchsdaten!$B$2:$B$1117,$B13,Versuchsdaten!$C$2:$C$1117,"Sprint_5m",Versuchsdaten!$E$2:$E$1117,$E13,Versuchsdaten!$J$2:$J$1117,1),"")) | L13: =IF(LEFT(C13,7)<>"Sprint_","",IF(COUNTIFS(Versuchsdaten!$A$2:$A$1117,$A13,Versuchsdaten!$B$2:$B$1117,$B13,Versuchsdaten!$C$2:$C$1117,"Sprint_10m",Versuchsdaten!$E$2:$E$1117,$E13,Versuchsdaten!$J$2:$J$1117,1)=1,SUMIFS(Versuchsdaten!$F$2:$F$1117,Versuchsdaten!$A$2:$A$1117,$A13,Versuchsdaten!$B$2:$B$1117,$B13,Versuchsdaten!$C$2:$C$1117,"Sprint_10m",Versuchsdaten!$E$2:$E$1117,$E13,Versuchsdaten!$J$2:$J$1117,1),"")) | M13: =IF(LEFT(C13,7)<>"Sprint_","",IF(COUNTIFS(Versuchsdaten!$A$2:$A$1117,$A13,Versuchsdaten!$B$2:$B$1117,$B13,Versuchsdaten!$C$2:$C$1117,"Sprint_30m",Versuchsdaten!$E$2:$E$1117,$E13,Versuchsdaten!$J$2:$J$1117,1)=1,SUMIFS(Versuchsdaten!$F$2:$F$1117,Versuchsdaten!$A$2:$A$1117,$A13,Versuchsdaten!$B$2:$B$1117,$B13,Versuchsdaten!$C$2:$C$1117,"Sprint_30m",Versuchsdaten!$E$2:$E$1117,$E13,Versuchsdaten!$J$2:$J$1117,1),"")) | N13: =IF(LEFT(C13,7)<>"Sprint_",0,IF(IF(ISNUMBER(K13),IF(K13<=0,1,IF(5/K13>10,1,0)),0)+IF(ISNUMBER(L13),IF(ISNUMBER(K13),IF(L13-K13<=0,1,IF(5/(L13-K13)>10,1,0)),IF(L13<=0,1,IF(10/L13>10,1,0))),0)+IF(ISNUMBER(M13),IF(ISNUMBER(L13),IF(M13-L13<=0,1,IF(20/(M13-L13)>10,1,0)),IF(ISNUMBER(K13),IF(M13-K13<=0,1,IF(25/(M13-K13)>10,1,0)),IF(M13<=0,1,IF(30/M13>10,1,0)))),0)>0,1,0)) | O13: =IF(AND(J13=1,N13=0),1,0) | P13: =INDEX(Personendaten!$J$2:$J$32,MATCH(A13,Personendaten!$A$2:$A$32,0)) | Q13: =IF(O13=1,"",IF(AND(B13="post",P13="nicht angetreten"),"NANG",IF(N13=1,"AUSL",IFERROR(VLOOKUP(H13,Vokabular!$A$2:$B$8,2,FALSE),"UNBEKANNT"))))
A14: BW-01 | B14: prä | C14: COD_505 | D14: L | E14: 1 | F14: 2.6 | I14: =INDEX(Personendaten!$C$2:$C$32,MATCH(A14,Personendaten!$A$2:$A$32,0)) | J14: =IF(AND(F14<>"",G14=""),1,0) | K14: =IF(LEFT(C14,7)<>"Sprint_","",IF(COUNTIFS(Versuchsdaten!$A$2:$A$1117,$A14,Versuchsdaten!$B$2:$B$1117,$B14,Versuchsdaten!$C$2:$C$1117,"Sprint_5m",Versuchsdaten!$E$2:$E$1117,$E14,Versuchsdaten!$J$2:$J$1117,1)=1,SUMIFS(Versuchsdaten!$F$2:$F$1117,Versuchsdaten!$A$2:$A$1117,$A14,Versuchsdaten!$B$2:$B$1117,$B14,Versuchsdaten!$C$2:$C$1117,"Sprint_5m",Versuchsdaten!$E$2:$E$1117,$E14,Versuchsdaten!$J$2:$J$1117,1),"")) | L14: =IF(LEFT(C14,7)<>"Sprint_","",IF(COUNTIFS(Versuchsdaten!$A$2:$A$1117,$A14,Versuchsdaten!$B$2:$B$1117,$B14,Versuchsdaten!$C$2:$C$1117,"Sprint_10m",Versuchsdaten!$E$2:$E$1117,$E14,Versuchsdaten!$J$2:$J$1117,1)=1,SUMIFS(Versuchsdaten!$F$2:$F$1117,Versuchsdaten!$A$2:$A$1117,$A14,Versuchsdaten!$B$2:$B$1117,$B14,Versuchsdaten!$C$2:$C$1117,"Sprint_10m",Versuchsdaten!$E$2:$E$1117,$E14,Versuchsdaten!$J$2:$J$1117,1),"")) | M14: =IF(LEFT(C14,7)<>"Sprint_","",IF(COUNTIFS(Versuchsdaten!$A$2:$A$1117,$A14,Versuchsdaten!$B$2:$B$1117,$B14,Versuchsdaten!$C$2:$C$1117,"Sprint_30m",Versuchsdaten!$E$2:$E$1117,$E14,Versuchsdaten!$J$2:$J$1117,1)=1,SUMIFS(Versuchsdaten!$F$2:$F$1117,Versuchsdaten!$A$2:$A$1117,$A14,Versuchsdaten!$B$2:$B$1117,$B14,Versuchsdaten!$C$2:$C$1117,"Sprint_30m",Versuchsdaten!$E$2:$E$1117,$E14,Versuchsdaten!$J$2:$J$1117,1),"")) | N14: =IF(LEFT(C14,7)<>"Sprint_",0,IF(IF(ISNUMBER(K14),IF(K14<=0,1,IF(5/K14>10,1,0)),0)+IF(ISNUMBER(L14),IF(ISNUMBER(K14),IF(L14-K14<=0,1,IF(5/(L14-K14)>10,1,0)),IF(L14<=0,1,IF(10/L14>10,1,0))),0)+IF(ISNUMBER(M14),IF(ISNUMBER(L14),IF(M14-L14<=0,1,IF(20/(M14-L14)>10,1,0)),IF(ISNUMBER(K14),IF(M14-K14<=0,1,IF(25/(M14-K14)>10,1,0)),IF(M14<=0,1,IF(30/M14>10,1,0)))),0)>0,1,0)) | O14: =IF(AND(J14=1,N14=0),1,0) | P14: =INDEX(Personendaten!$J$2:$J$32,MATCH(A14,Personendaten!$A$2:$A$32,0)) | Q14: =IF(O14=1,"",IF(AND(B14="post",P14="nicht angetreten"),"NANG",IF(N14=1,"AUSL",IFERROR(VLOOKUP(H14,Vokabular!$A$2:$B$8,2,FALSE),"UNBEKANNT"))))
A15: BW-01 | B15: prä | C15: COD_505 | D15: L | E15: 2 | F15: 2.44 | I15: =INDEX(Personendaten!$C$2:$C$32,MATCH(A15,Personendaten!$A$2:$A$32,0)) | J15: =IF(AND(F15<>"",G15=""),1,0) | K15: =IF(LEFT(C15,7)<>"Sprint_","",IF(COUNTIFS(Versuchsdaten!$A$2:$A$1117,$A15,Versuchsdaten!$B$2:$B$1117,$B15,Versuchsdaten!$C$2:$C$1117,"Sprint_5m",Versuchsdaten!$E$2:$E$1117,$E15,Versuchsdaten!$J$2:$J$1117,1)=1,SUMIFS(Versuchsdaten!$F$2:$F$1117,Versuchsdaten!$A$2:$A$1117,$A15,Versuchsdaten!$B$2:$B$1117,$B15,Versuchsdaten!$C$2:$C$1117,"Sprint_5m",Versuchsdaten!$E$2:$E$1117,$E15,Versuchsdaten!$J$2:$J$1117,1),"")) | L15: =IF(LEFT(C15,7)<>"Sprint_","",IF(COUNTIFS(Versuchsdaten!$A$2:$A$1117,$A15,Versuchsdaten!$B$2:$B$1117,$B15,Versuchsdaten!$C$2:$C$1117,"Sprint_10m",Versuchsdaten!$E$2:$E$1117,$E15,Versuchsdaten!$J$2:$J$1117,1)=1,SUMIFS(Versuchsdaten!$F$2:$F$1117,Versuchsdaten!$A$2:$A$1117,$A15,Versuchsdaten!$B$2:$B$1117,$B15,Versuchsdaten!$C$2:$C$1117,"Sprint_10m",Versuchsdaten!$E$2:$E$1117,$E15,Versuchsdaten!$J$2:$J$1117,1),"")) | M15: =IF(LEFT(C15,7)<>"Sprint_","",IF(COUNTIFS(Versuchsdaten!$A$2:$A$1117,$A15,Versuchsdaten!$B$2:$B$1117,$B15,Versuchsdaten!$C$2:$C$1117,"Sprint_30m",Versuchsdaten!$E$2:$E$1117,$E15,Versuchsdaten!$J$2:$J$1117,1)=1,SUMIFS(Versuchsdaten!$F$2:$F$1117,Versuchsdaten!$A$2:$A$1117,$A15,Versuchsdaten!$B$2:$B$1117,$B15,Versuchsdaten!$C$2:$C$1117,"Sprint_30m",Versuchsdaten!$E$2:$E$1117,$E15,Versuchsdaten!$J$2:$J$1117,1),"")) | N15: =IF(LEFT(C15,7)<>"Sprint_",0,IF(IF(ISNUMBER(K15),IF(K15<=0,1,IF(5/K15>10,1,0)),0)+IF(ISNUMBER(L15),IF(ISNUMBER(K15),IF(L15-K15<=0,1,IF(5/(L15-K15)>10,1,0)),IF(L15<=0,1,IF(10/L15>10,1,0))),0)+IF(ISNUMBER(M15),IF(ISNUMBER(L15),IF(M15-L15<=0,1,IF(20/(M15-L15)>10,1,0)),IF(ISNUMBER(K15),IF(M15-K15<=0,1,IF(25/(M15-K15)>10,1,0)),IF(M15<=0,1,IF(30/M15>10,1,0)))),0)>0,1,0)) | O15: =IF(AND(J15=1,N15=0),1,0) | P15: =INDEX(Personendaten!$J$2:$J$32,MATCH(A15,Personendaten!$A$2:$A$32,0)) | Q15: =IF(O15=1,"",IF(AND(B15="post",P15="nicht angetreten"),"NANG",IF(N15=1,"AUSL",IFERROR(VLOOKUP(H15,Vokabular!$A$2:$B$8,2,FALSE),"UNBEKANNT"))))
A16: BW-01 | B16: prä | C16: COD_505 | D16: L | E16: 3 | H16: Nur 2 Versuche aus Zeitmangel | I16: =INDEX(Personendaten!$C$2:$C$32,MATCH(A16,Personendaten!$A$2:$A$32,0)) | J16: =IF(AND(F16<>"",G16=""),1,0) | K16: =IF(LEFT(C16,7)<>"Sprint_","",IF(COUNTIFS(Versuchsdaten!$A$2:$A$1117,$A16,Versuchsdaten!$B$2:$B$1117,$B16,Versuchsdaten!$C$2:$C$1117,"Sprint_5m",Versuchsdaten!$E$2:$E$1117,$E16,Versuchsdaten!$J$2:$J$1117,1)=1,SUMIFS(Versuchsdaten!$F$2:$F$1117,Versuchsdaten!$A$2:$A$1117,$A16,Versuchsdaten!$B$2:$B$1117,$B16,Versuchsdaten!$C$2:$C$1117,"Sprint_5m",Versuchsdaten!$E$2:$E$1117,$E16,Versuchsdaten!$J$2:$J$1117,1),"")) | L16: =IF(LEFT(C16,7)<>"Sprint_","",IF(COUNTIFS(Versuchsdaten!$A$2:$A$1117,$A16,Versuchsdaten!$B$2:$B$1117,$B16,Versuchsdaten!$C$2:$C$1117,"Sprint_10m",Versuchsdaten!$E$2:$E$1117,$E16,Versuchsdaten!$J$2:$J$1117,1)=1,SUMIFS(Versuchsdaten!$F$2:$F$1117,Versuchsdaten!$A$2:$A$1117,$A16,Versuchsdaten!$B$2:$B$1117,$B16,Versuchsdaten!$C$2:$C$1117,"Sprint_10m",Versuchsdaten!$E$2:$E$1117,$E16,Versuchsdaten!$J$2:$J$1117,1),"")) | M16: =IF(LEFT(C16,7)<>"Sprint_","",IF(COUNTIFS(Versuchsdaten!$A$2:$A$1117,$A16,Versuchsdaten!$B$2:$B$1117,$B16,Versuchsdaten!$C$2:$C$1117,"Sprint_30m",Versuchsdaten!$E$2:$E$1117,$E16,Versuchsdaten!$J$2:$J$1117,1)=1,SUMIFS(Versuchsdaten!$F$2:$F$1117,Versuchsdaten!$A$2:$A$1117,$A16,Versuchsdaten!$B$2:$B$1117,$B16,Versuchsdaten!$C$2:$C$1117,"Sprint_30m",Versuchsdaten!$E$2:$E$1117,$E16,Versuchsdaten!$J$2:$J$1117,1),"")) | N16: =IF(LEFT(C16,7)<>"Sprint_",0,IF(IF(ISNUMBER(K16),IF(K16<=0,1,IF(5/K16>10,1,0)),0)+IF(ISNUMBER(L16),IF(ISNUMBER(K16),IF(L16-K16<=0,1,IF(5/(L16-K16)>10,1,0)),IF(L16<=0,1,IF(10/L16>10,1,0))),0)+IF(ISNUMBER(M16),IF(ISNUMBER(L16),IF(M16-L16<=0,1,IF(20/(M16-L16)>10,1,0)),IF(ISNUMBER(K16),IF(M16-K16<=0,1,IF(25/(M16-K16)>10,1,0)),IF(M16<=0,1,IF(30/M16>10,1,0)))),0)>0,1,0)) | O16: =IF(AND(J16=1,N16=0),1,0) | P16: =INDEX(Personendaten!$J$2:$J$32,MATCH(A16,Personendaten!$A$2:$A$32,0)) | Q16: =IF(O16=1,"",IF(AND(B16="post",P16="nicht angetreten"),"NANG",IF(N16=1,"AUSL",IFERROR(VLOOKUP(H16,Vokabular!$A$2:$B$8,2,FALSE),"UNBEKANNT"))))
A17: BW-01 | B17: prä | C17: COD_505 | D17: R | E17: 1 | F17: 2.67 | I17: =INDEX(Personendaten!$C$2:$C$32,MATCH(A17,Personendaten!$A$2:$A$32,0)) | J17: =IF(AND(F17<>"",G17=""),1,0) | K17: =IF(LEFT(C17,7)<>"Sprint_","",IF(COUNTIFS(Versuchsdaten!$A$2:$A$1117,$A17,Versuchsdaten!$B$2:$B$1117,$B17,Versuchsdaten!$C$2:$C$1117,"Sprint_5m",Versuchsdaten!$E$2:$E$1117,$E17,Versuchsdaten!$J$2:$J$1117,1)=1,SUMIFS(Versuchsdaten!$F$2:$F$1117,Versuchsdaten!$A$2:$A$1117,$A17,Versuchsdaten!$B$2:$B$1117,$B17,Versuchsdaten!$C$2:$C$1117,"Sprint_5m",Versuchsdaten!$E$2:$E$1117,$E17,Versuchsdaten!$J$2:$J$1117,1),"")) | L17: =IF(LEFT(C17,7)<>"Sprint_","",IF(COUNTIFS(Versuchsdaten!$A$2:$A$1117,$A17,Versuchsdaten!$B$2:$B$1117,$B17,Versuchsdaten!$C$2:$C$1117,"Sprint_10m",Versuchsdaten!$E$2:$E$1117,$E17,Versuchsdaten!$J$2:$J$1117,1)=1,SUMIFS(Versuchsdaten!$F$2:$F$1117,Versuchsdaten!$A$2:$A$1117,$A17,Versuchsdaten!$B$2:$B$1117,$B17,Versuchsdaten!$C$2:$C$1117,"Sprint_10m",Versuchsdaten!$E$2:$E$1117,$E17,Versuchsdaten!$J$2:$J$1117,1),"")) | M17: =IF(LEFT(C17,7)<>"Sprint_","",IF(COUNTIFS(Versuchsdaten!$A$2:$A$1117,$A17,Versuchsdaten!$B$2:$B$1117,$B17,Versuchsdaten!$C$2:$C$1117,"Sprint_30m",Versuchsdaten!$E$2:$E$1117,$E17,Versuchsdaten!$J$2:$J$1117,1)=1,SUMIFS(Versuchsdaten!$F$2:$F$1117,Versuchsdaten!$A$2:$A$1117,$A17,Versuchsdaten!$B$2:$B$1117,$B17,Versuchsdaten!$C$2:$C$1117,"Sprint_30m",Versuchsdaten!$E$2:$E$1117,$E17,Versuchsdaten!$J$2:$J$1117,1),"")) | N17: =IF(LEFT(C17,7)<>"Sprint_",0,IF(IF(ISNUMBER(K17),IF(K17<=0,1,IF(5/K17>10,1,0)),0)+IF(ISNUMBER(L17),IF(ISNUMBER(K17),IF(L17-K17<=0,1,IF(5/(L17-K17)>10,1,0)),IF(L17<=0,1,IF(10/L17>10,1,0))),0)+IF(ISNUMBER(M17),IF(ISNUMBER(L17),IF(M17-L17<=0,1,IF(20/(M17-L17)>10,1,0)),IF(ISNUMBER(K17),IF(M17-K17<=0,1,IF(25/(M17-K17)>10,1,0)),IF(M17<=0,1,IF(30/M17>10,1,0)))),0)>0,1,0)) | O17: =IF(AND(J17=1,N17=0),1,0) | P17: =INDEX(Personendaten!$J$2:$J$32,MATCH(A17,Personendaten!$A$2:$A$32,0)) | Q17: =IF(O17=1,"",IF(AND(B17="post",P17="nicht angetreten"),"NANG",IF(N17=1,"AUSL",IFERROR(VLOOKUP(H17,Vokabular!$A$2:$B$8,2,FALSE),"UNBEKANNT"))))
A18: BW-01 | B18: prä | C18: COD_505 | D18: R | E18: 2 | F18: 2.72 | I18: =INDEX(Personendaten!$C$2:$C$32,MATCH(A18,Personendaten!$A$2:$A$32,0)) | J18: =IF(AND(F18<>"",G18=""),1,0) | K18: =IF(LEFT(C18,7)<>"Sprint_","",IF(COUNTIFS(Versuchsdaten!$A$2:$A$1117,$A18,Versuchsdaten!$B$2:$B$1117,$B18,Versuchsdaten!$C$2:$C$1117,"Sprint_5m",Versuchsdaten!$E$2:$E$1117,$E18,Versuchsdaten!$J$2:$J$1117,1)=1,SUMIFS(Versuchsdaten!$F$2:$F$1117,Versuchsdaten!$A$2:$A$1117,$A18,Versuchsdaten!$B$2:$B$1117,$B18,Versuchsdaten!$C$2:$C$1117,"Sprint_5m",Versuchsdaten!$E$2:$E$1117,$E18,Versuchsdaten!$J$2:$J$1117,1),"")) | L18: =IF(LEFT(C18,7)<>"Sprint_","",IF(COUNTIFS(Versuchsdaten!$A$2:$A$1117,$A18,Versuchsdaten!$B$2:$B$1117,$B18,Versuchsdaten!$C$2:$C$1117,"Sprint_10m",Versuchsdaten!$E$2:$E$1117,$E18,Versuchsdaten!$J$2:$J$1117,1)=1,SUMIFS(Versuchsdaten!$F$2:$F$1117,Versuchsdaten!$A$2:$A$1117,$A18,Versuchsdaten!$B$2:$B$1117,$B18,Versuchsdaten!$C$2:$C$1117,"Sprint_10m",Versuchsdaten!$E$2:$E$1117,$E18,Versuchsdaten!$J$2:$J$1117,1),"")) | M18: =IF(LEFT(C18,7)<>"Sprint_","",IF(COUNTIFS(Versuchsdaten!$A$2:$A$1117,$A18,Versuchsdaten!$B$2:$B$1117,$B18,Versuchsdaten!$C$2:$C$1117,"Sprint_30m",Versuchsdaten!$E$2:$E$1117,$E18,Versuchsdaten!$J$2:$J$1117,1)=1,SUMIFS(Versuchsdaten!$F$2:$F$1117,Versuchsdaten!$A$2:$A$1117,$A18,Versuchsdaten!$B$2:$B$1117,$B18,Versuchsdaten!$C$2:$C$1117,"Sprint_30m",Versuchsdaten!$E$2:$E$1117,$E18,Versuchsdaten!$J$2:$J$1117,1),"")) | N18: =IF(LEFT(C18,7)<>"Sprint_",0,IF(IF(ISNUMBER(K18),IF(K18<=0,1,IF(5/K18>10,1,0)),0)+IF(ISNUMBER(L18),IF(ISNUMBER(K18),IF(L18-K18<=0,1,IF(5/(L18-K18)>10,1,0)),IF(L18<=0,1,IF(10/L18>10,1,0))),0)+IF(ISNUMBER(M18),IF(ISNUMBER(L18),IF(M18-L18<=0,1,IF(20/(M18-L18)>10,1,0)),IF(ISNUMBER(K18),IF(M18-K18<=0,1,IF(25/(M18-K18)>10,1,0)),IF(M18<=0,1,IF(30/M18>10,1,0)))),0)>0,1,0)) | O18: =IF(AND(J18=1,N18=0),1,0) | P18: =INDEX(Personendaten!$J$2:$J$32,MATCH(A18,Personendaten!$A$2:$A$32,0)) | Q18: =IF(O18=1,"",IF(AND(B18="post",P18="nicht angetreten"),"NANG",IF(N18=1,"AUSL",IFERROR(VLOOKUP(H18,Vokabular!$A$2:$B$8,2,FALSE),"UNBEKANNT"))))
A19: BW-01 | B19: prä | C19: COD_505 | D19: R | E19: 3 | H19: Nur 2 Versuche aus Zeitmangel | I19: =INDEX(Personendaten!$C$2:$C$32,MATCH(A19,Personendaten!$A$2:$A$32,0)) | J19: =IF(AND(F19<>"",G19=""),1,0) | K19: =IF(LEFT(C19,7)<>"Sprint_","",IF(COUNTIFS(Versuchsdaten!$A$2:$A$1117,$A19,Versuchsdaten!$B$2:$B$1117,$B19,Versuchsdaten!$C$2:$C$1117,"Sprint_5m",Versuchsdaten!$E$2:$E$1117,$E19,Versuchsdaten!$J$2:$J$1117,1)=1,SUMIFS(Versuchsdaten!$F$2:$F$1117,Versuchsdaten!$A$2:$A$1117,$A19,Versuchsdaten!$B$2:$B$1117,$B19,Versuchsdaten!$C$2:$C$1117,"Sprint_5m",Versuchsdaten!$E$2:$E$1117,$E19,Versuchsdaten!$J$2:$J$1117,1),"")) | L19: =IF(LEFT(C19,7)<>"Sprint_","",IF(COUNTIFS(Versuchsdaten!$A$2:$A$1117,$A19,Versuchsdaten!$B$2:$B$1117,$B19,Versuchsdaten!$C$2:$C$1117,"Sprint_10m",Versuchsdaten!$E$2:$E$1117,$E19,Versuchsdaten!$J$2:$J$1117,1)=1,SUMIFS(Versuchsdaten!$F$2:$F$1117,Versuchsdaten!$A$2:$A$1117,$A19,Versuchsdaten!$B$2:$B$1117,$B19,Versuchsdaten!$C$2:$C$1117,"Sprint_10m",Versuchsdaten!$E$2:$E$1117,$E19,Versuchsdaten!$J$2:$J$1117,1),"")) | M19: =IF(LEFT(C19,7)<>"Sprint_","",IF(COUNTIFS(Versuchsdaten!$A$2:$A$1117,$A19,Versuchsdaten!$B$2:$B$1117,$B19,Versuchsdaten!$C$2:$C$1117,"Sprint_30m",Versuchsdaten!$E$2:$E$1117,$E19,Versuchsdaten!$J$2:$J$1117,1)=1,SUMIFS(Versuchsdaten!$F$2:$F$1117,Versuchsdaten!$A$2:$A$1117,$A19,Versuchsdaten!$B$2:$B$1117,$B19,Versuchsdaten!$C$2:$C$1117,"Sprint_30m",Versuchsdaten!$E$2:$E$1117,$E19,Versuchsdaten!$J$2:$J$1117,1),"")) | N19: =IF(LEFT(C19,7)<>"Sprint_",0,IF(IF(ISNUMBER(K19),IF(K19<=0,1,IF(5/K19>10,1,0)),0)+IF(ISNUMBER(L19),IF(ISNUMBER(K19),IF(L19-K19<=0,1,IF(5/(L19-K19)>10,1,0)),IF(L19<=0,1,IF(10/L19>10,1,0))),0)+IF(ISNUMBER(M19),IF(ISNUMBER(L19),IF(M19-L19<=0,1,IF(20/(M19-L19)>10,1,0)),IF(ISNUMBER(K19),IF(M19-K19<=0,1,IF(25/(M19-K19)>10,1,0)),IF(M19<=0,1,IF(30/M19>10,1,0)))),0)>0,1,0)) | O19: =IF(AND(J19=1,N19=0),1,0) | P19: =INDEX(Personendaten!$J$2:$J$32,MATCH(A19,Personendaten!$A$2:$A$32,0)) | Q19: =IF(O19=1,"",IF(AND(B19="post",P19="nicht angetreten"),"NANG",IF(N19=1,"AUSL",IFERROR(VLOOKUP(H19,Vokabular!$A$2:$B$8,2,FALSE),"UNBEKANNT"))))
